Workbook

Sheet Diagrama de clases
A2: En esta hoja se ubica la imagen del modelo, asegurando que sea clara y legible

Sheet Clases
A1: Clase | B1: Estereotipo | C1: Desripción | D1: Modificador de acceso | E1: Tipo de Clase
A2: Employee | B2: struct | C2: Estructura que representa a un empleado del sistema, ya sea piloto o administrador, con sus datos personales, credenciales de acceso y rol asignado. | D2: exported | E2: N/A
A3: Airline | B3: struct | C3: Estructura que representa una aerolínea comercial registrada en el sistema, identificada por su nombre, código y estado de actividad. | D3: exported | E3: N/A
A4: AirlineEmployee | B4: struct | C4: Estructura que representa la vinculación laboral de un empleado con una aerolínea, incluyendo las fechas de inicio y fin de la relación y su estado actual. | D4: exported | E4: N/A
A5: Airport | B5: struct | C5: Estructura que representa un aeropuerto con su nombre, código de identificación, tipo de operación y si se encuentra activo o inactivo. | D5: exported | E5: N/A
A6: Manufacturer | B6: struct | C6: Estructura que representa un fabricante de aeronaves, como Boeing, Airbus | D6: exported | E6: N/A
A7: Engine | B7: struct | C7: Estructura que representa un tipo de motor utilizado en aeronaves como CFM,IAE. | D7: exported | E7: N/A
A8: AircraftFamily | B8: struct | C8: Estructura que representa una familia de aeronaves agrupada por fabricante, como las familias Airbus A320. | D8: exported | E8: N/A
A9: AircraftModel | B9: struct | C9: Estructura que representa un modelo específico de aeronave, con su nombre, tipo, motor asociado, familia, fabricante y estado de disponibilidad. | D9: exported | E9: N/A
A10: TailNumber | B10: struct | C10: Estructura que representa la matrícula de una aeronave, vinculando un número de registro con un modelo de avión y la aerolínea. | D10: exported | E10: N/A
A11: Route | B11: struct | C11: Estructura que representa una ruta aérea entre dos aeropuertos, con el tiempo estimado de vuelo y los códigos de los aeropuertos de origen y destino. | D11: exported | E11: N/A
A12: AirlineRoute | B12: struct | C12: Estructura que representa una ruta aérea operada por una aerolínea específica, incluyendo los datos de la ruta, la aerolínea asignada y el estado de operación. | D12: exported | E12: N/A
... A26: SummaryPeriodType | B26: enum | C26: Enumeración que representa los tipos de período para los resúmenes de vuelo: mensual, trimestral, anual, primera quincena o segunda quincena. | D26: exported | E26: N/A

Sheet Employee
A1: <-Volver al inicio
A2: =Clases!$A$1 -> Clase | B2: =Clases!A2 -> Employee
A3: =Clases!$B$1 -> Estereotipo | B3: struct
A4: =Clases!$C$1 -> Desripción | B4: =Clases!C2 -> Estructura que representa a un empleado del sistema, ya sea piloto o administrador, con sus datos personales, credenciales de acceso y rol asignado.
A5: Modificador acceso: | B5: exported
A6: Tipo clase: | B6: N/A
A7: Relaciones
A8: Relación | B8: Tipo relación | E8: Estructura
A9: Es usada por | B9: Asociación | E9: =HYPERLINK("#'"&F9&"'!A1", F9) -> AirlineEmployee | F9: AirlineEmployee
A10: Es usada por | B10: Asociación | E10: =HYPERLINK("#'"&F10&"'!A1", F10) -> DailyLogbook | F10: DailyLogbook
A11: Es usada por | B11: Asociación | E11: =HYPERLINK("#'"&F11&"'!A1", F11) -> EmployeeFlightSummary | F11: EmployeeFlightSummary
A12: Necesita de | B12: Dependencia | E12: =HYPERLINK("#'"&F12&"'!A1", F12) -> EmployeeRole | F12: EmployeeRole
A13: Atributos
A14: Modificador de acceso | B14: Nombre | C14: Tipo de dato | E14: Tipo modificación atributo | F14: Tipo acceso atributo | G14: Valor por defecto | J14: Descripción atributo
C15: Tipo de dato | D15: ¿Cuál?
A16: exported | B16: ID | C16: String | E16: no final | F16: no static | J16: Identificador único del empleado
A17: exported | B17: Name | C17: String | E17: no final | F17: no static | J17: Nombre completo del empleado
A18: exported | B18: Email | C18: String | E18: no final | F18: no static | J18: Correo electrónico de acceso
A19: exported | B19: Password | C19: String | E19: no final | F19: no static | J19: Contraseña del empleado
A20: exported | B20: IdentificationNumber | C20: String | E20: no final | F20: no static | J20: Número de identificación personal
A21: exported | B21: Role | C21: String | E21: no final | F21: no static | J21: Rol asignado(admin o pilot)
A22: exported | B22: KeycloakUserID | C22: String | E22: no final | F22: no static | J22: Identificador del usuario en el sistema de autenticacion.
A23: Constructores
A24: Modificador de acceso | B24: Nombre | C24: Tipo constructor | D24: Descripción | E24: Parámetros | M24: Excepciones
E25: Nombre | F25: Tipo de dato | G25: ¿Cuál? | H25: Tipo parámetro | I25: Tipo modificación atributo | J25: Descripción
A26: N/A | D26: Las estructuras en Go no usan constructores explícitos
A27: Métodos accesores
A28: Modificador de aceso | B28: Nombre | C28: Tipo método accesor | D28: Tipo modificación método | E28: Descripción | F28: Parámetros | L28: Tipo dato de retorno | N28: Excepciones
F29: Nombre | G29: Tipo de dato | H29: ¿Cuál? | I29: Tipo parámetro | J29: Tipo modificación atributo | K29: Descripción | L29: Tipo de dato | M29: ¿Cuál?
A30: N/A | E30: En Go los campos son accesibles directamente, no se usan getters/setters
A31: Métodos
A32: Modificador de aceso | B32: Nombre | C32: Tipo acceso método | D32: Tipo modificación método | E32: Descripción | F32: Parámetros | L32: Tipo dato de retorno | N32: Excepciones
F33: Nombre | G33: Tipo de dato | H33: ¿Cuál? | I33: Tipo parámetro | J33: Tipo modificación atributo | K33: Descripción | L33: Tipo de dato | M33: ¿Cuál?
A34: exported | B34: SetID | C34: no static | D34: no final | E34: Genera un identificador único para el empleado usando UUID | L34: void
A35: exported | B35: ToLogger | C35: no static | D35: no final | E35: Retorna información del empleado (id, email, rol) para registro en bitácora del sistema | L35: Otro | M35: []string

Sheet Airline
A1: <-Volver al inicio
A2: =Clases!$A$1 -> Clase | B2: =Clases!A3 -> Airline
A3: =Clases!$B$1 -> Estereotipo | B3: struct
A4: =Clases!$C$1 -> Desripción | B4: =Clases!C3 -> Estructura que representa una aerolínea comercial registrada en el sistema, identificada por su nombre, código y estado de actividad.
A5: Modificador acceso: | B5: exported
A6: Tipo clase: | B6: N/A
A7: Relaciones
A8: Relación | B8: Tipo relación | E8: Estructura
A9: Es usada por | B9: Asociación | E9: =HYPERLINK("#'"&F9&"'!A1", F9) -> AirlineEmployee | F9: AirlineEmployee
A10: Es usada por | B10: Asociación | E10: =HYPERLINK("#'"&F10&"'!A1", F10) -> TailNumber | F10: TailNumber
A11: Es usada por | B11: Asociación | E11: =HYPERLINK("#'"&F11&"'!A1", F11) -> AirlineRoute | F11: AirlineRoute
A12: Atributos
A13: Modificador de acceso | B13: Nombre | C13: Tipo de dato | E13: Tipo modificación atributo | F13: Tipo acceso atributo | G13: Valor por defecto | J13: Descripción atributo
C14: Tipo de dato | D14: ¿Cuál?
A15: exported | B15: ID | C15: String | E15: no final | F15: no static | J15: Identificador único de la aerolínea
A16: exported | B16: AirlineName | C16: String | E16: no final | F16: no static | J16: Nombre de la aerolínea
A17: exported | B17: AirlineCode | C17: String | E17: no final | F17: no static | J17: Código IATA de la aerolínea
A18: exported | B18: Status | C18: String | E18: no final | F18: no static | J18: Estado de la aerolínea(activa/inactiva)
A19: Constructores
A20: Modificador de acceso | B20: Nombre | C20: Tipo constructor | D20: Descripción | E20: Parámetros | M20: Excepciones
E21: Nombre | F21: Tipo de dato | G21: ¿Cuál? | H21: Tipo parámetro | I21: Tipo modificación atributo | J21: Descripción
A22: N/A | D22: Las estructuras en Go no usan constructores explícitos
A23: Métodos accesores
A24: Modificador de aceso | B24: Nombre | C24: Tipo método accesor | D24: Tipo modificación método | E24: Descripción | F24: Parámetros | L24: Tipo dato de retorno | N24: Excepciones
F25: Nombre | G25: Tipo de dato | H25: ¿Cuál? | I25: Tipo parámetro | J25: Tipo modificación atributo | K25: Descripción | L25: Tipo de dato | M25: ¿Cuál?
A26: N/A | E26: En Go los campos son accesibles directamente, no se usan getters/setters
A27: Métodos
A28: Modificador de acceso | B28: Nombre | C28: Tipo acceso método | D28: Tipo modificación método | E28: Descripción | F28: Parámetros | L28: Tipo dato de retorno | N28: Excepciones
F29: Nombre | G29: Tipo de dato | H29: ¿Cuál? | I29: Tipo parámetro | J29: Tipo modificación atributo | K29: Descripción | L29: Tipo de dato | M29: ¿Cuál?
A30: exported | B30: ToLogger | C30: no static | D30: no final | E30: Retorna información de la aerolínea (id, nombre, código, estado) para registro en bitácora del sistema | L30: Otro | M30: []string

Sheet AirlineEmployee
A1: <-Volver al inicio
A2: =Clases!$A$1 -> Clase | B2: =Clases!A4 -> AirlineEmployee
A3: =Clases!$B$1 -> Estereotipo | B3: struct
A4: =Clases!$C$1 -> Desripción | B4: =Clases!C4 -> Estructura que representa la vinculación laboral de un empleado con una aerolínea, incluyendo las fechas de inicio y fin de la relación y su estado actual.
A5: Modificador acceso: | B5: exported
A6: Tipo clase: | B6: N/A
A7: Relaciones
A8: Relación | B8: Tipo relación | E8: Estructura
A9: Necesita de | B9: Asociación | E9: =HYPERLINK("#'"&F9&"'!A1", F9) -> Employee | F9: Employee
A10: Necesita de | B10: Asociación | E10: =HYPERLINK("#'"&F10&"'!A1", F10) -> Airline | F10: Airline
A11: Atributos
A12: Modificador de acceso | B12: Nombre | C12: Tipo de dato | E12: Tipo modificación atributo | F12: Tipo acceso atributo | G12: Valor por defecto | J12: Descripción atributo
C13: Tipo de dato | D13: ¿Cuál?
A14: exported | B14: ID | C14: String | E14: no final | F14: no static | J14: Identificador único de la vinculación
A15: exported | B15: AirlineID | C15: String | E15: no final | F15: no static | J15: Identificador de la aerolínea asociada
A16: exported | B16: Bp | C16: String | E16: no final | F16: no static | J16: Numero de boarding pass del empleado en la aerolínea
A17: exported | B17: StartDate | C17: Date | E17: no final | F17: no static | J17: Fecha de inicio de la vinculación a la aerolínea
A18: exported | B18: EndDate | C18: Date | E18: no final | F18: no static | J18: Fecha de fin de la vinculacion a la aerolinea
A19: exported | B19: Active | C19: boolean/Boolean | E19: no final | F19: no static | J19: Indica si la vinculacion esta activa
A20: Constructores
A21: Modificador de acceso | B21: Nombre | C21: Tipo constructor | D21: Descripción | E21: Parámetros | M21: Excepciones
E22: Nombre | F22: Tipo de dato | G22: ¿Cuál? | H22: Tipo parámetro | I22: Tipo modificación atributo | J22: Descripción
A23: N/A | D23: Las estructuras en Go no usan constructores explícitos
A24: Métodos accesores
A25: Modificador de acceso | B25: Nombre | C25: Tipo método accesor | D25: Tipo modificación método | E25: Descripción | F25: Parámetros | L25: Tipo dato de retorno | N25: Excepciones
F26: Nombre | G26: Tipo de dato | H26: ¿Cuál? | I26: Tipo parámetro | J26: Tipo modificación atributo | K26: Descripción | L26: Tipo de dato | M26: ¿Cuál?
A27: N/A | E27: En Go los campos son accesibles directamente, no se usan getters/setters
A28: Métodos
A29: Modificador de acceso | B29: Nombre | C29: Tipo acceso método | D29: Tipo modificación método | E29: Descripción | F29: Parámetros | L29: Tipo dato de retorno | N29: Excepciones
F30: Nombre | G30: Tipo de dato | H30: ¿Cuál? | I30: Tipo parámetro | J30: Tipo modificación atributo | K30: Descripción | L30: Tipo de dato | M30: ¿Cuál?
A31: exported | B31: SetID | C31: no static | D31: no final | E31: Genera un identificador único para la vinculación usando UUID | L31: void
A32: exported | B32: ToLogger | C32: no static | D32: no final | E32: Retorna información de la vinculación (id, aerolínea, bp, fechas, estado) para registro en bitácora del sistema | L32: Otro | M32: []string

Sheet Airport
A1: <-Volver al inicio
A2: =Clases!$A$1 -> Clase | B2: =Clases!A5 -> Airport
A3: =Clases!$B$1 -> Estereotipo | B3: struct
A4: =Clases!$C$1 -> Desripción | B4: =Clases!C5 -> Estructura que representa un aeropuerto con su nombre, código de identificación, tipo de operación y si se encuentra activo o inactivo.
A5: Modificador acceso: | B5: exported
A6: Tipo clase: | B6: N/A
A7: Relaciones
A8: Relación | B8: Tipo relación | E8: Estructura
A9: Es usada por | B9: Asociación | E9: =HYPERLINK("#'"&F9&"'!A1", F9) -> Route | F9: Route
A10: Atributos
A11: Modificador de acceso | B11: Nombre | C11: Tipo de dato | E11: Tipo modificación atributo | F11: Tipo acceso atributo | G11: Valor por defecto | J11: Descripción atributo
C12: Tipo de dato | D12: ¿Cuál?
A13: exported | B13: ID | C13: String | E13: no final | F13: no static | J13: Identificador único del aeropuerto
A14: exported | B14: Name | C14: String | E14: no final | F14: no static | J14: Nombre del aeropuerto
A15: exported | B15: IATACode | C15: String | E15: no final | F15: no static | J15: Código IATA del aeropuerto(ej. BOG,CLO)
A16: exported | B16: Status | C16: boolean/Boolean | E16: no final | F16: no static | J16: Indica si el aeropuerto esta activo
A17: exported | B17: AirportType | C17: String | E17: no final | F17: no static | J17: Tipo de aeropuerto(nacional/internacional)
A18: Constructores
A19: Modificador de acceso | B19: Nombre | C19: Tipo constructor | D19: Descripción | E19: Parámetros | M19: Excepciones
E20: Nombre | F20: Tipo de dato | G20: ¿Cuál? | H20: Tipo parámetro | I20: Tipo modificación atributo | J20: Descripción
A21: N/A | D21: Las estructuras en Go no usan constructores explícitos
A22: Métodos accesores
A23: Modificador de acceso | B23: Nombre | C23: Tipo método accesor | D23: Tipo modificación método | E23: Descripción | F23: Parámetros | L23: Tipo dato de retorno | N23: Excepciones
F24: Nombre | G24: Tipo de dato | H24: ¿Cuál? | I24: Tipo parámetro | J24: Tipo modificación atributo | K24: Descripción | L24: Tipo de dato | M24: ¿Cuál?
A25: N/A | E25: En Go los campos son accesibles directamente, no se usan getters/setters
A26: Métodos
A27: Modificador de acceso | B27: Nombre | C27: Tipo acceso método | D27: Tipo modificación método | E27: Descripción | F27: Parámetros | L27: Tipo dato de retorno | N27: Excepciones
F28: Nombre | G28: Tipo de dato | H28: ¿Cuál? | I28: Tipo parámetro | J28: Tipo modificación atributo | K28: Descripción | L28: Tipo de dato | M28: ¿Cuál?
A29: exported | B29: ToLogger | C29: no static | D29: no final | E29: Retorna información del aeropuerto (id, nombre, código IATA, tipo, estado) para registro en bitácora del sistema | L29: Otro | M29: [] string
A30: exported | B30: IsActive | C30: no static | D30: no final | E30: Verifica si el aeropuerto se encuentra activo | L30: boolean/Boolean

Sheet Manufacturer
A1: <-Volver al inicio
A2: =Clases!$A$1 -> Clase | B2: =Clases!A6 -> Manufacturer
A3: =Clases!$B$1 -> Estereotipo | B3: struct
A4: =Clases!$C$1 -> Desripción | B4: =Clases!C6 -> Estructura que representa un fabricante de aeronaves, como Boeing, Airbus
A5: Modificador acceso: | B5: exported
A6: Tipo clase: | B6: N/A
A7: Relaciones
A8: Relación | B8: Tipo relación | E8: Estructura
A9: Es usada por | B9: Asociación | E9: =HYPERLINK("#'"&F9&"'!A1", F9) -> AircraftFamily | F9: AircraftFamily
A10: Es usada por | B10: Asociación | E10: =HYPERLINK("#'"&F10&"'!A1", F10) -> AircraftModel | F10: AircraftModel
A11: Atributos
A12: Modificador de acceso | B12: Nombre | C12: Tipo de dato | E12: Tipo modificación atributo | F12: Tipo acceso atributo | G12: Valor por defecto | J12: Descripción atributo
C13: Tipo de dato | D13: ¿Cuál?
A14: exported | B14: ID | C14: String | E14: no final | F14: no static | J14: Identificador único del fabricante
A15: exported | B15: Name | C15: String | E15: no final | F15: no static | J15: Nombre del fabricante
A16: Constructores
A17: Modificador de acceso | B17: Nombre | C17: Tipo constructor | D17: Descripción | E17: Parámetros | M17: |
E18: Nombre | F18: Tipo de dato | G18: ¿Cuál? | H18: Tipo parámetro | I18: Tipo modificación atributo | J18: Descripción
A19: N/A | D19: Las estructuras en Go no usan constructores explícitos
A20: Métodos accesores
A21: Modificador de acceso | B21: Nombre | C21: Tipo método accesor | D21: Tipo modificación método | E21: Descripción | F21: Parámetros | L21: Tipo dato de retorno | N21: Excepciones
F22: Nombre | G22: Tipo de dato | H22: ¿Cuál? | I22: Tipo parámetro | J22: Tipo modificación atributo | K22: Descripción | L22: Tipo de dato | M22: ¿Cuál?
A23: N/A | E23: En Go los campos son accesibles directamente, no se usan getters/setters
A24: Métodos
A25: Modificador de acceso | B25: Nombre | C25: Tipo acceso método | D25: Tipo modificación método | E25: Descripción | F25: Parámetros | L25: Tipo dato de retorno | N25: Excepciones
F26: Nombre | G26: Tipo de dato | H26: ¿Cuál? | I26: Tipo parámetro | J26: Tipo modificación atributo | K26: Descripción | L26: Tipo de dato | M26: ¿Cuál?
A27: exported | B27: ToLogger | C27: no static | D27: no final | E27: Retorna información del fabricante (id, nombre) para registro en bitácora del sistema | L27: Otro | M27: []string

Sheet Engine
A1: <-Volver al inicio
A2: =Clases!$A$1 -> Clase | B2: =Clases!A7 -> Engine
A3: =Clases!$B$1 -> Estereotipo | B3: struct
A4: =Clases!$C$1 -> Desripción | B4: =Clases!C7 -> Estructura que representa un tipo de motor utilizado en aeronaves como CFM,IAE.
A5: Modificador acceso: | B5: exported
A6: Tipo clase: | B6: N/A
A7: Relaciones
A8: Relación | B8: Tipo relación | E8: Estructura
A9: Es usada por | B9: Asociación | E9: =HYPERLINK("#'"&F9&"'!A1", F9) -> AircraftModel | F9: AircraftModel
A10: Atributos
A11: Modificador de acceso | B11: Nombre | C11: Tipo de dato | E11: Tipo modificación atributo | F11: Tipo acceso atributo | G11: Valor por defecto | J11: Descripción atributo
C12: Tipo de dato | D12: ¿Cuál?
A13: exported | B13: ID | C13: String | E13: no final | F13: no static | J13: Identificador único del motor
A14: exported | B14: Name | C14: String | E14: no final | F14: no static | J14: Nombre del motor
A15: Constructores
A16: Modificador de acceso | B16: Nombre | C16: Tipo constructor | D16: Descripción | E16: Parámetros | M16: Excepciones
E17: Nombre | F17: Tipo de dato | G17: ¿Cuál? | H17: Tipo parámetro | I17: Tipo modificación atributo | J17: Descripción
A18: N/A | D18: Las estructuras en Go no usan constructores explícitos
A19: Métodos accesores
A20: Modificador de acceso | B20: Nombre | C20: Tipo método accesor | D20: Tipo modificación método | E20: Descripción | F20: Parámetros | L20: Tipo dato de retorno | N20: Excepciones
F21: Nombre | G21: Tipo de dato | H21: ¿Cuál? | I21: Tipo parámetro | J21: Tipo modificación atributo | K21: Descripción | L21: Tipo de dato | M21: ¿Cuál?
A22: N/A | E22: En Go los campos son accesibles directamente, no se usan getters/setters
A23: Métodos
A24: Modificador de acceso | B24: Nombre | C24: Tipo acceso método | D24: Tipo modificación método | E24: Descripción | F24: Parámetros | L24: Tipo dato de retorno | N24: Excepciones
F25: Nombre | G25: Tipo de dato | H25: ¿Cuál? | I25: Tipo parámetro | J25: Tipo modificación atributo | K25: Descripción | L25: Tipo de dato | M25: ¿Cuál?
A26: exported | B26: ToLogger | C26: no static | D26: no final | E26: Retorna información del motor (id, nombre) para registro en bitácora del sistema | L26: Otro | M26: []string

Sheet AircraftFamily
A1: <-Volver al inicio
A2: =Clases!$A$1 -> Clase | B2: =Clases!A8 -> AircraftFamily
A3: =Clases!$B$1 -> Estereotipo | B3: struct
A4: =Clases!$C$1 -> Desripción | B4: =Clases!C8 -> Estructura que representa una familia de aeronaves agrupada por fabricante, como las familias Airbus A320.
A5: Modificador acceso: | B5: exported
A6: Tipo clase: | B6: N/A
A7: Relaciones
A8: Relación | B8: Tipo relación | E8: Estructura
A9: Necesita de | B9: Asociación | E9: =HYPERLINK("#'"&F9&"'!A1", F9) -> Manufacturer | F9: Manufacturer
A10: Es usada por | B10: Asociación | E10: =HYPERLINK("#'"&F10&"'!A1", F10) -> AircraftModel | F10: AircraftModel
A11: Atributos
A12: Modificador de acceso | B12: Nombre | C12: Tipo de dato | E12: Tipo modificación atributo | F12: Tipo acceso atributo | G12: Valor por defecto | J12: Descripción atributo
C13: Tipo de dato | D13: ¿Cuál?
A14: exported | B14: Family | C14: String | E14: no final | F14: no static | J14: Nombre de la familia de aeronaves
A15: exported | B15: Manufacturer | C15: String | E15: no final | F15: no static | J15: Nombre del fabricante asociado
A16: Constructores
A17: Modificador de acceso | B17: Nombre | C17: Tipo constructor | D17: Descripción | E17: Parámetros | M17: Excepciones
E18: Nombre | F18: Tipo de dato | G18: ¿Cuál? | H18: Tipo parámetro | I18: Tipo modificación atributo | J18: Descripción
A19: N/A | D19: Las estructuras en Go no usan constructores explícitos
A20: Métodos accesores
A21: Modificador de acceso | B21: Nombre | C21: Tipo método accesor | D21: Tipo modificación método | E21: Descripción | F21: Parámetros | L21: Tipo dato de retorno | N21: Excepciones
F22: Nombre | G22: Tipo de dato | H22: ¿Cuál? | I22: Tipo parámetro | J22: Tipo modificación atributo | K22: Descripción | L22: Tipo de dato | M22: ¿Cuál?
A23: N/A | E23: En Go los campos son accesibles directamente, no se usan getters/setters
A25: Métodos
A26: Modificador de acceso | B26: Nombre | C26: Tipo acceso método | D26: Tipo modificación método | E26: Descripción | F26: Parámetros | L26: Tipo dato de retorno | N26: Excepciones
F27: Nombre | G27: Tipo de dato | H27: ¿Cuál? | I27: Tipo parámetro | J27: Tipo modificación atributo | K27: Descripción | L27: Tipo de dato | M27: ¿Cuál?
A28: exported | B28: ToLogger | C28: no static | D28: no final | E28: Retorna información de la familia de aeronaves (familia, fabricante) para registro en bitácora del sistema | L28: Otro | M28: []string

Sheet AircraftModel
A1: <-Volver al inicio
A2: =Clases!$A$1 -> Clase | B2: =Clases!A9 -> AircraftModel
A3: =Clases!$B$1 -> Estereotipo | B3: struct
A4: =Clases!$C$1 -> Desripción | B4: =Clases!C9 -> Estructura que representa un modelo específico de aeronave, con su nombre, tipo, motor asociado, familia, fabricante y estado de disponibilidad.
A5: Modificador acceso: | B5: exported
A6: Tipo clase: | B6: N/A
A7: Relaciones
A8: Relación | B8: Tipo relación | E8: Estructura
A9: Necesita de | B9: Asociación | E9: =HYPERLINK("#'"&F9&"'!A1", F9) -> Manufacturer | F9: Manufacturer
A10: Necesita de | B10: Asociación | E10: =HYPERLINK("#'"&F10&"'!A1", F10) -> AircraftFamily | F10: AircraftFamily
A11: Necesita de | B11: Asociación | E11: =HYPERLINK("#'"&F11&"'!A1", F11) -> Engine | F11: Engine
A12: Es usada por | B12: Asociación | E12: =HYPERLINK("#'"&F12&"'!A1", F12) -> TailNumber | F12: TailNumber
A13: Atributos
A14: Modificador de aceso | B14: Nombre | C14: Tipo de dato | E14: Tipo modificación atributo | F14: Tipo acceso atributo | G14: Valor por defecto | J14: Descripción atributo
C15: Tipo de dato | D15: ¿Cuál?
A16: exported | B16: ID | C16: String | E16: no final | F16: no static | J16: Identificador único del modelo de aeronave
A17: exported | B17: ModelName | C17: String | E17: no final | F17: no static | J17: Nombre del modelo de aeronave
A18: exported | B18: AircraftTypeName | C18: String | E18: no final | F18: no static | J18: Nombre del tipo de aeronave
A19: exported | B19: EnigneTypeName | C19: String | E19: no final | F19: no static | J19: Nombre del tipo de motor asociado
A20: exported | B20: Family | C20: String | E20: no final | F20: no static | J20: Familia de aeronaves a la que pertenece
A21: exported | B21: Manufacturer | C21: String | E21: no final | F21: no static | J21: Fabricante de la aeronave
A22: exported | B22: Status | C22: boolean/Boolean | E22: no final | F22: no static | J22: Indica si el modelo de aeronave está activo
A23: Constructores
A24: Modificador de aceso | B24: Nombre | C24: Tipo constructor | D24: Descripción | E24: Parámetros | M24: Excepciones
E25: Nombre | F25: Tipo de dato | G25: ¿Cuál? | H25: Tipo parámetro | I25: Tipo modificación atributo | J25: Descripción
A26: N/A | D26: Las estructuras en Go no usan constructores explícitos
A27: Métodos accesores
A28: Modificador de aceso | B28: Nombre | C28: Tipo método accesor | D28: Tipo modificación método | E28: Descripción | F28: Parámetros | L28: Tipo dato de retorno | N28: Excepciones
F29: Nombre | G29: Tipo de dato | H29: ¿Cuál? | I29: Tipo parámetro | J29: Tipo modificación atributo | K29: Descripción | L29: Tipo de dato | M29: ¿Cuál?
A30: N/A | E30: En Go los campos son accesibles directamente, no se usan getters/setters
A31: Métodos
A32: Modificador de aceso | B32: Nombre | C32: Tipo acceso método | D32: Tipo modificación método | E32: Descripción | F32: Parámetros | L32: Tipo dato de retorno | N32: Excepciones
F33: Nombre | G33: Tipo de dato | H33: ¿Cuál? | I33: Tipo parámetro | J33: Tipo modificación atributo | K33: Descripción | L33: Tipo de dato | M33: ¿Cuál?
A34: exported | B34: ToLogger | C34: no static | D34: no final | E34: Retorna información del modelo de aeronave (id, nombre, tipo, motor, familia, fabricante, estado) para registro en bitácora del sistema | L34: Otro | M34: []string

Sheet TailNumber
A1: <-Volver al inicio
A2: =Clases!$A$1 -> Clase | B2: =Clases!A10 -> TailNumber
A3: =Clases!$B$1 -> Estereotipo | B3: struct
A4: =Clases!$C$1 -> Desripción | B4: =Clases!C10 -> Estructura que representa la matrícula de una aeronave, vinculando un número de registro con un modelo de avión y la aerolínea.
A5: Modificador acceso: | B5: exported
A6: Tipo clase: | B6: N/A
A7: Relaciones
A8: Relación | B8: Tipo relación | E8: Estructura
A9: Necesita de | B9: Asociación | E9: =HYPERLINK("#'"&F9&"'!A1", F9) -> AircraftModel | F9: AircraftModel
A10: Necesita de | B10: Asociación | E10: =HYPERLINK("#'"&F10&"'!A1", F10) -> Airline | F10: Airline
A11: Es usada por | B11: Asociación | E11: =HYPERLINK("#'"&F11&"'!A1", F11) -> DailyLogbookDetail | F11: DailyLogbookDetail
A12: Atributos
A13: Modificador de acceso | B13: Nombre | C13: Tipo de dato | E13: Tipo modificación atributo | F13: Tipo acceso atributo | G13: Valor por defecto | J13: Descripción atributo
C14: Tipo de dato | D14: ¿Cuál?
A15: exported | B15: ID | C15: String | E15: no final | F15: no static | J15: Identificador único de la matrícula
A16: exported | B16: TailNumber | C16: String | E16: no final | F16: no static | J16: Número de matrícula de la aeronave
A17: exported | B17: AircraftModelID | C17: String | E17: no final | F17: no static | J17: Identificador del modelo de aeronave asociado
A18: exported | B18: AirlineID | C18: String | E18: no final | F18: no static | J18: Identificador de la aerolínea propietaria
A19: exported | B19: ModelName | C19: String | E19: no final | F19: no static | J19: Nombre del modelo de aeronave (campo de consulta)
A20: exported | B20: AirlineName | C20: String | E20: no final | F20: no static | J20: Nombre de la aerolínea (campo de consulta)
A21: Constructores
A22: Modificador de acceso | B22: Nombre | C22: Tipo constructor | D22: Descripción | E22: Parámetros | M22: Excepciones
E23: Nombre | F23: Tipo de dato | G23: ¿Cuál? | H23: Tipo parámetro | I23: Tipo modificación atributo | J23: Descripción
A24: N/A | D24: Las estructuras en Go no usan constructores explícitos
A25: Métodos accesores
A26: Modificador de acceso | B26: Nombre | C26: Tipo método accesor | D26: Tipo modificación método | E26: Descripción | F26: Parámetros | L26: Tipo dato de retorno | N26: Excepciones
F27: Nombre | G27: Tipo de dato | H27: ¿Cuál? | I27: Tipo parámetro | J27: Tipo modificación atributo | K27: Descripción | L27: Tipo de dato | M27: ¿Cuál?
A28: N/A | E28: En Go los campos son accesibles directamente, no se usan getters/setters
A30: Métodos
A31: Modificador de acceso | B31: Nombre | C31: Tipo acceso método | D31: Tipo modificación método | E31: Descripción | F31: Parámetros | L31: Tipo dato de retorno | N31: Excepciones
F32: Nombre | G32: Tipo de dato | H32: ¿Cuál? | I32: Tipo parámetro | J32: Tipo modificación atributo | K32: Descripción | L32: Tipo de dato | M32: ¿Cuál?
A33: exported | B33: ToLogger | C33: no static | D33: no final | E33: Retorna información de la matrícula (id, número de cola, modelo, aerolínea) para registro en bitácora del sistema | L33: Otro | M33: []string

Sheet Route
A1: <-Volver al inicio
A2: =Clases!$A$1 -> Clase | B2: =Clases!A11 -> Route
A3: =Clases!$B$1 -> Estereotipo | B3: struct
A4: =Clases!$C$1 -> Desripción | B4: =Clases!C11 -> Estructura que representa una ruta aérea entre dos aeropuertos, con el tiempo estimado de vuelo y los códigos de los aeropuertos de origen y destino.
A5: Modificador acceso: | B5: exported
A6: Tipo clase: | B6: N/A
A7: Relaciones
A8: Relación | B8: Tipo relación | E8: Estructura
A9: Necesita de | B9: Asociación | E9: =HYPERLINK("#'"&F9&"'!A1", F9) -> Airport | F9: Airport
A10: Es usada por | B10: Asociación | E10: =HYPERLINK("#'"&F10&"'!A1", F10) -> AirlineRoute | F10: AirlineRoute
A11: Atributos
A12: Modificador de acceso | B12: Nombre | C12: Tipo de dato | E12: Tipo modificación atributo | F12: Tipo acceso atributo | G12: Valor por defecto | J12: Descripción atributo
C13: Tipo de dato | D13: ¿Cuál?
A14: exported | B14: ID | C14: String | E14: no final | F14: no static | J14: Identificador único de la ruta
A15: exported | B15: OriginAirportID | C15: String | E15: no final | F15: no static | J15: Identificador del aeropuerto de origen
A16: exported | B16: DestinationAirportID | C16: String | E16: no final | F16: no static | J16: Identificador del aeropuerto de destino
A17: exported | B17: AirportType | C17: String | E17: no final | F17: no static | J17: Tipo de operación (nacional/internacional)
A18: exported | B18: EstimatedFlightTime | C18: String | E18: no final | F18: no static | J18: Tiempo estimado de vuelo en formato HH:MM:SS
A19: exported | B19: OriginIataCode | C19: String | E19: no final | F19: no static | J19: Código IATA del aeropuerto de origen
A20: exported | B20: OriginAirportName | C20: String | E20: no final | F20: no static | J20: Nombre del aeropuerto de origen
A21: exported | B21: DestinationIataCode | C21: String | E21: no final | F21: no static | J21: Código IATA del aeropuerto de destino
A22: exported | B22: DestinationAirportName | C22: String | E22: no final | F22: no static | J22: Nombre del aeropuerto de destino
A23: exported | B23: RouteCode | C23: String | E23: no final | F23: no static | J23: Código de la ruta (ej. BOG-CLO)
A24: Constructores
A25: Modificador de acceso | B25: Nombre | C25: Tipo constructor | D25: Descripción | E25: Parámetros | M25: Excepciones
E26: Nombre | F26: Tipo de dato | G26: ¿Cuál? | H26: Tipo parámetro | I26: Tipo modificación atributo | J26: Descripción
A27: N/A | D27: Las estructuras en Go no usan constructores explícitos
A28: Métodos accesores
A29: Modificador de acceso | B29: Nombre | C29: Tipo método accesor | D29: Tipo modificación método | E29: Descripción | F29: Parámetros | L29: Tipo dato de retorno | N29: Excepciones
F30: Nombre | G30: Tipo de dato | H30: ¿Cuál? | I30: Tipo parámetro | J30: Tipo modificación atributo | K30: Descripción | L30: Tipo de dato | M30: ¿Cuál?
A31: N/A | E31: En Go los campos son accesibles directamente, no se usan getters/setters
A32: Métodos
A33: Modificador de acceso | B33: Nombre | C33: Tipo acceso método | D33: Tipo modificación método | E33: Descripción | F33: Parámetros | L33: Tipo dato de retorno | N33: Excepciones
F34: Nombre | G34: Tipo de dato | H34: ¿Cuál? | I34: Tipo parámetro | J34: Tipo modificación atributo | K34: Descripción | L34: Tipo de dato | M34: ¿Cuál?
A35: exported | B35: ToLogger | C35: no static | D35: no final | E35: Retorna información de la ruta (id, origen, destino, código IATA, tipo, código ruta) para registro en bitácora del sistema | L35: Otro | M35: []string

Sheet AirlineRoute
A1: <-Volver al inicio
A2: =Clases!$A$1 -> Clase | B2: =Clases!A12 -> AirlineRoute
A3: =Clases!$B$1 -> Estereotipo | B3: struct
A4: =Clases!$C$1 -> Desripción | B4: =Clases!C12 -> Estructura que representa una ruta aérea operada por una aerolínea específica, incluyendo los datos de la ruta, la aerolínea asignada y el estado de operación.
A5: Modificador acceso: | B5: exported
A6: Tipo clase: | B6: N/A
A7: Relaciones
A8: Relación | B8: Tipo relación | E8: Estructura
A9: Necesita de | B9: Asociación | E9: =HYPERLINK("#'"&F9&"'!A1", F9) -> Route | F9: Route
A10: Necesita de | B10: Asociación | E10: =HYPERLINK("#'"&F10&"'!A1", F10) -> Airline | F10: Airline
A11: Es usada por | B11: Asociación | E11: =HYPERLINK("#'"&F11&"'!A1", F11) -> DailyLogbookDetail | F11: DailyLogbookDetail
A12: Atributos
A13: Modificador de acceso | B13: Nombre | C13: Tipo de dato | E13: Tipo modificación atributo | F13: Tipo acceso atributo | G13: Valor por defecto | J13: Descripción atributo
C14: Tipo de dato | D14: ¿Cuál?
A15: exported | B15: ID | C15: String | E15: no final | F15: no static | J15: Identificador único de la ruta de aerolínea
A16: exported | B16: RouteID | C16: String | E16: no final | F16: no static | J16: Identificador de la ruta física asociada
A17: exported | B17: AirlineID | C17: String | E17: no final | F17: no static | J17: Identificador de la aerolínea asociada
A18: exported | B18: Status | C18: boolean/Boolean | E18: no final | F18: no static | J18: Indica si la asignación de ruta está activa
A19: exported | B19: OriginIataCode | C19: String | E19: no final | F19: no static | J19: Código IATA del aeropuerto de origen (campo de consulta)
A20: exported | B20: DestinationIataCode | C20: String | E20: no final | F20: no static | J20: Código IATA del aeropuerto de destino (campo de consulta)
A21: exported | B21: RouteCode | C21: String | E21: no final | F21: no static | J21: Código de la ruta (campo de consulta)
A22: exported | B22: OriginAirportName | C22: String | E22: no final | F22: no static | J22: Nombre del aeropuerto de origen (campo de consulta)
A23: exported | B23: DestinationAirportName | C23: String | E23: no final | F23: no static | J23: Nombre del aeropuerto de destino (campo de consulta)
A24: exported | B24: AirportType | C24: String | E24: no final | F24: no static | J24: Tipo de operación (campo de consulta)
A25: exported | B25: EstimatedFlightTime | C25: String | E25: no final | F25: no static | J25: Tiempo estimado de vuelo (campo de consulta)
A26: exported | B26: AirlineCode | C26: String | E26: no final | F26: no static | J26: Código IATA de la aerolínea (campo de consulta)
A27: exported | B27: AirlineName | C27: String | E27: no final | F27: no static | J27: Nombre de la aerolínea (campo de consulta)
A28: Constructores
A29: Modificador de acceso | B29: Nombre | C29: Tipo constructor | D29: Descripción | E29: Parámetros | M29: Excepciones
E30: Nombre | F30: Tipo de dato | G30: ¿Cuál? | H30: Tipo parámetro | I30: Tipo modificación atributo | J30: Descripción
A31: N/A | D31: Las estructuras en Go no usan constructores explícitos
A32: Métodos accesores
A33: Modificador de acceso | B33: Nombre | C33: Tipo método accesor | D33: Tipo modificación método | E33: Descripción | F33: Parámetros | L33: Tipo dato de retorno | N33: Excepciones
F34: Nombre | G34: Tipo de dato | H34: ¿Cuál? | I34: Tipo parámetro | J34: Tipo modificación atributo | K34: Descripción | L34: Tipo de dato | M34: ¿Cuál?
A35: N/A | E35: En Go los campos son accesibles directamente, no se usan getters/setters
A36: Métodos
A37: Modificador de acceso | B37: Nombre | C37: Tipo acceso método | D37: Tipo modificación método | E37: Descripción | F37: Parámetros | L37: Tipo dato de retorno | N37: Excepciones
F38: Nombre | G38: Tipo de dato | H38: ¿Cuál? | I38: Tipo parámetro | J38: Tipo modificación atributo | K38: Descripción | L38: Tipo de dato | M38: ¿Cuál?
A39: exported | B39: Tologger | C39: no static | D39: no final | E39: Retorna información de la ruta de aerolínea (id, ruta, aerolínea, código, estado) para registro en bitácora del sistema | L39: Otro | M39: []string

Sheet DailyLogbook
A1: <-Volver al inicio
A2: =Clases!$A$1 -> Clase | B2: =Clases!A13 -> DailyLogbook
A3: =Clases!$B$1 -> Estereotipo | B3: struct
A4: =Clases!$C$1 -> Desripción | B4: =Clases!C13 -> Estructura que representa una página diaria de la bitácora de vuelo de un piloto, con la fecha del registro, la página del libro y su estado.
A5: Modificador acceso: | B5: exported
A6: Tipo clase: | B6: N/A
A7: Relaciones
A8: Relación | B8: Tipo relación | E8: Estructura
A9: Necesita de | B9: Asociación | E9: =HYPERLINK("#'"&F9&"'!A1", F9) -> Employee | F9: Employee
A10: Es usada por | B10: Asociación | E10: =HYPERLINK("#'"&F10&"'!A1", F10) -> DailyLogbookDetail | F10: DailyLogbookDetail
A11: Atributos
A12: Modificador de acceso | B12: Nombre | C12: Tipo de dato | E12: Tipo modificación atributo | F12: Tipo acceso atributo | G12: Valor por defecto | J12: Descripción atributo
C13: Tipo de dato | D13: ¿Cuál?
A14: exported | B14: ID | C14: String | E14: no final | F14: no static | J14: Identificador único de la bitácora diaria
A15: exported | B15: LogDate | C15: Date | E15: no final | F15: no static | J15: Fecha del registro de la bitácora
A16: exported | B16: EmployeeID | C16: String | E16: no final | F16: no static | J16: Identificador del piloto asociado
A17: exported | B17: BookPage | C17: Integer | E17: no final | F17: no static | J17: Número de página del libro de vuelo (opcional)
A18: exported | B18: Status | C18: boolean/Boolean | E18: no final | F18: no static | J18: Indica si la bitácora está activa
A19: Constructores
A20: Modificador de acceso | B20: Nombre | C20: Tipo constructor | D20: Descripción | E20: Parámetros | M20: Excepciones
E21: Nombre | F21: Tipo de dato | G21: ¿Cuál? | H21: Tipo parámetro | I21: Tipo modificación atributo | J21: Descripción
A22: N/A | D22: Las estructuras en Go no usan constructores explícitos
A23: Métodos accesores
A24: Modificador de acceso | B24: Nombre | C24: Tipo método accesor | D24: Tipo modificación método | E24: Descripción | F24: Parámetros | L24: Tipo dato de retorno | N24: Excepciones
F25: Nombre | G25: Tipo de dato | H25: ¿Cuál? | I25: Tipo parámetro | J25: Tipo modificación atributo | K25: Descripción | L25: Tipo de dato | M25: ¿Cuál?
A26: N/A | E26: En Go los campos son accesibles directamente, no se usan getters/setters
A27: Métodos
A28: Modificador de acceso | B28: Nombre | C28: Tipo acceso método | D28: Tipo modificación método | E28: Descripción | F28: Parámetros | L28: Tipo dato de retorno | N28: Excepciones
F29: Nombre | G29: Tipo de dato | H29: ¿Cuál? | I29: Tipo parámetro | J29: Tipo modificación atributo | K29: Descripción | L29: Tipo de dato | M29: ¿Cuál?
A30: exported | B30: SetID | C30: no static | D30: no final | E30: Genera un identificador único para la bitácora diaria usando UUID | L30: void
A31: exported | B31: ToLogger | C31: no static | D31: no final | E31: Retorna información de la bitácora (id, empleado, fecha) para registro en bitácora del sistema | L31: Otro | M31: []string
A32: exported | B32: IsActive | C32: no static | D32: no final | E32: Verifica si la bitácora diaria se encuentra activa | L32: boolean/Boolean
A33: exported | B33: StatusString | C33: no static | D33: no final | E33: Retorna el estado de la bitácora como texto (active/inactive) | L33: String

Sheet DailyLogbookDetail
A1: <-Volver al inicio
A2: =Clases!$A$1 -> Clase | B2: =Clases!A14 -> DailyLogbookDetail
A3: =Clases!$B$1 -> Estereotipo | B3: struct
A4: =Clases!$C$1 -> Desripción | B4: =Clases!C14 -> Estructura que representa un segmento de vuelo individual dentro de una bitácora diaria. Es la entidad central del sistema, contiene el número de vuelo, la ruta , la aeronave utilizada, los tiempos de operación y el rol del piloto.
A5: Modificador acceso: | B5: exported
A6: Tipo clase: | B6: N/A
A7: Relaciones
A8: Relación | B8: Tipo relación | E8: Estructura
A9: Necesita de | B9: Asociación | E9: =HYPERLINK("#'"&F9&"'!A1", F9) -> DailyLogbook | F9: DailyLogbook
A10: Necesita de | B10: Asociación | E10: =HYPERLINK("#'"&F10&"'!A1", F10) -> AirlineRoute | F10: AirlineRoute
A11: Necesita de | B11: Asociación | E11: =HYPERLINK("#'"&F11&"'!A1", F11) -> TailNumber | F11: TailNumber
A12: Necesita de | B12: Dependencia | E12: =HYPERLINK("#'"&F12&"'!A1", F12) -> PilotRole | F12: PilotRole
A13: Necesita de | B13: Dependencia | E13: =HYPERLINK("#'"&F13&"'!A1", F13) -> CrewRole | F13: CrewRole
A14: Necesita de | B14: Dependencia | E14: =HYPERLINK("#'"&F14&"'!A1", F14) -> ApproachType | F14: ApproachType
A15: Atributos
A16: Modificador de acceso | B16: Nombre | C16: Tipo de dato | E16: Tipo modificación atributo | F16: Tipo acceso atributo | G16: Valor por defecto | J16: Descripción atributo
C17: Tipo de dato | D17: ¿Cuál?
A18: exported | B18: ID | C18: String | E18: no final | F18: no static | J18: Identificador único del detalle de bitácora
A19: exported | B19: DailyLogbookID | C19: String | E19: no final | F19: no static | J19: Identificador de la bitácora diaria
A20: exported | B20: FlightRealDate | C20: String | E20: no final | F20: no static | J20: Fecha real del vuelo en formato YYYY-MM-DD
A21: exported | B21: FlightNumber | C21: String | E21: no final | F21: no static | J21: Número del vuelo
A22: exported | B22: AirlineRouteID | C22: String | E22: no final | F22: no static | J22: Identificador de la ruta de aerolínea asignada
A23: exported | B23: TailNumberID | C23: String | E23: no final | F23: no static | J23: Identificador de la matrícula de la aeronave
A24: exported | B24: Passengers | C24: Integer | E24: no final | F24: no static | J24: Cantidad de pasajeros en el vuelo (opcional)
A25: exported | B25: OutTime | C25: String | E25: no final | F25: no static | J25: Hora de salida de bloque - OUT (opcional)
A26: exported | B26: TakeOffTime | C26: String | E26: no final | F26: no static | J26: Hora de despegue - OFF (opcional)
A27: exported | B27: LandingTime | C27: String | E27: no final | F27: no static | J27: Hora de aterrizaje - ON (opcional)
A28: exported | B28: InTime | C28: String | E28: no final | F28: no static | J28: Hora de llegada a bloque - IN (opcional)
A29: exported | B29: PilotRole | C29: Otro | D29: PilotRole | E29: no final | F29: no static | J29: Rol del piloto en el segmento (PF, PM, PFTO, PFL)
A30: exported | B30: CrewRole | C30: Otro | D30: CrewRole | E30: no final | F30: no static | J30: Posición de tripulación (captain, first officer)
A31: exported | B31: CompanionName | C31: String | E31: no final | F31: no static | J31: Nombre del compañero de tripulación (opcional)
A32: exported | B32: AirTime | C32: String | E32: no final | F32: no static | J32: Tiempo de vuelo calculado ON - OFF (opcional)
A33: exported | B33: BlockTime | C33: String | E33: no final | F33: no static | J33: Tiempo de bloque calculado IN - OUT (opcional)
A34: exported | B34: ApproachTIme | C34: Otro | D34: ApproachType | E34: no final | F34: no static | J34: Tipo de aproximación en aterrizaje (APV, VISUAL)
A35: exported | B35: FlightType | C35: String | E35: no final | F35: no static | J35: Tipo de vuelo (COMMERCIAL, TRAINING, FERRY, CHECK, POSITIONING)
A36: exported | B36: EmployeeLogbookID | C36: String | E36: no final | F36: no static | J36: Identificador del logbook del empleado (opcional)
A37: exported | B37: LogDate | C37: String | E37: no final | F37: no static | J37: Fecha del registro (campo de consulta)
A38: exported | B38: RouteCode | C38: String | E38: no final | F38: no static | J38: Código de la ruta (campo de consulta)
A39: exported | B39: OriginIataCode | C39: String | E39: no final | F39: no static | J39: Código IATA del aeropuerto de origen (campo de consulta)
A40: exported | B40: DestinationIataCode | C40: String | E40: no final | F40: no static | J40: Código IATA del aeropuerto de destino (campo de consulta)
...

Sheet EmployeeFlightSummary
A1: <-Volver al inicio
A2: =Clases!$A$1 -> Clase | B2: =Clases!A15 -> EmployeeFlightSummary
A3: =Clases!$B$1 -> Estereotipo | B3: struct
A4: =Clases!$C$1 -> Desripción | B4: =Clases!C15 -> Estructura que representa el resumen acumulado de horas de vuelo de un empleado en un período determinado, incluyendo tiempo de vuelo, tiempo de bloque, cantidad de vuelos y aterrizajes realizados.
A5: Modificador acceso: | B5: exported
A6: Tipo clase: | B6: N/A
A7: Relaciones
A8: Relación | B8: Tipo relación | E8: Estructura
A9: Necesita de | B9: Asociación | E9: =HYPERLINK("#'"&F9&"'!A1", F9) -> Employee | F9: Employee
A10: Necesita de | B10: Dependencia | E10: =HYPERLINK("#'"&F10&"'!A1", F10) -> PeriodInfo | F10: PeriodInfo
A11: Atributos
A12: Modificador de aceso | B12: Nombre | C12: Tipo de dato | E12: Tipo modificación atributo | F12: Tipo acceso atributo | G12: Valor por defecto | J12: Descripción atributo
C13: Tipo de dato | D13: ¿Cuál?
A14: exported | B14: ID | C14: String | E14: no final | F14: no static | J14: Identificador único del resumen de vuelo
A15: exported | B15: EmployeeID | C15: String | E15: no final | F15: no static | J15: Identificador del piloto asociado
A16: exported | B16: PeriodType | C16: String | E16: no final | F16: no static | J16: Tipo de período (MONTHLY, QUARTERLY, ANNUAL, PERIOD_1_15, PERIOD_16_31)
A17: exported | B17: PeriodYear | C17: Integer | E17: no final | F17: no static | J17: Año del período
A18: exported | B18: PeriodNumber | C18: Integer | E18: no final | F18: no static | J18: Número del período dentro del año
A19: exported | B19: PeriodStart | C19: String | E19: no final | F19: no static | J19: Fecha de inicio del período (YYYY-MM-DD)
A20: exported | B20: PeriodEnd | C20: String | E20: no final | F20: no static | J20: Fecha de fin del período (YYYY-MM-DD)
A21: exported | B21: TotalAirTime | C21: Integer | E21: no final | F21: no static | J21: Tiempo total de vuelo en minutos
A22: exported | B22: TotalBlockTIme | C22: Integer | E22: no final | F22: no static | J22: Tiempo total de bloque en minutos
A23: exported | B23: TotalFlights | C23: Integer | E23: no final | F23: no static | J23: Número total de vuelos
A24: exported | B24: TotalLandings | C24: Integer | E24: no final | F24: no static | J24: Número total de aterrizajes
A25: exported | B25: CatApproaches | C25: Integer | E25: no final | F25: no static | J25: Número de aproximaciones de categoría
... A27: exported | B27: LastUpdated | C27: String | E27: no final | F27: no static | J27: Fecha de última actualización del resumen (opcional
A28: Constructores
A29: Modificador de aceso | B29: Nombre | C29: Tipo constructor | D29: Descripción | E29: Parámetros | M29: Excepciones
E30: Nombre | F30: Tipo de dato | G30: ¿Cuál? | H30: Tipo parámetro | I30: Tipo modificación atributo | J30: Descripción
A31: N/A | D31: Las estructuras en Go no usan constructores explícitos
A33: Métodos accesores
A34: Modificador de aceso | B34: Nombre | C34: Tipo método accesor | D34: Tipo modificación método | E34: Descripción | F34: Parámetros | L34: Tipo dato de retorno | N34: Excepciones
F35: Nombre | G35: Tipo de dato | H35: ¿Cuál? | I35: Tipo parámetro | J35: Tipo modificación atributo | K35: Descripción | L35: Tipo de dato | M35: ¿Cuál?
A36: N/A | E36: En Go los campos son accesibles directamente, no se usan getters/setters
A37: Métodos
A38: Modificador de aceso | B38: Nombre | C38: Tipo acceso método | D38: Tipo modificación método | E38: Descripción | F38: Parámetros | L38: Tipo dato de retorno | N38: Excepciones
F39: Nombre | G39: Tipo de dato | H39: ¿Cuál? | I39: Tipo parámetro | J39: Tipo modificación atributo | K39: Descripción | L39: Tipo de dato | M39: ¿Cuál?
A40: exported | B40: SetID | C40: no static | D40: no final | E40: Genera un identificador único para el resumen de vuelo usando UUID | L40: void

Sheet FlightHoursSummary
A1: <-Volver al inicio
A2: =Clases!$A$1 -> Clase | B2: =Clases!A16 -> FlightHoursSummary
A3: =Clases!$B$1 -> Estereotipo | B3: struct
A4: =Clases!$C$1 -> Desripción | B4: =Clases!C16 -> Estructura que representa un resumen general de horas de vuelo con totales de minutos, vuelos y aterrizajes para un rango de fechas específico.
A5: Modificador acceso: | B5: exported
A6: Tipo clase: | B6: N/A
A7: Relaciones
A8: Relación | B8: Tipo relación | E8: Estructura
A9: Necesita de | B9: Dependencia | E9: =HYPERLINK("#'"&F9&"'!A1", F9) -> PilotRoleBreakdown | F9: PilotRoleBreakdown
A10: Necesita de | B10: Dependencia | E10: =HYPERLINK("#'"&F10&"'!A1", F10) -> FlightAlert | F10: FlightAlert
A11: Atributos
A12: Modificador de acceso | B12: Nombre | C12: Tipo de dato | E12: Tipo modificación atributo | F12: Tipo acceso atributo | G12: Valor por defecto | J12: Descripción atributo
C13: Tipo de dato | D13: ¿Cuál?
A14: exported | B14: Period | C14: String | E14: no final | F14: no static | J14: Tipo de período (monthly, bimonthly, quarterly, semiannual, annual)
A15: exported | B15: StartDate | C15: String | E15: no final | F15: no static | J15: Fecha de inicio del período
A16: exported | B16: EndDate | C16: String | E16: no final | F16: no static | J16: Fecha de fin del período
A17: exported | B17: TotalMinutes | C17: Integer | E17: no final | F17: no static | J17: Total de minutos de vuelo en el período
A18: exported | B18: TotalFlights | C18: Integer | E18: no final | F18: no static | J18: Total de vuelos en el período
A19: exported | B19: ToltalLandings | C19: Integer | E19: no final | F19: no static | J19: Total de aterrizajes en el período
A20: exported | B20: Breakdown | C20: Otro | D20: map[string]int | E20: no final | F20: no static | J20: Desglose de minutos por rol de piloto
A21: Constructores
A22: Modificador de acceso | B22: Nombre | C22: Tipo constructor | D22: Descripción | E22: Parámetros | M22: Excepciones
E23: Nombre | F23: Tipo de dato | G23: ¿Cuál? | H23: Tipo parámetro | I23: Tipo modificación atributo | J23: Descripción
A24: N/A | D24: Las estructuras en Go no usan constructores explícitos
A25: Métodos accesores
A26: Modificador de acceso | B26: Nombre | C26: Tipo método accesor | D26: Tipo modificación método | E26: Descripción | F26: Parámetros | L26: Tipo dato de retorno | N26: Excepciones
F27: Nombre | G27: Tipo de dato | H27: ¿Cuál? | I27: Tipo parámetro | J27: Tipo modificación atributo | K27: Descripción | L27: Tipo de dato | M27: ¿Cuál?
A28: N/A | E28: En Go los campos son accesibles directamente, no se usan getters/setters
A29: Métodos
A30: Modificador de acceso | B30: Nombre | C30: Tipo acceso método | D30: Tipo modificación método | E30: Descripción | F30: Parámetros | L30: Tipo dato de retorno | N30: Excepciones
F31: Nombre | G31: Tipo de dato | H31: ¿Cuál? | I31: Tipo parámetro | J31: Tipo modificación atributo | K31: Descripción | L31: Tipo de dato | M31: ¿Cuál?
A32: N/A | E32: Esta estructura no define métodos de instancia; las funciones asociadas (IsValidPeriod, FormatMinutesToHHMM) son funciones de paquete

Sheet Message
A1: <-Volver al inicio
A2: =Clases!$A$1 -> Clase | B2: =Clases!A20 -> Message
A3: =Clases!$B$1 -> Estereotipo | B3: struct
A4: =Clases!$C$1 -> Desripción | B4: =Clases!C20 -> Estructura que representa un mensaje del sistema utilizado para comunicar errores, información, advertencias o confirmaciones al usuario.
A5: Modificador acceso: | B5: exported
A6: Tipo clase: | B6: N/A
A7: Relaciones
A8: Relación | B8: Tipo relación | E8: Estructura
A9: Necesita de | B9: Dependencia | E9: =HYPERLINK("#'"&F9&"'!A1", F9) -> MessageType | F9: MessageType
A10: Atributos
A11: Modificador de acceso | B11: Nombre | C11: Tipo de dato | E11: Tipo modificación atributo | F11: Tipo acceso atributo | G11: Valor por defecto | J11: Descripción atributo
C12: Tipo de dato | D12: ¿Cuál?
A13: exported | B13: ID | C13: String | E13: no final | F13: no static | J13: Identificador único del mensaje
A14: exported | B14: Code | C14: String | E14: no final | F14: no static | J14: Código único del mensaje en el sistema
A15: exported | B15: Type | C15: Otro | D15: MessageType | E15: no final | F15: no static | J15: Tipo de mensaje (ERROR, EXITO, WARNING, INFO, DEBUG)
A16: exported | B16: Category | C16: String | E16: no final | F16: no static | J16: Categoría del mensaje
A17: exported | B17: Module | C17: String | E17: no final | F17: no static | J17: Módulo del sistema al que pertenece el mensaje
A18: exported | B18: Title | C18: String | E18: no final | F18: no static | J18: Título del mensaje
A19: exported | B19: Content | C19: String | E19: no final | F19: no static | J19: Contenido/cuerpo del mensaje
A20: exported | B20: Active | C20: boolean/Boolean | E20: no final | F20: no static | J20: Indica si el mensaje está activo
A21: exported | B21: CreatedAt | C21: Date | E21: no final | F21: no static | J21: Fecha de creación del mensaje
A22: exported | B22: UpdatedAt | C22: Date | E22: no final | F22: no static | J22: Fecha de última actualización del mensaje
A23: Constructores
A24: Modificador de acceso | B24: Nombre | C24: Tipo constructor | D24: Descripción | E24: Parámetros | M24: Excepciones
E25: Nombre | F25: Tipo de dato | G25: ¿Cuál? | H25: Tipo parámetro | I25: Tipo modificación atributo | J25: Descripción
A26: N/A | D26: Las estructuras en Go no usan constructores explícitos
A27: Métodos accesores
A28: Modificador de acceso | B28: Nombre | C28: Tipo método accesor | D28: Tipo modificación método | E28: Descripción | F28: Parámetros | L28: Tipo dato de retorno | N28: Excepciones
F29: Nombre | G29: Tipo de dato | H29: ¿Cuál? | I29: Tipo parámetro | J29: Tipo modificación atributo | K29: Descripción | L29: Tipo de dato | M29: ¿Cuál?
A30: N/A | E30: En Go los campos son accesibles directamente, no se usan getters/setters
A31: Métodos
A32: Modificador de acceso | B32: Nombre | C32: Tipo acceso método | D32: Tipo modificación método | E32: Descripción | F32: Parámetros | L32: Tipo dato de retorno | N32: Excepciones
F33: Nombre | G33: Tipo de dato | H33: ¿Cuál? | I33: Tipo parámetro | J33: Tipo modificación atributo | K33: Descripción | L33: Tipo de dato | M33: ¿Cuál?
A34: exported | B34: SetID | C34: no static | D34: no final | E34: Genera un identificador único para el mensaje usando UUID | L34: void
A35: exported | B35: ToLogger | C35: no static | D35: no final | E35: Retorna información del mensaje (id, código, tipo, módulo) para registro en bitácora del sistema | L35: Otro | M35: []string
A36: exported | B36: Validate | C36: no static | D36: no final | E36: Valida que el mensaje tenga un código asignado, retorna error si no lo tiene | L36: Otro | M36: error | N36: ErrMessageCodeRequired

Sheet PilotRoleBreakdown
A1: <-Volver al inicio
A2: =Clases!$A$1 -> Clase | B2: =Clases!A17 -> PilotRoleBreakdown
A3: =Clases!$B$1 -> Estereotipo | B3: struct
A4: =Clases!$C$1 -> Desripción | B4: =Clases!C17 -> Estructura que representa el desglose de tiempo de vuelo según el rol del piloto, indicando cuántos segundos y vuelos se realizaron en cada posición.
A5: Modificador acceso: | B5: exported
A6: Tipo clase: | B6: N/A
A7: Relaciones
A8: Relación | B8: Tipo relación | E8: Estructura
A9: Usada por | B9: Dependencia | E9: =HYPERLINK("#'"&F9&"'!A1", F9) -> FlightHoursSummary | F9: FlightHoursSummary
A10: Atributos
A11: Modificador de acceso | B11: Nombre | C11: Tipo de dato | E11: Tipo modificación atributo | F11: Tipo acceso atributo | G11: Valor por defecto | J11: Descripción atributo
C12: Tipo de dato | D12: ¿Cuál?
A13: exported | B13: PilotRole | C13: String | E13: no final | F13: no static | J13: Rol del piloto (PF, PM, PFTO, PFL)
A14: exported | B14: TotalSeconds | C14: Integer | E14: no final | F14: no static | J14: Total de segundos de vuelo para ese rol
A15: exported | B15: FlightCount | C15: Integer | E15: no final | F15: no static | J15: Número de vuelos para ese rol
A16: Constructores
A17: Modificador de acceso | B17: Nombre | C17: Tipo constructor | D17: Descripción | E17: Parámetros | M17: Excepciones
E18: Nombre | F18: Tipo de dato | G18: ¿Cuál? | H18: Tipo parámetro | I18: Tipo modificación atributo | J18: Descripción
A19: N/A | D19: Las estructuras en Go no usan constructores explícitos
A20: Métodos accesores
A21: Modificador de acceso | B21: Nombre | C21: Tipo método accesor | D21: Tipo modificación método | E21: Descripción | F21: Parámetros | L21: Tipo dato de retorno | N21: Excepciones
F22: Nombre | G22: Tipo de dato | H22: ¿Cuál? | I22: Tipo parámetro | J22: Tipo modificación atributo | K22: Descripción | L22: Tipo de dato | M22: ¿Cuál?
A23: N/A | E23: En Go los campos son accesibles directamente, no se usan getters/setters
A24: Métodos
A25: Modificador de acceso | B25: Nombre | C25: Tipo acceso método | D25: Tipo modificación método | E25: Descripción | F25: Parámetros | L25: Tipo dato de retorno | N25: Excepciones
F26: Nombre | G26: Tipo de dato | H26: ¿Cuál? | I26: Tipo parámetro | J26: Tipo modificación atributo | K26: Descripción | L26: Tipo de dato | M26: ¿Cuál?
A27: N/A | E27: Esta estructura no define métodos

Sheet FlightAlert
A1: <-Volver al inicio
A2: =Clases!$A$1 -> Clase | B2: =Clases!A18 -> FlightAlert
A3: =Clases!$B$1 -> Estereotipo | B3: struct
A4: =Clases!$C$1 -> Desripción | B4: =Clases!C18 -> Estructura que representa una alerta del sistema cuando las horas de vuelo se acercan o superan los límites establecidos.
A5: Modificador acceso: | B5: exported
A6: Tipo clase: | B6: N/A
A7: Relaciones
A8: Relación | B8: Tipo relación | E8: Estructura
A9: Usada por | B9: Dependencia | E9: =HYPERLINK("#'"&F9&"'!A1", F9) -> FlightHoursSummary | F9: FlightHoursSummary
A10: Atributos
A11: Modificador de acceso | B11: Nombre | C11: Tipo de dato | E11: Tipo modificación atributo | F11: Tipo acceso atributo | G11: Valor por defecto | J11: Descripción atributo
C12: Tipo de dato | D12: ¿Cuál?
A13: exported | B13: Type | C13: String | E13: no final | F13: no static | J13: Tipo de alerta (HOUR_LIMIT_15_DAYS, HOUR_LIMIT_MONTHLY, HOUR_LIMIT_QUARTERLY, HOUR_LIMIT_ANNUAL, MIN_LANDINGS_90_DAYS)
A14: exported | B14: Severity | C14: String | E14: no final | F14: no static | J14: Severidad de la alerta (WARNING, INFO, NOTICE)
A15: exported | B15: Message | C15: String | E15: no final | F15: no static | J15: Mensaje descriptivo de la alerta
A16: exported | B16: CurrentValue | C16: Integer | E16: no final | F16: no static | J16: Valor actual del piloto
A17: exported | B17: Threshold | C17: Integer | E17: no final | F17: no static | J17: Umbral regulatorio que genera la alerta
A18: Constructores
A19: Modificador de acceso | B19: Nombre | C19: Tipo constructor | D19: Descripción | E19: Parámetros | M19: Excepciones
E20: Nombre | F20: Tipo de dato | G20: ¿Cuál? | H20: Tipo parámetro | I20: Tipo modificación atributo | J20: Descripción
A21: N/A | D21: Las estructuras en Go no usan constructores explícitos
A22: Métodos accesores
A23: Modificador de acceso | B23: Nombre | C23: Tipo método accesor | D23: Tipo modificación método | E23: Descripción | F23: Parámetros | L23: Tipo dato de retorno | N23: Excepciones
F24: Nombre | G24: Tipo de dato | H24: ¿Cuál? | I24: Tipo parámetro | J24: Tipo modificación atributo | K24: Descripción | L24: Tipo de dato | M24: ¿Cuál?
A25: N/A | E25: En Go los campos son accesibles directamente, no se usan getters/setters
A26: Métodos
A27: Modificador de acceso | B27: Nombre | C27: Tipo acceso método | D27: Tipo modificación método | E27: Descripción | F27: Parámetros | L27: Tipo dato de retorno | N27: Excepciones
F28: Nombre | G28: Tipo de dato | H28: ¿Cuál? | I28: Tipo parámetro | J28: Tipo modificación atributo | K28: Descripción | L28: Tipo de dato | M28: ¿Cuál?
A29: N/A | E29: Esta estructura no define métodos

Sheet PeriodInfo
A1: <-Volver al inicio
A2: =Clases!$A$1 -> Clase | B2: =Clases!A19 -> PeriodInfo
A3: =Clases!$B$1 -> Estereotipo | B3: struct
A4: =Clases!$C$1 -> Desripción | B4: =Clases!C19 -> Estructura que representa la información de un período de resumen, con el tipo de período, año, número y rango de fechas.
A5: Modificador acceso: | B5: exported
A6: Tipo clase: | B6: N/A
A7: Relaciones
A8: Relación | B8: Tipo relación | E8: Estructura
A9: Usada por | B9: Dependencia | E9: =HYPERLINK("#'"&F9&"'!A1", F9) -> EmployeeFlightSummary | F9: EmployeeFlightSummary
