Workbook

Sheet Mapa empatía
A1: Atributos de calidad | B1: Administrador | C1: Piloto | D1: Total | E1: Porcentaje | F1: Total Características | G1: Total votos | H1: Administrador | I1: Piloto
A2: Disponibilidad | B2: 8 | C2: 14 | D2: =B2+C2 -> 22 | E2: =D2/$D$17 -> 0.093220339 | F2: =COUNTA(Disponibilidad!A2:A15) -> 5 | G2: =F17/2+1 -> 28.5 | H2: =Disponibilidad!C7 -> 5 | I2: =Disponibilidad!D7 -> 2
A3: Confiabilidad | B3: 7 | C3: 15 | D3: =B3+C3 -> 22 | E3: =D3/$D$17 -> 0.093220339 | F3: =COUNTA(Confiabilidad!A2:A13) -> 5 | H3: =Confiabilidad!C7 -> 5 | I3: =Confiabilidad!D7 -> 3
A4: Rendimiento | B4: 9 | C4: 12 | D4: =B4+C4 -> 21 | E4: =D4/$D$17 -> 0.088983051 | F4: =COUNTA(Rendimiento!A2:A15) -> 5 | H4: =Rendimiento!C7 -> 4 | I4: =Rendimiento!D7 -> 4
A5: Seguridad | B5: 6 | C5: 13 | D5: =B5+C5 -> 19 | E5: =D5/$D$17 -> 0.080508475 | F5: =COUNTA(Seguridad!A2:A14) -> 6 | H5: =Seguridad!C8 -> 4 | I5: =Seguridad!D8 -> 4 | K5: Nota: Esta votado de 1 a 15 donde a mayor numero tiene un mayor impacto
A6: Escalabilidad | B6: 11 | C6: 7 | D6: =B6+C6 -> 18 | E6: =D6/$D$17 -> 0.076271186 | F6: =COUNTA(Escalabilidad!A2:A15) -> 4 | H6: =Escalabilidad!C6 -> 4 | I6: =Escalabilidad!D6 -> 1
A7: Mantenibilidad | B7: 12 | C7: 5 | D7: =B7+C7 -> 17 | E7: =D7/$D$17 -> 0.072033898 | F7: =COUNTA(#REF!) -> 1 | H7: 0 | I7: 0
A8: Capacidad para ser soportado | B8: 13 | C8: 3 | D8: =B8+C8 -> 16 | E8: =D8/$D$17 -> 0.06779661 | F8: =COUNTA(#REF!) -> 1 | H8: 0 | I8: 0
A9: Capacidad para ser probado | B9: 14 | C9: 2 | D9: =B9+C9 -> 16 | E9: =D9/$D$17 -> 0.06779661 | F9: =COUNTA(#REF!) -> 1 | H9: 0 | I9: 0
A10: Capacidad de ser administrado | B10: 15 | C10: 1 | D10: =B10+C10 -> 16 | E10: =D10/$D$17 -> 0.06779661 | F10: =COUNTA('Capacidad de ser administrado'!A2:A15) -> 5 | H10: ='Capacidad de ser administrado'!C7 -> 5 | I10: ='Capacidad de ser administrado'!D7 -> 1
A11: Interoperabilidad | B11: 10 | C11: 6 | D11: =B11+C11 -> 16 | E11: =D11/$D$17 -> 0.06779661 | F11: =COUNTA(Interoperabilidad!A2:A15) -> 3 | H11: =Interoperabilidad!C5 -> 3 | I11: =Interoperabilidad!D5 -> 1
A12: Accesibilidad | B12: 4 | C12: 10 | D12: =B12+C11 -> 10 | E12: =D12/$D$17 -> 0.042372881 | F12: =COUNTA(Accesibilidad!A2:A13) -> 3 | H12: =Accesibilidad!C5 -> 3 | I12: =Accesibilidad!D5 -> 3
A13: Experiencia de usuario | B13: 3 | C13: 11 | D13: =B13+C13 -> 14 | E13: =D13/$D$17 -> 0.059322034 | F13: =COUNTA('Experiencia de usuario'!A2:A15) -> 10 | H13: ='Experiencia de usuario'!C12 -> 0 | I13: ='Experiencia de usuario'!D12 -> 10
A14: Conformidad | B14: 2 | C14: 9 | D14: =B14+C14 -> 11 | E14: =D14/$D$17 -> 0.046610169 | F14: =COUNTA(Conformidad!A2:A15) -> 4 | H14: =Conformidad!C6 -> 4 | I14: =Conformidad!D6 -> 1
A15: Internacionalización | B15: 1 | C15: 8 | D15: =B15+C15 -> 9 | E15: =D15/$D$17 -> 0.038135593 | F15: =COUNTA(#REF!) -> 1 | H15: 0 | I15: 0
A16: Flexibilidad | B16: 5 | C16: 4 | D16: =B16+C16 -> 9 | E16: =D16/$D$17 -> 0.038135593 | F16: =COUNTA(#REF!) -> 1 | H16: 0 | I16: 0
A17: Total | B17: =SUM(B1:B16) -> 120 | C17: =SUM(C1:C16) -> 120 | D17: =SUM(D1:D16) -> 236 | E17: =SUM(E1:E16) -> 1 | F17: =SUM(F2:F16) -> 55 | H17: =SUM(H2:H16) -> 37 | I17: =SUM(I2:I16) -> 30

Sheet Accesibilidad
A1: Características | B1: Escenarios | C1: Administrador | D1: Piloto | E1: Total
A2: Se requiere que los elementos interactivos tengan un tamaño y espaciado suficiente para evitar errores al ser seleccionados. | B2: Escenarios | C2: 1 | D2: 1 | E2: =C2+D2 -> 2
A3: Se requiere que la aplicación utilice tamaños de texto fijos y legibles, asegurando lectura cómoda sin necesidad de ajustes manuales. | B3: Escenarios | C3: 1 | D3: 1 | E3: =C3+D3 -> 2
A4: Se requiere que los mensajes de error se presenten de forma clara y comprensible, ofreciendo orientación para corregir la acción. | B4: Escenarios | C4: 1 | D4: 1 | E4: =C4+D4 -> 2
C5: =SUM(C2:C4) -> 3 | D5: =SUM(D2:D4) -> 3 | E5: =SUM(C5:D5) -> 6

Sheet Capacidad de ser administrado
A1: Características | B1: Escenarios | C1: Administrador | D1: Piloto | E1: Priorización | G1: NOTA: define que tan fácil es gestionar la aplicación, usualmente a través de una instrumentación suficiente y adecuada que se expone en un sistema de monitoreo para efectos mejoramiento del rendimiento e identificación de errores.
A2: Se requiere que la aplicación cuente con un panel de administración que permita gestionar aerolíneas, rutas aéreas, aeropuertos y modelos de aeronave, activándolos o desactivándolos según las necesidades operativas. | B2: Escenarios | C2: 1 | D2: 0 | E2: =C2+D2 -> 1
A3: Se requiere que la aplicación permita al administrador activar o desactivar recursos operativos (aerolíneas, rutas, aeropuertos, aeronaves) sin necesidad de modificar el código fuente, reflejando los cambios inmediatamente para los pilotos. | B3: Escenarios | C3: 1 | D3: 1 | E3: =C3+D3 -> 2
A4: Se requiere que la aplicación soporte la gestión del catálogo de recursos operativos (aerolíneas, rutas aéreas) con operaciones de activación/desactivación desde la interfaz administrativa. | B4: Escenarios | C4: 1 | D4: 0 | E4: =C4+D4 -> 1
A5: Se requiere que la aplicación permita la administración remota, ya que el panel de administración es accesible desde cualquier navegador web mediante la versión web de Flutter. | B5: Escenarios | C5: 1 | D5: 0 | E5: =C5+D5 -> 1
A6: Se requiere que la API del sistema cuente con documentación Swagger actualizada y accesible, facilitando la comprensión de los endpoints disponibles para la administración. | B6: Escenarios | C6: 1 | D6: 0 | E6: =C6+D6 -> 1
C7: =SUM(C2:C6) -> 5 | D7: =SUM(D2:D6) -> 1 | E7: =SUM(E2:E6) -> 6

Sheet Confiabilidad
A1: Características | B1: Escenarios | C1: Administrador | D1: Piloto | E1: Priorización
A2: Se requiere que los cálculos de horas de vuelo, alertas regulatorias y conteo de aterrizajes sean consistentes y precisos en cada consulta del piloto. | B2: Escenarios | C2: 1 | D2: 1 | E2: =C2+D2 -> 2
A3: Se requiere que la aplicación maneje los errores de comunicación con el backend de manera controlada, mostrando mensajes claros al piloto sin perder datos en proceso. | B3: Escenarios | C3: 1 | D3: 0 | E3: =C3+D3 -> 1
A4: Se requiere que la información de horas de vuelo, logbooks y registros de pilotos esté almacenada de forma persistente en base de datos MySQL, previniendo pérdida de datos. | B4: Escenarios | C4: 1 | D4: 1 | E4: =C4+D4 -> 2
A5: Se requiere que el backend procese las solicitudes concurrentemente mediante goroutines de Go, asegurando que un error en una solicitud no afecte las demás. | B5: Escenarios | C5: 1 | D5: 0 | E5: =C5+D5 -> 1
A6: Se requiere que la aplicación detecte errores en cálculos de horas, alertas o comunicación con Keycloak, y los presente al piloto de manera controlada sin cierres inesperados. | B6: Escenarios | C6: 1 | D6: 1 | E6: =C6+D6 -> 2
C7: =SUM(C2:C6) -> 5 | D7: =SUM(D2:D6) -> 3 | E7: =SUM(E2:E6) -> 8

Sheet Conformidad
A1: Características | B1: Escenarios | C1: Administrador | D1: Piloto | E1: Priorización
A2: Se requiere que la aplicación cumpla con las regulaciones de aviación civil vigentes en materia de registro de horas de vuelo, límites operacionales y documentación de la actividad del piloto. | B2: Escenario | C2: 1 | D2: 1 | E2: =SUM(C2:D2) -> 2
A3: Se requiere que los umbrales(limites) regulatorios (50h/15días, 90h/mes, 270h/trimestre, 1000h/año, 3 aterrizajes/90días) estén definidos como constantes en el código, facilitando su actualización ante cambios normativos. | B3: Escenario | C3: 1 | D3: 0 | E3: =SUM(C3:D3) -> 1
A4: Se requiere que la aplicación proteja los datos de los pilotos mediante autenticación JWT con cookies HttpOnly, cifrado de credenciales delegado a Keycloak, y validación de schemas JSON en cada endpoint. | B4: Escenario | C4: 1 | D4: 0 | E4: =SUM(C4:D4) -> 1
A5: Se requiere que la aplicación presente mensajes claros al piloto sobre el propósito del registro de horas y la importancia de la precisión de los datos ingresados para el cumplimiento regulatorio. | B5: Escenario | C5: 1 | D5: 0 | E5: =SUM(C5:D5) -> 1
C6: =SUM(C2:C5) -> 4 | D6: =SUM(D2:D5) -> 1 | E6: =SUM(E2:E5) -> 5
F7: NOTA: Grado en el que los datos tienen atributos que se adhieren a estándares, convenciones o normativas vigentes y reglas similares referentes a la calidad de datos en un contexto de uso específico.

Sheet Disponibilidad
A1: Característica | B1: Escenarios | C1: Administrador | D1: Piloto | E1: Priorización
A2: Se requiere que la aplicación pueda ejecutarse sin interrupciones durante eventos críticos o de alta demanda. | B2: Escenarios | C2: 1 | D2: 1 | E2: =SUM(C2:D2) -> 2
A3: Se requiere que la base de datos MySQL permita realizar copias de seguridad de la información de vuelos y pilotos sin interrumpir la operación de la aplicación. | B3: Escenarios | C3: 1 | D3: 0 | E3: =SUM(C3:D3) -> 1
A4: Se requiere que la aplicación cuente con endpoints de monitoreo (/health) y métricas (Prometheus) que permitan supervisar el estado del servicio en todo momento. | B4: Escenarios | C4: 1 | D4: 1 | E4: =SUM(C4:D4) -> 2
A5: Se requiere que la aplicación pueda ser restaurada rápidamente en caso de caída, mediante contenedores Docker y scripts de despliegue automatizado. | B5: Escenarios | C5: 1 | D5: 0 | E5: =SUM(C5:D5) -> 1
A6: Se requiere que la aplicación informe al piloto de manera clara cuando el servicio no esté disponible, mostrando mensajes de error descriptivos y permitiendo reintentar la operación. | B6: Escenarios | C6: 1 | D6: 0 | E6: =SUM(C6:D6) -> 1
C7: =SUM(C2:C6) -> 5 | D7: =SUM(D2:D4) -> 2 | E7: =SUM(C7:D7) -> 7
G9: NOTA: Disponibilidad: Capacidad del sistema o componente de estar operativo y accesible para su uso cuando se requiere.

Sheet Escalabilidad
A1: Características | B1: Escenarios | C1: Administrador | D1: Piloto | E1: Priorización
A2: Se requiere que la aplicación pueda ser desplegada en contenedores, permitiendo escalar horizontalmente agregando instancias adicionales según la demanda. | B2: Escenarios | C2: 1 | D2: 0 | E2: =C2+D2 -> 1
A3: Se requiere que la base de datos MySQL soporte el crecimiento del historial de vuelos y pilotos sin degradar los tiempos de consulta de resúmenes y alertas. | B3: Escenarios | C3: 1 | D3: 0 | E3: =C3+D3 -> 1
A4: Se requiere que la aplicación pueda someterse a pruebas que muestren cómo se comporta cuando tiene que atender a muchos usuarios al mismo tiempo, para asegurar que siga funcionando bien. | B4: Escenarios | C4: 1 | D4: 1 | E4: =C4+D4 -> 2
A5: Se requiere que la aplicación gestione adecuadamente múltiples pilotos consultando simultáneamente sus horas de vuelo y alertas, utilizando la concurrencia nativa de Go sin pérdida de datos. | B5: Escenarios | C5: 1 | D5: 0 | E5: =C5+D5 -> 1
C6: =SUM(C2:C5) -> 4 | D6: =SUM(D2:D5) -> 1 | E6: =SUM(E2:E5) -> 5

Sheet Experiencia de usuario
A1: Características | B1: Escenarios | C1: Administrador | D1: Piloto | E1: Priorización | G1: NOTA: se define como el conjunto de factores y elementos relacionados con el proceso de interacción de un usuario respecto a un producto o servicio.
A2: Se requiere que la aplicación mantenga una estética visual coherente con la identidad de la marca, mejorando la percepción de confianza. | B2: Escenarios | C2: 0 | D2: 1 | E2: =SUM(C2:D2) -> 1
A3: Se requiere que la aplicación mantenga una navegación consistente, con menús y controles ubicados de manera predecible. | B3: Escenarios | C3: 0 | D3: 1 | E3: =SUM(C3:D3) -> 1
A4: Se requiere que la aplicación minimice la cantidad de pasos necesarios para realizar las tareas más frecuentes. | B4: Escenarios | C4: 0 | D4: 1 | E4: =SUM(C4:D4) -> 1
A5: Se requiere que la aplicación evite sobrecargar la interfaz con elementos innecesarios que dificulten la interacción. | B5: Escenarios | C5: 0 | D5: 1 | E5: =SUM(C5:D5) -> 1
A6: Se requiere que la aplicación presente textos descriptivos y labels claros en cada sección, guiando al piloto sobre la función de cada elemento de la interfaz. | B6: Escenarios | C6: 0 | D6: 1 | E6: =SUM(C6:D6) -> 1
A7: Se requiere que la aplicación cuente con tiempos de respuesta ágiles, evitando retrasos que generen frustración en la experiencia del usuario. | B7: Escenarios | C7: 0 | D7: 1 | E7: =SUM(C7:D7) -> 1
A8: Se requiere que la aplicación utilice tamaños de fuente legibles, colores de alto contraste y espaciado adecuado para garantizar una buena experiencia visual a todos los pilotos. | B8: Escenarios | C8: 0 | D8: 1 | E8: =SUM(C8:D8) -> 1
A9: Se requiere que la aplicación proporcione retroalimentación inmediata a las acciones del usuario (mensajes de éxito, error o progreso) para mantener claridad en la interacción. | B9: Escenarios | C9: 0 | D9: 1 | E9: =SUM(C9:D9) -> 1
A10: Se requiere que la aplicación mantenga una experiencia visual predecible y consistente en todas sus secciones, utilizando el mismo sistema de diseño (colores, tipografía, iconografía) en cada pantalla. | B10: Escenarios | C10: 0 | D10: 1 | E10: =SUM(C10:D10) -> 1
A11: Se requiere que la aplicación mantenga consistencia entre plataformas y dispositivos, de forma que la experiencia sea homogénea en web, móvil o tablet. | B11: Escenarios | C11: 0 | D11: 1 | E11: =SUM(C11:D11) -> 1
C12: =SUM(C2:C11) -> 0 | D12: =SUM(D2:D11) -> 10 | E12: =SUM(E2:E11) -> 10

Sheet Interoperabilidad
A1: Características | B1: Escenario | C1: Administrador | D1: Piloto | E1: Priorización
A2: Se requiere que la aplicación se integre correctamente con Keycloak como proveedor de identidad (OIDC), asegurando la autenticación, registro, verificación de email y recuperación de contraseña del piloto. | B2: Escenario | C2: 1 | D2: 1 | E2: =SUM(C2:D2) -> 2
A3: Se requiere que la comunicación entre la aplicación y Keycloak utilice tokens JWT seguros y cookies HttpOnly para proteger la información de autenticación intercambiada. | B3: Escenario | C3: 1 | D3: 0 | E3: =SUM(C3:D3) -> 1
A4: Se requiere que la aplicación funcione correctamente en múltiples plataformas (Android, iOS, Web) conectándose al mismo backend Go mediante API REST, independientemente del sistema operativo del dispositivo. | B4: Escenario | C4: 1 | D4: 0 | E4: =SUM(C4:D4) -> 1
C5: =SUM(C2:C4) -> 3 | D5: =SUM(D2:D2) -> 1 | E5: =SUM(C5:D5) -> 4 | H5: NOTA: es la habilidad de que diversos componentes de un sistema diferentes sistemas funcionen correctamente al intercambiar información, comúnmente por medio de servicios. Un sistema interoperable hace fácil intercambiar y usar información interna y externamente.

Sheet Rendimiento
A1: Características | B1: Escenario | C1: Administrador | D1: Piloto | E1: Priorización
A2: Se requiere que la aplicación haga un uso eficiente de los recursos del servidor, utilizando Go con Gin framework y pool de conexiones MySQL para minimizar el consumo de memoria y CPU. | B2: Escenario | C2: 1 | D2: 1 | E2: =SUM(C2:D2) -> 2
A3: Se requiere que la aplicación maneje eficientemente el historial de vuelos del piloto, manteniendo tiempos de respuesta estables a medida que crece el número de registros. | B3: Escenario | C3: 0 | D3: 1 | E3: =SUM(C3:D3) -> 1
A4: Se requiere que la respuesta de la aplicación ante una solicitud del usuario no supere los 2 segundos en condiciones operativas normales, garantizando una experiencia fluida y ágil. | B4: Escenario | C4: 1 | D4: 1 | E4: =SUM(C4:D4) -> 2
A5: Se requiere que las consultas de resumen de horas de vuelo, alertas regulatorias y logbooks estén optimizadas con agregación SQL para reducir tiempos de espera. | B5: Escenario | C5: 1 | D5: 1 | E5: =SUM(C5:D5) -> 2 | G5: NOTA: es un indicador de la capacidad de respuesta del sistema para ejecutar una acción dentro de un intervalo de tiempo dado. Puede ser medida en términos de latencia o de respuesta.
A6: Se requiere que las métricas de rendimiento del servidor sean recolectadas mediante Prometheus sin afectar la experiencia del usuario con la aplicación. | B6: Escenario | C6: 1 | D6: 0 | E6: =SUM(C6:D6) -> 1
C7: =SUM(C2:C6) -> 4 | D7: =SUM(D2:D6) -> 4 | E7: =SUM(E2:E6) -> 8

Sheet Seguridad
A1: Característica | B1: Escenarios | C1: Administrador | D1: Piloto | E1: Priorización
A2: Se requiere que los usuarios puedan autenticarse mediante un nombre de usuario y una contraseña válidos, permitiendo el acceso a la aplicación solo a personas autorizadas. | B2: Escenarios | C2: 1 | D2: 1 | E2: =SUM(C2:D2) -> 2
A3: Se requiere que la aplicación permita el registro de nuevos pilotos con validación de correo electrónico (verificación por email via Keycloak) antes de activar la cuenta. | B3: Escenarios | C3: 0 | D3: 1 | E3: =SUM(C3:D3) -> 1
A4: Se requiere que los usuarios tengan la posibilidad de recuperar su contraseña, ya sea respondiendo preguntas de seguridad previamente configuradas o mediante un enlace enviado al correo electrónico registrado, garantizando la protección frente a accesos indebidos. | B4: Escenarios | C4: 0 | D4: 1 | E4: =SUM(C4:D4) -> 1
A5: Se requiere que las credenciales de los pilotos sean gestionadas por Keycloak con cifrado seguro, y que los tokens de sesión se transporten como cookies HttpOnly para evitar exposición. | B5: Escenarios | C5: 1 | D5: 0 | E5: =SUM(C5:D5) -> 1
A6: Se requiere que la aplicación implemente control de acceso basado en roles (RBAC), donde solo los administradores puedan gestionar aerolíneas, rutas y aeronaves, y los pilotos accedan únicamente a sus datos de vuelo. | B6: Escenarios | C6: 1 | D6: 0 | E6: =SUM(C6:D6) -> 1
A7: Se requiere que la aplicación cierre automáticamente la sesión del usuario tras un período determinado de inactividad, con el fin de evitar accesos no autorizados por descuido o abandono de sesión. | B7: Escenarios | C7: 1 | D7: 1 | E7: =SUM(C7:D7) -> 2
C8: =SUM(C2:C7) -> 4 | D8: =SUM(D2:D7) -> 4 | E8: =SUM(E2:E7) -> 8

Sheet ESC-CAL-ACCESIBILIDAD
A1: Accesibilidad
A3: Atributo de calidad: | D3: =$A$1 -> Accesibilidad
A4: Característica: | D4: =Accesibilidad!A2 -> Se requiere que los elementos interactivos tengan un tamaño y espaciado suficiente para evitar errores al ser seleccionados.
A5: Identificador del escenario de calidad: | D5: ESC-CAL-ACC-0001
A6: Nombre del escenario de calidad: | D6: Legibilidad de textos y datos en la aplicación
A7: Tipo escenario: | D7: Básico
A8: Objetivo | D8: Verificar que los textos y datos numéricos de la aplicación son legibles sin esfuerzo.
A9: Descripción: | D9: El piloto utiliza la app y todos los textos (etiquetas, horas, alertas, nombres de rutas) se muestran con tamaño de fuente adecuado y contraste suficiente.
A10: Criterio de éxito: | D10: Los textos principales tienen tamaño mínimo de 13px. El contraste de color cumple con ratio mínimo 4.5:1.
A11: Fuente del estímulo | C11: Estímulo | E11: Ambiente | G11: Artefacto | I11: Respuesta | K11: Medida de la respuesta | M11: ¿Cumplió? | N11: Tácticas y estrategia
A12: Piloto que utiliza la aplicación en condiciones normales. | C12: El piloto navega por las principales pantallas de la app (login, dashboard, alertas, logbook). | E12: Operación normal | G12: Aplicación móvil/web | I12: Todos los textos son legibles sin necesidad de zoom o ajustes manuales. | K12: Fuente mínima: 13px para texto normal, 22px para títulos. Contraste ≥ 4.5:1 entre texto y fondo. | N12: Flutter TextStyle con tamaños definidos: títulos 22px bold, body 13-16px, labels 12px. Colores de alto contraste: texto #1a1a2e sobre fondo #F5F8FF. AppPageHeader (core/widgets/app_page_header.dart) con color #1a1a2e para títulos.
A14: Atributo de calidad: | D14: =$A$1 -> Accesibilidad
A15: Característica: | D15: =Accesibilidad!A3 -> Se requiere que la aplicación utilice tamaños de texto fijos y legibles, asegurando lectura cómoda sin necesidad de ajustes manuales.
A16: Identificador del escenario de calidad: | D16: ESC-CAL-ACC-0002
A17: Nombre del escenario de calidad: | D17: Interfaz funcional en diferentes tamaños de pantalla
A18: Tipo escenario: | D18: Alternativo
A19: Objetivo | D19: Verificar que la interfaz se adapta correctamente a pantallas de diferentes tamaños (móvil, tablet, desktop).
A20: Descripción: | D20: El piloto accede a la app desde un dispositivo móvil y desde un navegador web. La disposición de elementos se adapta al tamaño de pantalla sin pérdida de funcionalidad.
A21: Criterio de éxito: | D21: En móvil los elementos se apilan verticalmente. En desktop se distribuyen en filas. Ningún botón o dato queda cortado.
A22: Fuente del estímulo | C22: Estímulo | E22: Ambiente | G22: Artefacto | I22: Respuesta | K22: Medida de la respuesta | M22: ¿Cumplió? | N22: Tácticas y estrategia
A23: Piloto que accede desde diferentes dispositivos. | C23: El piloto abre la pantalla de alertas en un teléfono móvil y luego en un navegador de escritorio. | E23: Operación normal | G23: Aplicación móvil/web | I23: En móvil: layout vertical (Column). En desktop: layout horizontal (Row) con tarjetas lado a lado. | K23: Responsive correcto en ancho ≤600px (móvil) y ≥1024px (desktop). Sin overflow visual ni elementos cortados. | N23: ResponsiveBreakpoints.isDesktop(constraints.maxWidth) en LayoutBuilder (core/responsive/responsive_breakpoints.dart). ResponsivePadding.page() adaptativo (core/responsive/responsive_padding.dart). Flutter cross-platform: un solo codebase para Android, iOS y Web.
A25: Atributo de calidad: | D25: =$A$1 -> Accesibilidad
A26: Característica: | D26: =Accesibilidad!A3 -> Se requiere que la aplicación utilice tamaños de texto fijos y legibles, asegurando lectura cómoda sin necesidad de ajustes manuales.
A27: Identificador del escenario de calidad: | D27: ESC-CAL-ACC-0003
A28: Nombre del escenario de calidad: | D28: Lectura clara de información en pantallas principales
A29: Tipo escenario: | D29: Básico
A30: Objetivo | D30: Verificar que todos los textos de la aplicación se muestran con tamaños fijos y legibles para el usuario.
A31: Descripción: | D31: El piloto accede a las principales pantallas de la aplicación (dashboard, alertas y logbook) y puede leer toda la información sin necesidad de acercar la pantalla o ajustar el tamaño del texto.
A32: Criterio de éxito: | D32: Los textos tienen tamaños definidos y consistentes en toda la aplicación, permitiendo una lectura clara.
A33: Fuente del estímulo | C33: Estímulo | E33: Ambiente | G33: Artefacto | I33: Respuesta | K33: Medida de la respuesta | M33: ¿Cumplió? | N33: Tácticas y estrategia
A34: Piloto que utiliza la aplicación en condiciones normales | C34: El piloto navega por diferentes pantallas de la aplicación | E34: Operación normal | G34: Aplicación móvil/web | I34: La aplicación muestra todos los textos con tamaños definidos y legibles | K34: Texto principal mínimo 14px, títulos mínimo 22px, sin necesidad de zoom | N34: Uso de estilos globales en Flutter con TextStyle definidos para títulos, subtítulos y contenido
A36: Atributo de calidad: | D36: =$A$1 -> Accesibilidad
A37: Característica: | D37: =Accesibilidad!A3 -> Se requiere que la aplicación utilice tamaños de texto fijos y legibles, asegurando lectura cómoda sin necesidad de ajustes manuales.
A38: Identificador del escenario de calidad: | D38: ESC-CAL-ACC-0004
A39: Nombre del escenario de calidad: | D39: Consistencia en tamaños de texto en toda la aplicación
A40: Tipo escenario: | D40: Alternativo
A41: Objetivo | D41: Verificar que el tamaño del texto se mantiene consistente en todas las secciones de la aplicación.
A42: Descripción: | D42: El piloto accede a diferentes módulos de la aplicación (perfil, alertas, historial de vuelo) y observa que el tamaño del texto mantiene un formato consistente.
A43: Criterio de éxito: | D43: No existen variaciones de tamaño inesperadas en textos que cumplen la misma función.
A44: Fuente del estímulo | C44: Estímulo | E44: Ambiente | G44: Artefacto | I44: Respuesta | K44: Medida de la respuesta | M44: ¿Cumplió? | N44: Tácticas y estrategia
...

Sheet ESC-CAL-CAPADMINISTRADO
A1: Capacidad de ser administrado
A3: Atributo de calidad: | D3: =$A$1 -> Capacidad de ser administrado
A4: Característica: | D4: ='Capacidad de ser administrado'!A3 -> Se requiere que la aplicación permita al administrador activar o desactivar recursos operativos (aerolíneas, rutas, aeropuertos, aeronaves) sin necesidad de modificar el código fuente, reflejando los cambios inmediatamente para los pilotos.
A5: Identificador del escenario de calidad: | D5: ESC-CAL-CADMI-0001
A6: Nombre del escenario de calidad: | D6: Gestión de aerolíneas, rutas y aeronaves desde la aplicación
A7: Tipo escenario: | D7: Básico
A8: Objetivo | D8: Verificar que el administrador puede gestionar (activar/desactivar) aerolíneas, rutas aéreas y modelos de aeronave directamente desde la aplicación.
A9: Descripción: | D9: El administrador accede a la app con rol 'admin' y gestiona los recursos del sistema: activa o desactiva aerolíneas, rutas aéreas, aeropuertos y modelos de aeronave disponibles para los pilotos.
A10: Criterio de éxito: | D10: El administrador puede activar y desactivar cada recurso. Los cambios se reflejan inmediatamente para los pilotos.
A11: Fuente del estímulo | C11: Estímulo | E11: Ambiente | G11: Artefacto | I11: Respuesta | K11: Medida de la respuesta | M11: ¿Cumplió? | N11: Tácticas y estrategia
A12: Administrador con rol 'admin' autenticado en la aplicación. | C12: El administrador activa o desactiva una aerolínea, ruta aérea, aeropuerto o modelo de aeronave. | E12: Operación normal | G12: Sistema (API + Frontend admin) | I12: El recurso cambia de estado (activo/inactivo). Los pilotos solo ven los recursos activos en sus listados. | K12: Cambio de estado confirmado con respuesta 200. Recurso actualizado visible en la app del piloto en menos de 5 segundos. | N12: Endpoints RBAC protegidos con middleware RequireRole('admin'): PATCH /airlines/:id/activate, /airlines/:id/deactivate, /airline-routes/:id/activate, /airports/:id/activate, /aircraft-models/:id/activate. Base de datos MySQL con campo 'status' booleano. AdminHomePage (admin_home_page.dart) como panel central.
A14: Atributo de calidad: | D14: =$A$1 -> Capacidad de ser administrado
A15: Característica: | D15: ='Capacidad de ser administrado'!A3 -> Se requiere que la aplicación permita al administrador activar o desactivar recursos operativos (aerolíneas, rutas, aeropuertos, aeronaves) sin necesidad de modificar el código fuente, reflejando los cambios inmediatamente para los pilotos.
A16: Identificador del escenario de calidad: | D16: ESC-CAL-CADMI-0002
A17: Nombre del escenario de calidad: | D17: Restricción de acceso administrativo por roles
A18: Tipo escenario: | D18: Alternativo
A19: Objetivo | D19: Verificar que un usuario con rol 'pilot' no puede acceder a las funcionalidades de administración.
A20: Descripción: | D20: Un piloto autenticado intenta acceder a los endpoints de administración (activar/desactivar aerolíneas, rutas, etc.). El sistema debe rechazar la solicitud por permisos insuficientes.
A21: Criterio de éxito: | D21: El sistema rechaza la solicitud con error 403 Forbidden. Ninguna acción administrativa se ejecuta.
A22: Fuente del estímulo | C22: Estímulo | E22: Ambiente | G22: Artefacto | I22: Respuesta | K22: Medida de la respuesta | M22: ¿Cumplió? | N22: Tácticas y estrategia
A23: Piloto autenticado que intenta acceder a funciones administrativas. | C23: El piloto envía una solicitud al endpoint PATCH /airlines/:id/activate. | E23: Operación normal | G23: Sistema (API Backend) | I23: El middleware RequireRole('admin') rechaza la solicitud con estado 403 y un mensaje de error claro. | K23: Respuesta HTTP 403 Forbidden. Mensaje de error descriptivo. Ningún recurso modificado en la base de datos. | N23: Middleware RequireRole('admin') en Gin que verifica el claim 'role' del JWT (middleware/jwt_middleware.go). Separación explícita de rutas: grupo 'pilot' vs grupo 'admin' en server.go. Validación en capa de middleware antes de llegar al handler.
A25: Atributo de calidad: | D25: =$A$1 -> Capacidad de ser administrado
A26: Característica: | D26: ='Capacidad de ser administrado'!A3 -> Se requiere que la aplicación permita al administrador activar o desactivar recursos operativos (aerolíneas, rutas, aeropuertos, aeronaves) sin necesidad de modificar el código fuente, reflejando los cambios inmediatamente para los pilotos.
A27: Identificador del escenario de calidad: | D27: ESC-CAL-CADMI-0003
A28: Nombre del escenario de calidad: | D28: Gestión dinámica de recursos sin intervención de desarrollo
A29: Tipo escenario: | D29: Básico
A30: Objetivo | D30: Verificar que los recursos operativos puedan modificarse desde el panel administrativo sin cambios en el código.
A31: Descripción: | D31: El administrador modifica el estado de una ruta aérea desde la interfaz administrativa sin necesidad de realizar despliegues o cambios en el código del sistema.
A32: Criterio de éxito: | D32: Los cambios se aplican directamente desde la interfaz administrativa.
A33: Fuente del estímulo | C33: Estímulo | E33: Ambiente | G33: Artefacto | I33: Respuesta | K33: Medida de la respuesta | M33: ¿Cumplió? | N33: Tácticas y estrategia
A34: Administrador del sistema | C34: Cambia el estado de una ruta aérea desde el panel administrativo | E34: Operación normal | G34: Sistema | I34: El sistema actualiza el recurso sin modificar el código del sistema | K34: Cambios visibles inmediatamente después de guardar | N34: Arquitectura basada en base de datos configurable
A36: Atributo de calidad: | D36: =$A$1 -> Capacidad de ser administrado
A37: Característica: | D37: ='Capacidad de ser administrado'!A3 -> Se requiere que la aplicación permita al administrador activar o desactivar recursos operativos (aerolíneas, rutas, aeropuertos, aeronaves) sin necesidad de modificar el código fuente, reflejando los cambios inmediatamente para los pilotos.
A38: Identificador del escenario de calidad: | D38: ESC-CAL-CADMI-0004
A39: Nombre del escenario de calidad: | D39: Gestión dinámica de recursos sin intervención de desarrollo
A40: Tipo escenario: | D40: Alternativo
A41: Objetivo | D41: Verificar que los recursos operativos puedan modificarse desde el panel administrativo sin cambios en el código.
A42: Descripción: | D42: El administrador modifica el estado de una ruta aérea desde la interfaz administrativa sin necesidad de realizar despliegues o cambios en el código del sistema.
A43: Criterio de éxito: | D43: Los cambios se aplican directamente desde la interfaz administrativa.
A44: Fuente del estímulo | C44: Estímulo | E44: Ambiente | G44: Artefacto | I44: Respuesta | K44: Medida de la respuesta | M44: ¿Cumplió? | N44: Tácticas y estrategia
...

Sheet ESC-CAL-CONFIABILIDAD
A1: Confiabilidad
A3: Atributo de calidad: | D3: =$A$1 -> Confiabilidad
A4: Característica: | D4: =Confiabilidad!A2 -> Se requiere que los cálculos de horas de vuelo, alertas regulatorias y conteo de aterrizajes sean consistentes y precisos en cada consulta del piloto.
A5: Identificador del escenario de calidad: | D5: ESC-CAL-CONF-0001
A6: Nombre del escenario de calidad: | D6: Cálculo correcto de horas de vuelo acumuladas
A7: Tipo escenario: | D7: Básico
A8: Objetivo | D8: Verificar que el sistema calcula correctamente las horas de vuelo totales y por rol del piloto (PF, PM, PFTO, PFL).
A9: Descripción: | D9: El piloto registra varios vuelos con diferentes roles y luego consulta el resumen de horas. El sistema debe sumar correctamente los minutos por rol y mostrar el total.
A10: Criterio de éxito: | D10: El total de horas mostrado coincide con la suma manual de los vuelos registrados. Los subtotales por rol son exactos.
A11: Fuente del estímulo | C11: Estímulo | E11: Ambiente | G11: Artefacto | I11: Respuesta | K11: Medida de la respuesta | M11: ¿Cumplió? | N11: Tácticas y estrategia
A12: Piloto que utiliza la aplicación | C12: El piloto navega a la sección de Flight Hours Summary y selecciona un período (mensual, trimestral, anual). | E12: Operación normal | G12: Sistema (API + Frontend) | I12: El sistema muestra el total de horas y el desglose por rol PF, PM, PFTO, PFL correctamente calculados. | K12: Los totales coinciden al 100% con la suma manual. Formato HH:MM consistente. | N12: Cálculo en backend con FormatMinutesToHHMM (flight_hours_summary.go). Agregación por PilotRoleBreakdown discriminando pilot_role. Frontend muestra valores con _buildStatCardsGrid (alerts_page.dart). Estado FlightHoursSummarySuccess porta los datos calculados.
A14: Atributo de calidad: | D14: =$A$1 -> Confiabilidad
A15: Característica: | D15: =Confiabilidad!A2 -> Se requiere que los cálculos de horas de vuelo, alertas regulatorias y conteo de aterrizajes sean consistentes y precisos en cada consulta del piloto.
A16: Identificador del escenario de calidad: | D16: ESC-CAL-CONF-0002
A17: Nombre del escenario de calidad: | D17: Consistencia en alertas regulatorias
A18: Tipo escenario: | D18: Alternativo
A19: Objetivo | D19: Verificar que las alertas regulatorias se generen correctamente según las horas registradas.
A20: Descripción: | D20: El piloto alcanza el límite de horas de vuelo permitido por regulación y el sistema genera una alerta automática.
A21: Criterio de éxito: | D21: La alerta aparece inmediatamente después de superar el límite configurado.
A22: Fuente del estímulo | C22: Estímulo | E22: Ambiente | G22: Artefacto | I22: Respuesta | K22: Medida de la respuesta | M22: ¿Cumplió? | N22: Tácticas y estrategia
A23: Piloto que registra un nuevo vuelo | C23: El sistema recalcula las horas acumuladas | E23: Operación normal | G23: Sistema | I23: Se genera una alerta regulatoria correspondiente | K23: Alerta generada inmediatamente después del cálculo | N23: Validaciones automáticas en backend
A25: Atributo de calidad: | D25: =$A$1 -> Confiabilidad
A26: Característica: | D26: =Confiabilidad!A3 -> Se requiere que la aplicación maneje los errores de comunicación con el backend de manera controlada, mostrando mensajes claros al piloto sin perder datos en proceso.
A27: Identificador del escenario de calidad: | D27: ESC-CAL-CONF-0003
A28: Nombre del escenario de calidad: | D28: Manejo de fallos de comunicación con backend
A29: Tipo escenario: | D29: Básico
A30: Objetivo | D30: Verificar que la aplicación maneje adecuadamente errores de comunicación con el servidor.
A31: Descripción: | D31: El piloto intenta consultar su logbook mientras ocurre un problema de conexión con el backend.
A32: Criterio de éxito: | D32: La aplicación muestra un mensaje claro sin cerrarse inesperadamente.
A33: Fuente del estímulo | C33: Estímulo | E33: Ambiente | G33: Artefacto | I33: Respuesta | K33: Medida de la respuesta | M33: ¿Cumplió? | N33: Tácticas y estrategia
A34: Piloto | C34: Solicita información del logbook | E34: Operación normal | G34: Sistema | I34: La aplicación muestra mensaje de error controlado | K34: Mensaje visible en menos de 2 segundos | N34: Manejo de errores HTTP en cliente
A36: Atributo de calidad: | D36: =$A$1 -> Confiabilidad
A37: Característica: | D37: =Confiabilidad!A3 -> Se requiere que la aplicación maneje los errores de comunicación con el backend de manera controlada, mostrando mensajes claros al piloto sin perder datos en proceso.
A38: Identificador del escenario de calidad: | D38: ESC-CAL-CONF-0004
A39: Nombre del escenario de calidad: | D39: Protección de datos durante fallos de comunicación
A40: Tipo escenario: | D40: Alternativo
A41: Objetivo | D41: Verificar que los datos en proceso no se pierdan durante fallos de comunicación.
A42: Descripción: | D42: El piloto está registrando un vuelo cuando se pierde la conexión con el backend.
A43: Criterio de éxito: | D43: Los datos ingresados permanecen almacenados hasta que la conexión se restablezca.
A44: Fuente del estímulo | C44: Estímulo | E44: Ambiente | G44: Artefacto | I44: Respuesta | K44: Medida de la respuesta | M44: ¿Cumplió? | N44: Tácticas y estrategia
...

Sheet ESC-CAL-CONFORMIDAD
A1: Conformidad
A3: Atributo de calidad: | D3: =$A$1 -> Conformidad
A4: Característica: | D4: =Conformidad!A2 -> Se requiere que la aplicación cumpla con las regulaciones de aviación civil vigentes en materia de registro de horas de vuelo, límites operacionales y documentación de la actividad del piloto.
A5: Identificador del escenario de calidad: | D5: ESC-CAL-CONFORM-0001
A6: Nombre del escenario de calidad: | D6: Registro conforme de horas de vuelo
A7: Tipo escenario: | D7: Básico
A8: Objetivo | D8: Verificar que la aplicación registre las horas de vuelo de acuerdo con la normativa de aviación civil.
A9: Descripción: | D9: El piloto registra un nuevo vuelo en la aplicación y el sistema almacena la información incluyendo horas de vuelo, fecha, aeronave y número de aterrizajes.
A10: Criterio de éxito: | D10: Los datos registrados cumplen con los campos requeridos por la normativa.
A11: Fuente del estímulo | C11: Estímulo | E11: Ambiente | G11: Artefacto | I11: Respuesta | K11: Medida de la respuesta | M11: ¿Cumplió? | N11: Tácticas y estrategia
A12: Piloto que utiliza la aplicación | C12: Registra un nuevo vuelo | E12: Operación normal | G12: Sistema | I12: El sistema guarda la información requerida por regulación | K12: Todos los campos obligatorios quedan almacenados | N12: Validación de campos obligatorios en backend
A14: Atributo de calidad: | D14: =$A$1 -> Conformidad
A15: Característica: | D15: =Conformidad!A2 -> Se requiere que la aplicación cumpla con las regulaciones de aviación civil vigentes en materia de registro de horas de vuelo, límites operacionales y documentación de la actividad del piloto.
A16: Identificador del escenario de calidad: | D16: ESC-CAL-CONFORM-0002
A17: Nombre del escenario de calidad: | D17: Verificación de límites operacionales regulatorios
A18: Tipo escenario: | D18: Alternativo
A19: Objetivo | D19: Verificar que el sistema controle los límites operacionales definidos por regulación.
A20: Descripción: | D20: El piloto registra un vuelo que supera el límite de horas permitido por normativa.
A21: Criterio de éxito: | D21: La aplicación genera una alerta indicando el incumplimiento regulatorio.
A22: Fuente del estímulo | C22: Estímulo | E22: Ambiente | G22: Artefacto | I22: Respuesta | K22: Medida de la respuesta | M22: ¿Cumplió? | N22: Tácticas y estrategia
A23: Piloto | C23: Registra vuelo que supera límite permitido | E23: Operación normal | G23: Sistema | I23: Se genera alerta informando el límite superado | K23: Alerta generada inmediatamente | N23: Validaciones regulatorias en backend
A25: Atributo de calidad: | D25: =$A$1 -> Conformidad
A26: Característica: | D26: =Conformidad!A3 -> Se requiere que los umbrales(limites) regulatorios (50h/15días, 90h/mes, 270h/trimestre, 1000h/año, 3 aterrizajes/90días) estén definidos como constantes en el código, facilitando su actualización ante cambios normativos.
A27: Identificador del escenario de calidad: | D27: ESC-CAL-CONFORM-0001
A28: Nombre del escenario de calidad: | D28: Uso de constantes regulatorias en cálculos
A29: Tipo escenario: | D29: Básico
A30: Objetivo | D30: Verificar que los cálculos regulatorios utilicen los valores definidos por normativa.
A31: Descripción: | D31: El sistema calcula las horas acumuladas del piloto utilizando los límites regulatorios definidos.
A32: Criterio de éxito: | D32: Los cálculos utilizan correctamente los valores establecidos en el código.
A33: Fuente del estímulo | C33: Estímulo | E33: Ambiente | G33: Artefacto | I33: Respuesta | K33: Medida de la respuesta | M33: ¿Cumplió? | N33: Tácticas y estrategia
A34: Sistema | C34: Calcula horas acumuladas del piloto | E34: Operación normal | G34: Sistema | I34: El cálculo utiliza constantes regulatorias | K34: Valores utilizados coinciden con normativa | N34: Uso de constantes definidas en código
A36: Atributo de calidad: | D36: =$A$1 -> Conformidad
A37: Característica: | D37: =Conformidad!A3 -> Se requiere que los umbrales(limites) regulatorios (50h/15días, 90h/mes, 270h/trimestre, 1000h/año, 3 aterrizajes/90días) estén definidos como constantes en el código, facilitando su actualización ante cambios normativos.
A38: Identificador del escenario de calidad: | D38: ESC-CAL-CONFORM-0004
A39: Nombre del escenario de calidad: | D39: Actualización de límites regulatorios en el sistema
A40: Tipo escenario: | D40: Alternativo
A41: Objetivo | D41: Verificar que los límites regulatorios puedan actualizarse fácilmente ante cambios normativos.
A42: Descripción: | D42: Un desarrollador actualiza un valor de límite regulatorio en el código.
A43: Criterio de éxito: | D43: El sistema utiliza el nuevo valor en los cálculos regulatorios.
A44: Fuente del estímulo | C44: Estímulo | E44: Ambiente | G44: Artefacto | I44: Respuesta | K44: Medida de la respuesta | M44: ¿Cumplió? | N44: Tácticas y estrategia
...

Sheet ESC-CAL-DISPONIBILIDAD
A1: Disponibilidad
A3: Atributo de calidad: | D3: =$A$1 -> Disponibilidad
A4: Característica: | D4: =Disponibilidad!A2 -> Se requiere que la aplicación pueda ejecutarse sin interrupciones durante eventos críticos o de alta demanda.
A5: Identificador del escenario de calidad: | D5: ESC-CAL-DISP-0001
A6: Nombre del escenario de calidad: | D6: Operación continua durante alta demanda
A7: Tipo escenario: | D7: Básico
A8: Objetivo | D8: Verificar que la aplicación continúe funcionando cuando múltiples pilotos acceden al sistema simultáneamente.
A9: Descripción: | D9: Varios pilotos acceden al sistema al mismo tiempo para consultar sus horas de vuelo o registrar nuevas actividades.
A10: Criterio de éxito: | D10: El sistema mantiene su funcionamiento sin interrupciones.
A11: Fuente del estímulo | C11: Estímulo | E11: Ambiente | G11: Artefacto | I11: Respuesta | K11: Medida de la respuesta | M11: ¿Cumplió? | N11: Tácticas y estrategia
A12: Piloto | C12: Realizan consultas y registros simultáneamente | E12: Operación normal | G12: Aplicación móvil/web | I12: El sistema procesa las solicitudes sin detener el servicio | K12: Tiempo de respuesta promedio menor a 3 segundos | N12: Arquitectura backend concurrente con Go
A14: Atributo de calidad: | D14: =$A$1 -> Disponibilidad
A15: Característica: | D15: =Disponibilidad!A2 -> Se requiere que la aplicación pueda ejecutarse sin interrupciones durante eventos críticos o de alta demanda.
A16: Identificador del escenario de calidad: | D16: ESC-CAL-DISP-0002
A17: Nombre del escenario de calidad: | D17: Mantenimiento de servicio durante picos de uso
A18: Tipo escenario: | D18: Alternativo
A19: Objetivo | D19: Verificar que el sistema mantenga disponibilidad durante picos de uso.
A20: Descripción: | D20: Durante un periodo de alta actividad varios pilotos acceden al sistema para consultar información.
A21: Criterio de éxito: | D21: El sistema continúa respondiendo a las solicitudes sin caídas.
A22: Fuente del estímulo | C22: Estímulo | E22: Ambiente | G22: Artefacto | I22: Respuesta | K22: Medida de la respuesta | M22: ¿Cumplió? | N22: Tácticas y estrategia
A23: Múltiples pilotos | C23: Acceden simultáneamente al sistema | E23: Conectividad intermitente | G23: Aplicación móvil/web | I23: El sistema mantiene operación normal | K23: Servicio disponible durante todo el evento | N23: Manejo concurrente de solicitudes
A25: Atributo de calidad: | D25: =$A$1 -> Disponibilidad
A26: Característica: | D26: =Disponibilidad!A3 -> Se requiere que la base de datos MySQL permita realizar copias de seguridad de la información de vuelos y pilotos sin interrumpir la operación de la aplicación.
A27: Identificador del escenario de calidad: | D27: ESC-CAL-DISP-0003
A28: Nombre del escenario de calidad: | D28: Respaldo de base de datos sin interrupción del servicio
A29: Tipo escenario: | D29: Básico
A30: Objetivo | D30: Verificar que la base de datos pueda generar copias de seguridad sin detener la aplicación.
A31: Descripción: | D31: El sistema realiza un respaldo de la base de datos mientras los pilotos continúan usando la aplicación.
A32: Criterio de éxito: | D32: El respaldo se realiza sin afectar el funcionamiento del sistema.
A33: Fuente del estímulo | C33: Estímulo | E33: Ambiente | G33: Artefacto | I33: Respuesta | K33: Medida de la respuesta | M33: ¿Cumplió? | N33: Tácticas y estrategia
A34: Piloto | C34: Inicia copia de seguridad | E34: Operación normal | G34: Aplicación móvil/web | I34: El respaldo se ejecuta sin detener el servicio | K34: Aplicación continúa disponible durante el respaldo | N34: Uso de herramientas de backup en MySQL
A36: Atributo de calidad: | D36: =$A$1 -> Disponibilidad
A37: Característica: | D37: =Disponibilidad!A3 -> Se requiere que la base de datos MySQL permita realizar copias de seguridad de la información de vuelos y pilotos sin interrumpir la operación de la aplicación.
A38: Identificador del escenario de calidad: | D38: ESC-CAL-DISP-0004
A39: Nombre del escenario de calidad: | D39: Mantenimiento de servicio durante picos de uso
A40: Tipo escenario: | D40: Alternativo
A41: Objetivo | D41: Verificar que las copias de seguridad permitan recuperar la información correctamente.
A42: Descripción: | D42: El administrador restaura una copia de seguridad para verificar la integridad de los datos.
A43: Criterio de éxito: | D43: Los datos restaurados coinciden con los datos originales.
A44: Fuente del estímulo | C44: Estímulo | E44: Ambiente | G44: Artefacto | I44: Respuesta | K44: Medida de la respuesta | M44: ¿Cumplió? | N44: Tácticas y estrategia
...

Sheet ESC-CAL-ESCALABILIDAD
A1: Escalabilidad
A3: Atributo de calidad: | D3: =$A$1 -> Escalabilidad
A4: Característica: | D4: =Escalabilidad!A2 -> Se requiere que la aplicación pueda ser desplegada en contenedores, permitiendo escalar horizontalmente agregando instancias adicionales según la demanda.
A5: Identificador del escenario de calidad: | D5: ESC-CAL-ESC-0001
A6: Nombre del escenario de calidad: | D6: Escalamiento horizontal del sistema
A7: Tipo escenario: | D7: Básico
A8: Objetivo | D8: Verificar que el sistema pueda aumentar su capacidad agregando nuevas instancias.
A9: Descripción: | D9: Escenario que simula un incremento en la cantidad de usuarios accediendo al sistema, lo que requiere desplegar nuevas instancias del backend mediante contenedores.
A10: Criterio de éxito: | D10: El sistema agrega nuevas instancias y mantiene el rendimiento del servicio.
A11: Fuente del estímulo | C11: Estímulo | E11: Ambiente | G11: Artefacto | I11: Respuesta | K11: Medida de la respuesta | M11: ¿Cumplió? | N11: Tácticas y estrategia
A12: Infraestructura del sistema | C12: Incremento de solicitudes de usuarios | E12: Prueba de carga | G12: Sistema (API Backend) | I12: El sistema despliega nuevas instancias del servicio | K12: Tiempo de respuesta menor a 3 segundos | N12: Escalamiento horizontal con contenedores
A14: Atributo de calidad: | D14: =$A$1 -> Escalabilidad
A15: Característica: | D15: =Escalabilidad!A2 -> Se requiere que la aplicación pueda ser desplegada en contenedores, permitiendo escalar horizontalmente agregando instancias adicionales según la demanda.
A16: Identificador del escenario de calidad: | D16: ESC-CAL-ESC-0002
A17: Nombre del escenario de calidad: | D17: Distribución de carga entre instancias
A18: Tipo escenario: | D18: Alternativo
A19: Objetivo | D19: Verificar que las solicitudes se distribuyan entre múltiples instancias.
A20: Descripción: | D20: Escenario que simula múltiples usuarios accediendo simultáneamente al sistema y distribuyendo las solicitudes entre las instancias disponibles.
A21: Criterio de éxito: | D21: Las solicitudes se distribuyen correctamente sin sobrecargar una sola instancia.
A22: Fuente del estímulo | C22: Estímulo | E22: Ambiente | G22: Artefacto | I22: Respuesta | K22: Medida de la respuesta | M22: ¿Cumplió? | N22: Tácticas y estrategia
A23: Piloto | C23: Acceso simultáneo de múltiples pilotos | E23: Operación normal con carga moderada | G23: Sistema (API Backend) | I23: El sistema distribuye las solicitudes entre instancias | K23: Carga balanceada entre instancias | N23: Balanceador de carga
A25: Atributo de calidad: | D25: =$A$1 -> Escalabilidad
A26: Característica: | D26: =Escalabilidad!A3 -> Se requiere que la base de datos MySQL soporte el crecimiento del historial de vuelos y pilotos sin degradar los tiempos de consulta de resúmenes y alertas.
A27: Identificador del escenario de calidad: | D27: ESC-CAL-ESC-0003
A28: Nombre del escenario de calidad: | D28: Consulta eficiente con grandes volúmenes de datos
A29: Tipo escenario: | D29: Básico
A30: Objetivo | D30: Verificar que el sistema mantenga tiempos de respuesta adecuados cuando la base de datos crece.
A31: Descripción: | D31: Escenario que evalúa el comportamiento del sistema cuando el historial de vuelos y registros de pilotos aumenta considerablemente.
A32: Criterio de éxito: | D32: Las consultas de resúmenes y alertas mantienen tiempos de respuesta aceptables.
A33: Fuente del estímulo | C33: Estímulo | E33: Ambiente | G33: Artefacto | I33: Respuesta | K33: Medida de la respuesta | M33: ¿Cumplió? | N33: Tácticas y estrategia
A34: Sistema | C34: Crecimiento del historial de vuelos | E34: Operación normal con carga moderada | G34: Sistema (API Backend) | I34: El sistema ejecuta consultas sin degradación significativa | K34: Tiempo de consulta menor a 3 segundos | N34: Indexación de tablas
A36: Atributo de calidad: | D36: =$A$1 -> Escalabilidad
A37: Característica: | D37: =Escalabilidad!A3 -> Se requiere que la base de datos MySQL soporte el crecimiento del historial de vuelos y pilotos sin degradar los tiempos de consulta de resúmenes y alertas.
A38: Identificador del escenario de calidad: | D38: ESC-CAL-ESC-0004
A39: Nombre del escenario de calidad: | D39: Optimización de consultas con gran volumen de datos
A40: Tipo escenario: | D40: Alternativo
A41: Objetivo | D41: Verificar que el sistema mantenga rendimiento en consultas complejas.
A42: Descripción: | D42: Escenario que evalúa consultas de resúmenes y alertas cuando la base de datos contiene una gran cantidad de registros.
A43: Criterio de éxito: | D43: Las consultas se ejecutan sin afectar el rendimiento general del sistema.
A44: Fuente del estímulo | C44: Estímulo | E44: Ambiente | G44: Artefacto | I44: Respuesta | K44: Medida de la respuesta | M44: ¿Cumplió? | N44: Tácticas y estrategia
...

Sheet ESC-CAL-EXPERIENCIA DE USUARIO
A1: Experiencia de Usuario
A3: Atributo de calidad: | D3: =$A$1 -> Experiencia de Usuario
A4: Característica: | D4: ='Experiencia de usuario'!A2 -> Se requiere que la aplicación mantenga una estética visual coherente con la identidad de la marca, mejorando la percepción de confianza.
A5: Identificador del escenario de calidad: | D5: ESC-CAL-UX-0001
A6: Nombre del escenario de calidad: | D6: Consistencia visual con la identidad de marca
A7: Tipo escenario: | D7: Básico
A8: Objetivo | D8: Verificar que la interfaz de la aplicación mantenga coherencia visual con la identidad de la marca.
A9: Descripción: | D9: Escenario que evalúa si los elementos visuales de la interfaz (colores, tipografía e iconografía) siguen el sistema de diseño definido.
A10: Criterio de éxito: | D10: La interfaz mantiene una apariencia consistente alineada con la identidad visual.
A11: Fuente del estímulo | C11: Estímulo | E11: Ambiente | G11: Artefacto | I11: Respuesta | K11: Medida de la respuesta | M11: ¿Cumplió? | N11: Tácticas y estrategia
A12: Piloto que utiliza la aplicación en uso diario. | C12: Navega por diferentes secciones del sistema | E12: Operación normal | G12: La aplicación mantiene consistencia visual | I12: La aplicación mantiene consistencia visual | K12: Elementos visuales uniformes en todas las pantallas | N12: Uso de sistema de diseño
A14: Atributo de calidad: | D14: =$A$1 -> Experiencia de Usuario
A15: Característica: | D15: ='Experiencia de usuario'!A2 -> Se requiere que la aplicación mantenga una estética visual coherente con la identidad de la marca, mejorando la percepción de confianza.
A16: Identificador del escenario de calidad: | D16: ESC-CAL-UX-0002
A17: Nombre del escenario de calidad: | D17: Validación de consistencia visual
A18: Tipo escenario: | D18: Alternativo
A19: Objetivo | D19: Verificar que las nuevas pantallas respeten la identidad visual.
A20: Descripción: | D20: Escenario que analiza nuevas interfaces agregadas al sistema verificando que sigan el mismo sistema de diseño.
A21: Criterio de éxito: | D21: Las nuevas pantallas mantienen coherencia visual.
A22: Fuente del estímulo | C22: Estímulo | E22: Ambiente | G22: Artefacto | I22: Respuesta | K22: Medida de la respuesta | M22: ¿Cumplió? | N22: Tácticas y estrategia
A23: Equipo de diseño | C23: Revisión de nueva interfaz | E23: Operación normal | G23: Aplicación móvil/web | I23: La interfaz respeta el sistema de diseño | K23: Cumplimiento de guías visuales | N23: Guía de estilo
A25: Atributo de calidad: | D25: =$A$1 -> Experiencia de Usuario
A26: Característica: | D26: ='Experiencia de usuario'!A3 -> Se requiere que la aplicación mantenga una navegación consistente, con menús y controles ubicados de manera predecible.
A27: Identificador del escenario de calidad: | D27: ESC-CAL-UX-0003
A28: Nombre del escenario de calidad: | D28: Navegación consistente en la aplicación
A29: Tipo escenario: | D29: Básico
A30: Objetivo | D30: Verificar que los usuarios encuentren fácilmente las funciones del sistema.
A31: Descripción: | D31: Escenario que evalúa la navegación del piloto a través de diferentes secciones del sistema.
A32: Criterio de éxito: | D32: Los menús y controles se encuentran siempre en ubicaciones predecibles.
A33: Fuente del estímulo | C33: Estímulo | E33: Ambiente | G33: Artefacto | I33: Respuesta | K33: Medida de la respuesta | M33: ¿Cumplió? | N33: Tácticas y estrategia
A34: Piloto | C34: Navega entre secciones | E34: Operación normal | G34: Aplicación móvil/web | I34: El sistema mantiene estructura de navegación consistente | K34: Usuario encuentra opciones rápidamente | N34: Diseño de navegación consistente
A36: Atributo de calidad: | D36: =$A$1 -> Experiencia de Usuario
A37: Característica: | D37: ='Experiencia de usuario'!A3 -> Se requiere que la aplicación mantenga una navegación consistente, con menús y controles ubicados de manera predecible.
A38: Identificador del escenario de calidad: | D38: ESC-CAL-UX-0004
A39: Nombre del escenario de calidad: | D39: Ubicación predecible de controles
A40: Tipo escenario: | D40: Alternativo
A41: Objetivo | D41: Verificar que los controles principales mantengan la misma ubicación.
A42: Descripción: | D42: Escenario que analiza si los botones y menús mantienen su posición entre diferentes pantallas.
A43: Criterio de éxito: | D43: Los usuarios identifican rápidamente los controles.
A44: Fuente del estímulo | C44: Estímulo | E44: Ambiente | G44: Artefacto | I44: Respuesta | K44: Medida de la respuesta | M44: ¿Cumplió? | N44: Tácticas y estrategia
...

Sheet ESC-CAL-INTEROPERABILIDAD
A1: Interoperabilidad
A3: Atributo de calidad: | D3: =$A$1 -> Interoperabilidad
A4: Característica: | D4: =Interoperabilidad!A2 -> Se requiere que la aplicación se integre correctamente con Keycloak como proveedor de identidad (OIDC), asegurando la autenticación, registro, verificación de email y recuperación de contraseña del piloto.
A5: Identificador del escenario de calidad: | D5: ESC-CAL-INOP-0001
A6: Nombre del escenario de calidad: | D6: Integración exitosa con Keycloak para autenticación
A7: Tipo escenario: | D7: Básico
A8: Objetivo | D8: Verificar que la comunicación entre la aplicación y el servidor Keycloak funciona correctamente para todas las operaciones de autenticación.
A9: Descripción: | D9: El piloto realiza operaciones de login, registro, verificación de email y cambio de contraseña. Todas estas operaciones se comunican con Keycloak exitosamente.
A10: Criterio de éxito: | D10: Todas las operaciones de autenticación se completan correctamente con Keycloak como proveedor de identidad.
A11: Fuente del estímulo | C11: Estímulo | E11: Ambiente | G11: Artefacto | I11: Respuesta | K11: Medida de la respuesta | M11: ¿Cumplió? | N11: Tácticas y estrategia
A12: Piloto que realiza operaciones de autenticación. | C12: El piloto ejecuta el flujo completo: registrarse → verificar email → login → cambiar contraseña. | E12: Operación normal | G12: Sistema (API + Keycloak) | I12: Cada paso del flujo se completa exitosamente: registro crea usuario en Keycloak, verificación valida el token, login genera JWT, cambio de contraseña actualiza Keycloak. | K12: Todas las operaciones retornan status 200/201. Token JWT válido generado. Sesión activa verificable. | N12: Integración via OIDC con Keycloak. Endpoints: /register, /login, /auth/verify-email, /auth/change-password, /auth/password-reset, /auth/refresh. Validación de schemas JSON por endpoint. Cookie HttpOnly para transporte seguro (platform/cookie/cookie.go).
A14: Atributo de calidad: | D14: =$A$1 -> Interoperabilidad
A15: Característica: | D15: =Interoperabilidad!A2 -> Se requiere que la aplicación se integre correctamente con Keycloak como proveedor de identidad (OIDC), asegurando la autenticación, registro, verificación de email y recuperación de contraseña del piloto.
A16: Identificador del escenario de calidad: | D16: ESC-CAL-INOP-0002
A17: Nombre del escenario de calidad: | D17: Registro y verificación de usuario mediante Keycloak
A18: Tipo escenario: | D18: Alternativo
A19: Objetivo | D19: Verificar que el proceso de registro y verificación de correo funcione correctamente.
A20: Descripción: | D20: Escenario que evalúa el registro de un nuevo piloto en la aplicación y la verificación de su correo electrónico mediante Keycloak.
A21: Criterio de éxito: | D21: El usuario completa el registro y verifica su correo correctamente.
A22: Fuente del estímulo | C22: Estímulo | E22: Ambiente | G22: Artefacto | I22: Respuesta | K22: Medida de la respuesta | M22: ¿Cumplió? | N22: Tácticas y estrategia
A23: Piloto | C23: Se registra en la aplicación | E23: Operación normal | G23: Sistema (API + Keycloak) | I23: El sistema crea la cuenta y solicita verificación de correo | K23: Usuario registrado y verificado | N23: Gestión de identidad con Keycloak
A25: Atributo de calidad: | D25: =$A$1 -> Interoperabilidad
A26: Característica: | D26: =Interoperabilidad!A3 -> Se requiere que la comunicación entre la aplicación y Keycloak utilice tokens JWT seguros y cookies HttpOnly para proteger la información de autenticación intercambiada.
A27: Identificador del escenario de calidad: | D27: ESC-CAL-INOP-0003
A28: Nombre del escenario de calidad: | D28: Integración exitosa con Keycloak para autenticación
A29: Tipo escenario: | D29: Básico
A30: Objetivo | D30: Verificar que la autenticación utilice tokens seguros para proteger la sesión del usuario.
A31: Descripción: | D31: Escenario que evalúa la comunicación entre la aplicación y el servidor de autenticación durante el proceso de inicio de sesión.
A32: Criterio de éxito: | D32: La autenticación utiliza tokens JWT válidos y protegidos.
A33: Fuente del estímulo | C33: Estímulo | E33: Ambiente | G33: Artefacto | I33: Respuesta | K33: Medida de la respuesta | M33: ¿Cumplió? | N33: Tácticas y estrategia
A34: Sistema | C34: Validación de token JWT | E34: Operación normal | G34: Sistema (API + Keycloak) | I34: El sistema valida el token recibido | K34: Token válido permite acceso | N34: Autenticación con JWT
A36: Atributo de calidad: | D36: =$A$1 -> Interoperabilidad
A37: Característica: | D37: =Interoperabilidad!A3 -> Se requiere que la comunicación entre la aplicación y Keycloak utilice tokens JWT seguros y cookies HttpOnly para proteger la información de autenticación intercambiada.
A38: Identificador del escenario de calidad: | D38: ESC-CAL-INOP-0004
A39: Nombre del escenario de calidad: | D39: Protección de sesión con cookies HttpOnly
A40: Tipo escenario: | D40: Alternativo
A41: Objetivo | D41: Verificar que la sesión del usuario esté protegida contra accesos no autorizados.
A42: Descripción: | D42: Escenario que evalúa el almacenamiento del token de autenticación en cookies seguras para evitar accesos indebidos.
A43: Criterio de éxito: | D43: El token se almacena en cookies HttpOnly y no puede ser accedido por scripts del navegador.
