Workbook

Sheet Valores
A1: Tipo | B1: Contextos | C1: Estado | D1: Respuesta | E1: Tipo Dato | F1: Tipo Redondeo
A2: Referenciado | B2: Flight Hours | C2: Activo | D2: SI | E2: Carácter | F2: Truncar
A3: Propio | C3: Inactivo | D3: NO | E3: Texto | F3: Por debajo
E4: Alfanumérico | F4: Por encima
E5: Numérico Entero
E6: Numérico Decimal
E7: Lógico
E8: Fecha
E9: Fecha/Hora
E10: País
E11: Departamento
E12: Ciudad
E13: Tipo Aeropuerto
E14: Aeropuerto
E15: Ruta
E16: Vuelo
... E32: Bitácora Diaria

Sheet Modelo Dominio Anémico

Sheet Objetos Dominio
A1: << Modelo de dominio
A2: Nombre | B2: Tipo | C2: Contexto Origen | D2: Descripción | E2: Muestreo Datos | F2: Caracterización
A3: Aerolínea | B3: Propio | C3: Flight Hours | D3: Objeto de dominio que representa aquel grupo de personas expertas en mantenimiento , dominio y control tanto en lo social como en lo aeronáutico para un bien común. | E3: Ver | F3: Ver
A4: Aeropuerto | B4: Referenciado | D4: Objeto de dominio que representa a cada uno de los aeropuertos que están ubicados dentro de una ciudad. | E4: Ver | F4: Ver
A5: Bitácora Diaria | B5: Referenciado | D5: Objeto de dominio que representa la fecha, el empleado y pagina del libro sobre el vuelo realizado. | E5: Ver | F5: Ver
A6: Ciudad | B6: Referenciado | D6: Objeto de dominio que representa a cada una de las ciudades de los departamentos que pertenecen a un país, donde están ubicados los aeropuertos. | E6: Ver | F6: Ver
A7: Departamento | B7: Referenciado | D7: Objeto de dominio que representa a cada uno de los departamentos que pertenecen a un país, donde están ubicadas las ciudades a las que pertenecen los aeropuertos. | E7: Ver | F7: Ver
A8: Detalle Bitácora Diaria | B8: Referenciado | D8: Objeto de dominio que representa a quien pertenece la bitácora, la información del vuelo, la matrícula de la aeronave, la tripulación y que rango tienen, las horas de vuelo y su total. | E8: Ver | F8: Ver
A9: Empleado | B9: Propio | C9: Flight Hours | D9: Objeto de dominio que representa el nombre y el código de la persona que trabaja en la aerolínea | E9: Ver | F9: Ver
A10: Empleado Aerolínea | B10: Referenciado | D10: Objeto de dominio que representa el nombre y la fecha de inicio y salida y vigencia de ese empleado en la aerolínea asignada | E10: Ver | F10: Ver
A11: Fabricante | B11: Propio | C11: Flight Hours | D11: Objeto de dominio que representa al fabricante del avión | E11: Ver | F11: Ver
A12: Familia | B12: Referenciado | D12: Objeto de dominio que representa la familia a la que pertenece el avión | E12: Ver | F12: Ver
A13: Matricula | B13: Referenciado | D13: Objeto de domino que representa un código asignado a la aeronave por un país | E13: Ver | F13: Ver
A14: Modelo | B14: Referenciado | D14: Objeto de dominio que representa el tipo motor y nombre de la aeronave | E14: Ver | F14: Ver
A15: Motor | B15: Propio | C15: Flight Hours | D15: Objeto de dominio que representa que tipo de motor tiene el avión | E15: Ver | F15: Ver
A16: País | B16: Propio | C16: Flight Hours | D16: Objeto de dominio que representa a cada uno de los países donde están ubicados los aeropuertos. | E16: Ver | F16: Ver
A17: Ruta | B17: Referenciado | D17: Objeto de dominio que representa el origen y destino de un vuelo de un aeropuerto a otro realizado por una aerolínea nacional o internacionalmente | E17: Ver | F17: Ver
A18: Ruta Aerolínea | B18: Referenciado | D18: Objeto de dominio que representa el trayecto que realiza un avión de una aerolínea en una cantidad determinada de vuelos | E18: Ver | F18: Ver
A19: Tipo | B19: Referenciado | D19: Objeto de dominio que representa el tipo de aeronaves | E19: Ver | F19: Ver
A20: Tipo Aeropuerto | B20: Propio | C20: Flight Hours | D20: Objeto de dominio que representa el tipo de aeropuerto | E20: Ver | F20: Ver
A21: Tipo Integrante | B21: Propio | C21: Flight Hours | D21: Objeto de dominio que clasifica que característica principal debe llevar un integrante que pertenece a una tripulación. | E21: Ver | F21: Ver
A22: Vuelo | B22: Referenciado | D22: Objeto de dominio que representa el viaje realizado en un avión por una aerolínea | E22: Ver | F22: Ver

Sheet Aerolinea_Caracterización
A1: << Modelo de dominio | B1: << Objetos de dominio | C1: << Muestreo Datos
A2: ='Objetos Dominio'!$A$2 -> Nombre | B2: ='Objetos Dominio'!$A$3 -> Aerolínea
A3: ='Objetos Dominio'!$B$2 -> Tipo | B3: ='Objetos Dominio'!$B$3 -> Propio
A4: ='Objetos Dominio'!$C$2 -> Contexto Origen | B4: ='Objetos Dominio'!$C$3 -> Flight Hours
A5: ='Objetos Dominio'!$D$2 -> Descripción | B5: ='Objetos Dominio'!$D$3 -> Objeto de dominio que representa aquel grupo de personas expertas en mantenimiento , dominio y control tanto en lo social como en lo aeronáutico para un bien común.
A6: Atributo | B6: Tipo de Dato | C6: Longitud mínima | D6: Longitud máxima | E6: Precisión | F6: Cantidad cifras redondeo | G6: Tipo redondeo | H6: Rango Inicial | I6: Rango Final | J6: Formato | K6: Valor por defecto | L6: Regla especial | M6: ¿Quitar espacios en blanco al inicio? | N6: ¿Quitar espacios en blanco al final? | O6: ¿Auto generado? | P6: ¿Calculado? | Q6: ¿Obligatorio? | R6: ¿Modificable? | S6: ¿Sensible? | T6: ¿Identifica al registro? | U6: Descripción | V6: =A28 -> Consultar la Información de la Aerolínea | W6: =A30 -> Inactivar la Aerolínea | X6: =A33 -> Activar la Aerolínea
A7: =Aerolinea_Muestreo!$A$3 -> Id | B7: Alfanumérico | C7: 36 | D7: 36 | J7: XXXXXXXX-XXXX-XXXX-XXXX-XXXXXXXXXXXX Donde X es cualquier digito o una letra de la "A" a la "F" | M7: SI | N7: SI | O7: SI | P7: NO | Q7: SI | R7: NO | S7: NO | T7: SI | U7: =Aerolinea_Muestreo!$A$2 -> Corresponde a un identificador único del parámetro dentro del objeto de dominio Parámetro. | V7: Filtro/Listar/ No Mostrar | W7: Requerido | X7: Requerido
A8: =Aerolinea_Muestreo!$B$3 -> Nombre | B8: Alfanumérico | C8: 1 | D8: 30 | J8: Cualquier cadena que incluye caracteres alfanuméricos, espacios, tildes(A-Z / a-z) | M8: SI | N8: SI | O8: NO | P8: NO | Q8: SI | R8: NO | S8: NO | T8: NO | U8: =Aerolinea_Muestreo!$B$2 -> Corresponde al nombre de la aerolínea. | V8: Filtro/Listar/Mostrar[Orden{1}/CriterioOrdenamiento{1, ASC}/BusquedaGeneral{SI}/Ordenador{SI}/Reordenamiento{NO}] | W8: NO Requerido | X8: NO Requerido
A9: =Aerolinea_Muestreo!$C$3 -> Código | B9: Alfanumérico | C9: 2 | D9: 3 | J9: Cualquier cadena de caracteres, formado por letras mayúsculas(A-Z). | M9: SI | N9: SI | O9: NO | P9: NO | Q9: SI | R9: NO | S9: NO | T9: NO | U9: =Aerolinea_Muestreo!$C$2 -> Corresponde al código de la aerolínea. | V9: Filtro/Listar/Mostrar[Orden{2}/BusquedaGeneral{SI}/Ordenador{NO}/Reordenamiento{NO}] | W9: NO Requerido | X9: NO Requerido
A10: =Aerolinea_Muestreo!$D$3 -> Estado | B10: Lógico | C10: 6 | D10: 8 | J10: Cualquier cadena de caracteres, formado por letras mayúsculas(A-Z). | M10: SI | N10: SI | O10: NO | P10: NO | Q10: SI | R10: NO | S10: NO | T10: NO | U10: =Aerolinea_Muestreo!$D$2 -> Indica el estado operativo de la aerolínea | V10: Filtro/Listar/No Mostrar | W10: Requerido | X10: Requerido
A14: Combinaciones únicas
A15: Nombre combinación | B15: Descripción | C15: Atributos
A16: Código único | B16: =Aerolinea_Muestreo!E2 -> El código de la aerolínea no se puede repetir. | C16: =A9 -> Código
A17: Nombre único | B17: =Aerolinea_Muestreo!F2 -> El nombre de la aerolínea no se puede repetir. | C17: =A8 -> Nombre
A26: Responsabilidad | B26: Descripción | D26: Entradas | G26: Salida | H26: Políticas (Reglas de Negocio) | J26: Excepción
C27: Parámetro | D27: Tipo de dato | E27: Descripción | F27: Tipo de Dato | G27: Descripción | H27: Política | I27: Descripción | J27: Detalle | K27: ¿Qué hago?
A28: Consultar la Información de la Aerolínea | B28: Permite consultar los detalles de una aerolínea | C28: Filtro | D28: Aerolínea | E28: Contiene la información de los filtros que servirán como base para llevar a cabo la consulta de la información | F28: Lista<Aerolínea> | G28: Contiene la información de todas las Aerolíneas que cumplen con el filtro de consulta | H28: Aerolínea -POL-0001 | I28: Asegurar que los datos que fueron enviados como filtro para llevar a cabo la acción sean válidos a nivel de tipo de dato, longitud, obligatoriedad, formato y rango. | J28: Generar una excepción indicándole al usuario que existen problemas con los datos y de ser posible indicarle cómo solucionarlos. | K28: Detener operación
A30: Inactivar la Aerolínea | B30: Permite inactivar una aerolínea | C30: Id | D30: Alfanumérico | E30: Contiene la información del identificador de la aerolínea para la cual se va a modificar la información | H30: Aerolínea -POL-0003 | I30: La Aerolínea debe estar previamente activada | J30: Generar una excepción indicándole al usuario que existen problemas con los datos y de ser posible indicarle cómo solucionarlos. | K30: Detener operación
H31: Aerolínea -POL-0002 | I31: La Aerolínea debe estar previamente registrada | J31: Generar una excepción indicándole al usuario que existen problemas con los datos y de ser posible indicarle cómo solucionarlos. | K31: Detener operación
C32: Estado | D32: Lógico | E32: Contiene el estado lógico que se le puede modificar a una Aerolínea | H32: Aerolínea -POL-0001 | I32: Asegurar que los datos que fueron enviados como filtro para llevar a cabo la acción sean válidos a nivel de tipo de dato, longitud, obligatoriedad, formato y rango. | J32: Generar una excepción indicándole al usuario que existen problemas con los datos y de ser posible indicarle cómo solucionarlos. | K32: Detener operación
A33: Activar la Aerolínea | B33: Permite activar una aerolínea | C33: id | D33: Alfanumérico | E33: Contiene la información del identificador de la aerolínea para la cual se va a modificar la información | H33: Aerolinea -POL-0003 | I33: La Aerolínea debe estar previamente inactivada | J33: Generar una excepción indicándole al usuario que existen problemas con los datos y de ser posible indicarle cómo solucionarlos. | K33: Detener operación
H34: Aerolínea -POL-0002 | I34: La Aerolínea debe estar previamente registrada | J34: Generar una excepción indicándole al usuario que existen problemas con los datos y de ser posible indicarle cómo solucionarlos. | K34: Detener operación
C35: Estado | D35: Lógico | E35: Contiene el estado lógico que se le puede modificar a una Aerolínea | H35: Aerolínea -POL-0001 | I35: Asegurar que los datos que fueron enviados como filtro para llevar a cabo la acción sean válidos a nivel de tipo de dato, longitud, obligatoriedad, formato y rango. | J35: Generar una excepción indicándole al usuario que existen problemas con los datos y de ser posible indicarle cómo solucionarlos. | K35: Detener operación

Sheet Aerolinea_Muestreo
A1: << Modelo de dominio | B1: << Objetos de dominio | C1: Caracterización objeto >>
A2: Corresponde a un identificador único del parámetro dentro del objeto de dominio Parámetro. | B2: Corresponde al nombre de la aerolínea. | C2: Corresponde al código de la aerolínea. | D2: Indica el estado operativo de la aerolínea | E2: El código de la aerolínea no se puede repetir. | F2: El nombre de la aerolínea no se puede repetir.
A3: Id | B3: Nombre | C3: Código | D3: Estado | E3: Combinación única 1 | F3: Combinación única 2
A4: 8574C2C9-DAED-4E5A-93E5-8EDF2661496D | B4: Latam Airlines | C4: LA | D4: Activa | E4: =_xlfn.CONCAT(C4) -> LA | F4: =_xlfn.CONCAT(B4) -> Latam Airlines
A5: 6633A10F-08FA-4F2C-A70A-19B160E486FA | B5: Avianca | C5: AV | D5: Activa | E5: =_xlfn.CONCAT(C5) -> AV | F5: =_xlfn.CONCAT(C5,"-",B5) -> AV-Avianca

Sheet Aeropuerto_Caracterización 
A1: << Modelo de dominio | B1: << Objetos de dominio | C1: << Muestreo Datos
A2: ='Objetos Dominio'!$A$2 -> Nombre | B2: ='Objetos Dominio'!$A$4 -> Aeropuerto
A3: ='Objetos Dominio'!$B$2 -> Tipo | B3: ='Objetos Dominio'!$B$7 -> Referenciado
A4: ='Objetos Dominio'!$C$2 -> Contexto Origen | B4: ='Objetos Dominio'!$C$7 -> 0
A5: ='Objetos Dominio'!$D$2 -> Descripción | B5: ='Objetos Dominio'!$D$4 -> Objeto de dominio que representa a cada uno de los aeropuertos que están ubicados dentro de una ciudad.
A6: Atributo | B6: Tipo de Dato | C6: Longitud mínima | D6: Longitud máxima | E6: Precisión | F6: Cantidad cifras redondeo | G6: Tipo redondeo | H6: Rango Inicial | I6: Rango Final | J6: Formato | K6: Valor por defecto | L6: Regla especial | M6: ¿Quitar espacios en blanco al inicio? | N6: ¿Quitar espacios en blanco al final? | O6: ¿Auto generado? | P6: ¿Calculado? | Q6: ¿Obligatorio? | R6: ¿Modificable? | S6: ¿Sensible? | T6: ¿Identifica al registro? | U6: Descripción | V6: =A35 -> Consultar la Información del Aeropuerto | W6: =A36 -> Activar el aeropuerto | X6: =A38 -> Inactivar el aeropuerto
A7: ='Aeropuerto_Muestreo '!A3 -> id | B7: Alfanumérico | C7: 36 | D7: 36 | J7: XXXXXXXX-XXXX-XXXX-XXXX-XXXXXXXXXXXX donde X es cualquier digito o una letra de la "A" a la "Z" | M7: SI | N7: SI | O7: SI | P7: NO | Q7: SI | R7: NO | S7: NO | T7: SI | U7: ='Aeropuerto_Muestreo '!A2 -> Corresponde a un identificador único del aeropuerto del objeto de dominio Aeropuerto. | V7: Filtro/Listar/ No Mostrar | W7: Requerido | X7: Requerido
A8: ='Aeropuerto_Muestreo '!B3 -> Nombre | B8: Alfanumérico | C8: 27 | D8: 50 | J8: Cualquier cadena que incluye caracteres alfanuméricos, espacios, tildes(A-Z / a-z) | M8: SI | N8: SI | O8: NO | P8: NO | Q8: SI | R8: SI | S8: NO | T8: NO | U8: ='Aeropuerto_Muestreo '!B2 -> Corresponde al nombre del aeropuerto . | V8: Filtro/Listar/Mostrar[Orden{1}/CriterioOrdenamiento{1, ASC}/BusquedaGeneral{SI}/Ordenador{NO}/Reordenamiento{NO}] | W8: No Requerido | X8: No Requerido
A9: ='Aeropuerto_Muestreo '!C3 -> Código Iata | B9: Alfanumérico | C9: 3 | D9: 3 | J9: X donde x puede ser caracteres, formado por letras mayúsculas(A-Z). | M9: NO | N9: NO | O9: NO | P9: NO | Q9: SI | R9: SI | S9: NO | T9: NO | U9: ='Aeropuerto_Muestreo '!C2 -> Código que identifica al aeropuerto, ciudades de origen y destino | V9: Filtro/Listar/Mostrar[Orden{3}/CriterioOrdenamiento{1, ASC}/BusquedaGeneral{SI}/Ordenador{NO}/Reordenamiento{NO}] | W9: No Requerido | X9: No Requerido
A10: ='Aeropuerto_Muestreo '!D3 -> Estado | B10: Lógico | C10: 6 | D10: 12 | J10: Cualquier cadena que incluye caracteres alfanuméricos, espacios, tildes(a-z) | M10: NO | N10: NO | O10: NO | P10: NO | Q10: SI | R10: SI | S10: NO | T10: NO | U10: ='Aeropuerto_Muestreo '!D2 -> Indica el estado operativo de la aerolínea | V10: Filtro/Listar/Mostrar[Orden{4}/BusquedaGeneral{NO}/Ordenador{NO}/Reordenamiento{NO} ] | W10: Requerido | X10: Requerido
A11: ='Aeropuerto_Muestreo '!E3 -> Tipo Aeropuerto | B11: Tipo Aeropuerto | M11: NO | N11: NO | O11: NO | P11: NO | Q11: SI | R11: SI | S11: NO | T11: NO | U11: ='Aeropuerto_Muestreo '!E2 -> Corresponde al tipo del aeropuerto | V11: Filtro/Listar/Mostrar[Orden{5}/BusquedaGeneral{SI}/Ordenador{NO}/Reordenamiento{NO}PropiedadesMostrar{ TipoAeroperto.Nombre}] | W11: No Requerido | X11: No Requerido
A20: Combinaciones únicas
A21: Nombre combinación | B21: Descripción | C21: Atributos
A22: Aeropuerto por código Iata | B22: ='Aeropuerto_Muestreo '!F2 -> El Código Iata de un aeropuerto solo puede estar una vez. | C22: =A9 -> Código Iata
A23: Tipo captura por libro única
A33: Responsabilidad | B33: Descripción | D33: Entradas | G33: Salida | H33: Políticas (Reglas de Negocio) | J33: Excepción
C34: Parámetro | D34: Tipo de dato | E34: Descripción | F34: Tipo de Dato | G34: Descripción | H34: Política | I34: Descripción | J34: Detalle | K34: ¿Qué hago?
A35: Consultar la Información del Aeropuerto | B35: Permite obtener la información del aeropuerto | C35: filtro | D35: Aeropuerto | E35: Contiene la información de los filtros que servirán como base para llevar a cabo la consulta de la información | F35: Lista<Aeropuerto> | G35: Contiene la información de todos los aeropuertos que cumplen con el filtro de consulta | H35: Aerolínea -POL-0004 | I35: Asegurar que los datos que fueron enviados como filtro para llevar a cabo la acción sean válidos a nivel de tipo de dato, longitud, obligatoriedad, formato y rango. | J35: Generar una excepción indicándole al usuario que no tiene permisos para consultar la información | K35: Detener operación
A36: Activar el aeropuerto | B36: Permite activar el aeropuerto | C36: Id | D36: Alfanumérico | E36: Contiene la información del identificador de la aeropuerto para la cual se va a modificar la información | H36: Aerolínea -POL-0003 | I36: Para activar un aeropuerto primero debe estar desactivado | J36: Generar una excepción indicándole al usuario que existen problemas con los datos y de ser posible indicarle cómo solucionarlos. | K36: Detener operación
C37: Estado | D37: Lógico | E37: Contiene el estado lógico que se le puede modificar un Aeropuerto | H37: Aerolínea -POL-0001 | I37: Asegurar que los datos requeridos para llevar a cabo la acción sean válidos a nivel de tipo de dato, longitud, obligatoriedad, formato y rango. | J37: Generar una excepción indicándole al usuario que existen problemas con los datos y de ser posible indicarle cómo solucionarlos. | K37: Detener operación
A38: Inactivar el aeropuerto | B38: Permite inactivar el aeropuerto | C38: id | D38: Alfanumérico | E38: Contiene la información del identificador del aeropuerto para la cual se va a modificar la información | H38: Aerolínea -POL-0002 | I38: Para desactivar un aeropuerto primero debe estar activo | J38: Generar una excepción indicándole al usuario que existen problemas con los datos y de ser posible indicarle cómo solucionarlos. | K38: Detener operación
C39: Estado | D39: Lógico | E39: Contiene el estado lógico que se le puede modificar a un Aeropuerto | H39: Aerolínea -POL-0001 | I39: Asegurar que los datos requeridos para llevar a cabo la acción sean válidos a nivel de tipo de dato, longitud, obligatoriedad, formato y rango. | J39: Generar una excepción indicándole al usuario que existen problemas con los datos y de ser posible indicarle cómo solucionarlos. | K39: Detener operación

Sheet Aeropuerto_Muestreo 
A1: << Modelo de dominio | B1: << Objetos de dominio
A2: Corresponde a un identificador único del aeropuerto del objeto de dominio Aeropuerto. | B2: Corresponde al nombre del aeropuerto . | C2: Código que identifica al aeropuerto, ciudades de origen y destino | D2: Indica el estado operativo de la aerolínea | E2: Corresponde al tipo del aeropuerto | F2: El Código Iata de un aeropuerto solo puede estar una vez.
A3: id | B3: Nombre | C3: Código Iata | D3: Estado | E3: Tipo Aeropuerto | F3: Combinación única
A4: D2B278DF-5924-4D3D-AF73-2ABB758ED0D2 | B4: José María Córdova | C4: MDE | D4: Activo | E4: =TipoAeropuerto_Muestreo!C5 -> Internacional | F4: =_xlfn.CONCAT(C4) -> MDE
A5: 6F3794C7-D7BD-47CC-A4C7-39D68A90D40F | B5: El Dorado | C5: BOG | D5: Activo | E5: =TipoAeropuerto_Muestreo!C5 -> Internacional | F5: =_xlfn.CONCAT(C5) -> BOG
A6: 0FC88418-DB9C-48EF-B3BE-4177FAB7CDF1 | B6: Olaya Herrera | C6: EOH | D6: Activo | E6: =TipoAeropuerto_Muestreo!C4 -> Nacional | F6: =_xlfn.CONCAT(C6) -> EOH
A7: 140E5509-8D5A-427F-922C-503936CD9858 | B7: Alfonso Bonilla Aragón | C7: CLO | D7: Activo | E7: =TipoAeropuerto_Muestreo!$C$5 -> Internacional | F7: =_xlfn.CONCAT(C7) -> CLO
A8: C5F98B68-C33D-4A8C-8F45-56539A487AC0 | B8: Ernesto Cortissoz | C8: BAQ | D8: Activo | E8: =TipoAeropuerto_Muestreo!$C$5 -> Internacional | F8: =_xlfn.CONCAT(C8) -> BAQ
A9: E2EE8162-5402-46FD-8102-5A33774DB38D | B9: Rafael Núñez | C9: CTG | D9: Activo | E9: =TipoAeropuerto_Muestreo!$C$5 -> Internacional | F9: =_xlfn.CONCAT(C9) -> CTG
A10: 7A9FAF10-985E-49A0-8FE1-729D9E4A445D | B10: Simón Bolívar | C10: SMR | D10: Activo | E10: =TipoAeropuerto_Muestreo!$C$5 -> Internacional | F10: =_xlfn.CONCAT(C10) -> SMR
A11: 4E94BB12-36F2-476F-BF79-B6450F821DB3 | B11: Matecaña | C11: PEI | D11: Activo | E11: =TipoAeropuerto_Muestreo!$C$5 -> Internacional | F11: =_xlfn.CONCAT(C11) -> PEI
A12: C3CE82BA-978A-44F8-943F-A6ED196DA94C | B12: Alfredo Vásquez Cobo | C12: LET | D12: Activo | E12: =TipoAeropuerto_Muestreo!$C$5 -> Internacional | F12: =_xlfn.CONCAT(C12) -> LET
A13: 2B64DE30-3E8A-4553-A86A-41241286288E | B13: Alfonso López Pumarejo | C13: VUP | D13: Activo | E13: =TipoAeropuerto_Muestreo!$C$5 -> Internacional | F13: =_xlfn.CONCAT(C13) -> VUP
A14: A881310E-568C-4EE9-ACCD-8AFA24006380 | B14: Camilo Daza | C14: CUC | D14: Activo | E14: =TipoAeropuerto_Muestreo!$C$5 -> Internacional | F14: =_xlfn.CONCAT(C14) -> CUC
A15: 924265BE-6259-4682-B94C-9AF0247121EE | B15: Palonegro | C15: BGA | D15: Activo | E15: =TipoAeropuerto_Muestreo!$C$5 -> Internacional | F15: =_xlfn.CONCAT(C15) -> BGA
A16: 8B4AE87B-BBBE-4A31-B928-418B604134B2 | B16: Antonio Nariño | C16: PSO | D16: Activo | E16: =TipoAeropuerto_Muestreo!$C$4 -> Nacional | F16: =_xlfn.CONCAT(C16) -> PSO
A17: C05C6FF2-0C62-4F05-A8F9-2605E5422C83 | B17: El Alcaraván | C17: EYP | D17: Activo | E17: =TipoAeropuerto_Muestreo!$C$5 -> Internacional | F17: =_xlfn.CONCAT(C17) -> EYP
A18: CA593CA2-2EB1-4483-8E56-C6B594329F42 | B18: El Edén | C18: AXM | D18: Activo | E18: =TipoAeropuerto_Muestreo!$C$5 -> Internacional | F18: =_xlfn.CONCAT(C18) -> AXM
A19: 8F2A4379-3CE8-4619-AC2C-DE4EC30F2F21 | B19: los Garzones | C19: MTR | D19: Activo | E19: =TipoAeropuerto_Muestreo!$C$4 -> Nacional | F19: =_xlfn.CONCAT(C19) -> MTR
A20: CC97AE1F-A628-41C1-B8FE-65C78E09A4D0 | B20: Gustavo Rojas Pinilla | C20: ADZ | D20: Activo | E20: =TipoAeropuerto_Muestreo!$C$5 -> Internacional | F20: =_xlfn.CONCAT(C20) -> ADZ
A21: 2E4F8A6D-5B91-42C3-8F7A-91C2D3E4F5A6 | B21: Internacional de Miami | C21: MIA | D21: Activo | E21: =TipoAeropuerto_Muestreo!$C$5 -> Internacional | F21: =_xlfn.CONCAT(C21) -> MIA

Sheet BitacoraDiaria_Caracterización 
A1: << Modelo de dominio | B1: << Objetos de dominio | C1: << Muestreo Datos
A2: ='Objetos Dominio'!$A$2 -> Nombre | B2: ='Objetos Dominio'!A5 -> Bitácora Diaria
A3: ='Objetos Dominio'!$B$2 -> Tipo | B3: ='Objetos Dominio'!$B$5 -> Referenciado
A4: ='Objetos Dominio'!$C$2 -> Contexto Origen | B4: ='Objetos Dominio'!$C$5 -> 0
A5: ='Objetos Dominio'!$D$2 -> Descripción | B5: ='Objetos Dominio'!$D$5 -> Objeto de dominio que representa la fecha, el empleado y pagina del libro sobre el vuelo realizado.
A6: Atributo | B6: Tipo de Dato | C6: Longitud mínima | D6: Longitud máxima | E6: Precisión | F6: Cantidad cifras redondeo | G6: Tipo redondeo | H6: Rango Inicial | I6: Rango Final | J6: Formato | K6: Valor por defecto | L6: Regla especial | M6: ¿Quitar espacios en blanco al inicio? | N6: ¿Quitar espacios en blanco al final? | O6: ¿Auto generado? | P6: ¿Calculado? | Q6: ¿Obligatorio? | R6: ¿Modificable? | S6: ¿Sensible? | T6: ¿Identifica al registro? | U6: Descripción | V6: =A21 -> Consultar la Información de la Bitácora Diaria | W6: =A23 -> Agregar la Información de la Bitácora Diaria | X6: =A27 -> Editar Información Bitácora Diaria | Y6: =A30 -> Editar la Informacion de la Bitacora Diaria | Z6: =A32 -> Activar la Bitácora Diaria | AA6: =A34 -> Inactivar la Bitácora Diaria
A7: ='BitacoraDiaria_Muestreo '!A3 -> Id | B7: Alfanumérico | C7: 36 | D7: 36 | J7: XXXXXXXX-XXXX-XXXX-XXXX-XXXXXXXXXXXX donde X es cualquier digito o una letra de la "A" a la "F" | M7: SI | N7: SI | O7: SI | P7: NO | Q7: SI | R7: NO | S7: NO | T7: SI | U7: ='BitacoraDiaria_Muestreo '!A2 -> Corresponde a un identificador único de la cuenta dentro del objeto de dominio | V7: Filtro/Listar/ No Mostrar | W7: Requerido | X7: Requerido / No modificable | Y7: Requerido | Z7: Requerido | AA7: Requerido
A8: ='BitacoraDiaria_Muestreo '!B3 -> Fecha | B8: Fecha | C8: 10 | D8: 10 | M8: SI | N8: SI | O8: NO | P8: NO | Q8: SI | R8: SI | S8: NO | T8: NO | U8: ='BitacoraDiaria_Muestreo '!B2 -> Corresponde a la fecha de la bitácora | V8: Filtro/Listar/Mostrar[Orden{1}/CriterioOrdenamiento{1, ASC}/BusquedaGeneral{SI}/Ordenador{NO}/Reordenamiento{NO}] | W8: Requerido | X8: Requerido / modificable | Y8: No Requerido | Z8: No Requerido | AA8: No Requerido
A9: ='BitacoraDiaria_Muestreo '!C3 -> Empleado Aerolínea | B9: EmpleadoAerolinea | M9: SI | N9: SI | O9: NO | P9: NO | Q9: SI | R9: SI | S9: NO | T9: NO | U9: ='BitacoraDiaria_Muestreo '!C2 -> Corresponde al nombre del empleado de la aerolínea que llena la bitácora | V9: Filtro/Listar/Mostrar[Orden{2}/CriterioOrdenamiento{1, ASC}/BusquedaGeneral{SI}/Ordenador{NO}/Reordenamiento{NO} /PropiedadesMostrar{ Empleado.numeroIdentificacion, Empleado.Aerolinea}] | W9: Requerido | X9: Requerido / modificable | Y9: No Requerido | Z9: No Requerido | AA9: No Requerido
A10: ='BitacoraDiaria_Muestreo '!D3 -> Pagina Libro | B10: Numérico Entero | C10: 9 | D10: 50 | M10: SI | N10: SI | O10: NO | P10: NO | Q10: SI | R10: SI | S10: NO | T10: NO | U10: ='BitacoraDiaria_Muestreo '!D2 -> Corresponde a la página del libro del empleado | V10: Filtro/Listar/Mostrar[Orden{3}/BusquedaGeneral{SI}/Ordenador{SI}/Reordenamiento{NO}] | W10: Requerido | X10: Requerido / modificable | Y10: No Requerido | Z10: No Requerido | AA10: No Requerido
A11: ='BitacoraDiaria_Muestreo '!E3 -> Estado | B11: Alfanumérico | C11: 6 | D11: 12 | J11: Cualquier cadena que incluye caracteres alfanuméricos, espacios, tildes(a-z) | M11: SI | N11: SI | O11: NO | P11: NO | Q11: SI | R11: SI | S11: NO | T11: NO | U11: ='BitacoraDiaria_Muestreo '!E2 -> Indica el estado operativo de la bitácora | V11: Filtro/Listar/ No Mostrar | W11: Requerido | X11: Requerido / modificable | Y11: No Requerido | Z11: No Requerido | AA11: No Requerido
A14: Combinaciones únicas
A15: Nombre combinación | B15: Descripción | C15: Atributos
A16: Nombre único | B16: ='BitacoraDiaria_Muestreo '!F2 -> El nombre del empleado y la fecha de la bitácora no puede repetirse. | C16: =A8 -> Fecha
C17: =A9 -> Empleado Aerolínea
A19: Responsabilidad | B19: Descripción | D19: Entradas | G19: Salida | H19: Políticas (Reglas de Negocio) | J19: Excepción
C20: Parámetro | D20: Tipo de dato | E20: Descripción | F20: Tipo de Dato | G20: Descripción | H20: Política | I20: Descripción | J20: Detalle | K20: ¿Qué hago?
A21: Consultar la Información de la Bitácora Diaria | B21: Permite obtener toda la información de la matricula | C21: Filtro | D21: BitacoraDiaria | E21: Contiene la información de los filtros que servirán como base para llevar a cabo la consulta de la información | F21: Lista<BiracoraDiaria> | G21: Contiene la información de la página de la bitácora diaria que cumplen con el filtro de consulta | H21: Bitácora Diaria - POL-0001 | I21: Asegurar que los datos que fueron enviados como filtro para llevar a cabo la acción sean válidos a nivel de tipo de dato, longitud, obligatoriedad, formato y rango. | J21: Generar una excepción indicándole al usuario que existen problemas con los datos y de ser posible indicarle cómo solucionarlos. | K21: Detener operación
A23: Agregar la Información de la Bitácora Diaria | B23: Permite registrar toda la información de la bitácora de un piloto | C23: Datos | D23: BitacoraDiaria | E23: Contiene los datos que se van a registrar dentro de la bitácora diaria | H23: Bitácora Diaria-Pol-0007 | I23: Asegurar que los datos requeridos para llevar a cabo la acción sean válidos a nivel de tipo de dato, longitud, obligatoriedad, formato y rango. | J23: Generar una excepción indicándole al usuario que existen problemas con los datos y de ser posible indicarle cómo solucionarlos. | K23: Detener operación
H24: Bitácora Diaria -POL-0002 | I24: No puede existir más de una bitácora realizada con la misma fecha y el mismo empleado. | J24: Generar una excepción indicándole al usuario que existen problemas con los datos y de ser posible indicarle cómo solucionarlos. | K24: Detener operación
H25: Bitácora Diaria-POL-0003 | I25: No puede existir más de una bitácora con el mismo número de página del libro. | J25: Generar una excepción indicándole al usuario que existen problemas con los datos y de ser posible indicarle cómo solucionarlos. | K25: Detener operación
H26: Bitácora Diaria -POL-0008 | I26: No puede existir otra bitácora con el mismo identificador. | J26: Generar un nuevo identificador hasta garantizar que no exista. | K26: Continuar operación
A27: Editar Información Bitácora Diaria | B27: Permite actualizar la información de una bitácora diaria | C27: Id | D27: Alfanumérico | E27: Contiene la información del identificador de la bitácora que se a eliminar | H27: Bitácora Diaria -Pol-0007 | I27: Asegurar que los datos requeridos para llevar a cabo la acción sean válidos a nivel de tipo de dato, longitud, obligatoriedad, formato y rango. | J27: Generar un nuevo identificador hasta garantizar que no exista. | K27: Detener operación
C28: Datos | D28: BitacoraDiaria | E28: Contiene los datos que se van a eliminar de la bitácora | H28: Bitácora Diaria -POL-0002 | I28: No puede existir más de una bitácora realizada con la misma fecha y el mismo empleado. | J28: Generar una excepción indicándole al usuario que existen problemas con los datos y de ser posible indicarle cómo solucionarlos. | K28: Detener operación
H29: Bitácora Diaria -POL-0003 | I29: No puede existir más de una bitácora con el mismo número de página del libro. | J29: Generar una nueva página del libro hasta garantizar que no exista. | K29: Continuar operación
A30: Editar la Informacion de la Bitacora Diaria | B30: Permite eliminar la información de una bitácora diaria | C30: Id | D30: Alfanumérico | E30: Contiene la información del identificador de la bitácora diaria para la cual se va a eliminar la información | H30: Bitácora Diaria -POL-0007 | I30: Asegurar que los datos que fueron enviados como filtro para llevar a cabo la acción sean válidos a nivel de tipo de dato, longitud, obligatoriedad, formato y rango. | J30: Generar una excepción indicándole al usuario que existen problemas con los datos y de ser posible indicarle cómo solucionarlos. | K30: Detener operación
A32: Activar la Bitácora Diaria | B32: Permite tener habilitada una página de la bitácora diaria | C32: Id | D32: Alfanumérico | E32: Contiene la información del identificador de la bitácora diaria para la cual se va activar la información | H32: Bitácora Diaria -POL-0007 | I32: Asegurar que los datos que fueron enviados como filtro para llevar a cabo la acción sean válidos a nivel de tipo de dato, longitud, obligatoriedad, formato y rango. | J32: Generar una excepción indicándole al usuario que existen problemas con los datos y de ser posible indicarle cómo solucionarlos. | K32: Detener operación
C33: Estado | D33: Lógico | E33: Contiene la información del estado booleano de la bitácora diaria para la cual se va a activar | H33: Bitácora Diaria -POL-0006 | I33: La bitácora debe estar previamente inactivada. | J33: Generar una excepción indicándole al usuario que existen problemas con los datos y de ser posible indicarle cómo solucionarlos. | K33: Detener operación
A34: Inactivar la Bitácora Diaria | B34: Permite inhabilitar una página de la bitácora diaria para su eliminación | C34: Id | D34: Alfanumérico | E34: Contiene la información del identificador de la bitácora diaria para la cual se va a Inactivar la información | H34: Bitácora Diaria -POL-0007 | I34: Asegurar que los datos que fueron enviados como filtro para llevar a cabo la acción sean válidos a nivel de tipo de dato, longitud, obligatoriedad, formato y rango. | J34: Generar una excepción indicándole al usuario que existen problemas con los datos y de ser posible indicarle cómo solucionarlos. | K34: Detener operación
C35: Estado | D35: Lógico | E35: Contiene la información del estado booleano de la bitácora diaria para la cual se va a inactivar | H35: Bitácora Diaria -POL-0005 | I35: La bitácora debe estar previamente activada. | J35: Generar una excepción indicándole al usuario que existen problemas con los datos y de ser posible indicarle cómo solucionarlos. | K35: Detener operación

Sheet BitacoraDiaria_Muestreo 
A1: << Modelo de dominio | B1: << Objetos de dominio | C1: Caracterización objeto >>
A2: Corresponde a un identificador único de la cuenta dentro del objeto de dominio | B2: Corresponde a la fecha de la bitácora | C2: Corresponde al nombre del empleado de la aerolínea que llena la bitácora | D2: Corresponde a la página del libro del empleado | E2: Indica el estado operativo de la bitácora | F2: El nombre del empleado y la fecha de la bitácora no puede repetirse. | G2: El numero de la hoja del libro del empleado no puede repetirse.
A3: Id | B3: Fecha | C3: Empleado Aerolínea | D3: Pagina Libro | E3: Estado | F3: Combinación única 1 | G3: combinación única 2
A4: FCDE13AF-66B1-431E-AF58-013DBB61E7F2 | B4: 01/01/2024 | C4: =EmpleadoAerolinea_Muestreo!I4 -> Latam Airlines-4472021 | D4: 176770012 | E4: Activa | F4: =C4&"-"&TEXT(B4,"DD/MM/AA") -> Latam Airlines-4472021-01/01/AA | G4: =D4 -> 176770012

Sheet Det_BitacoraDia_Caracterización
A1: << Modelo de dominio | B1: << Objetos de dominio | C1: << Muestreo Datos
A2: ='Objetos Dominio'!$A$2 -> Nombre | B2: ='Objetos Dominio'!$A$8 -> Detalle Bitácora Diaria
A3: ='Objetos Dominio'!$B$2 -> Tipo | B3: ='Objetos Dominio'!$B$8 -> Referenciado
A4: ='Objetos Dominio'!$C$2 -> Contexto Origen | B4: ='Objetos Dominio'!$C$8 -> 0
A5: ='Objetos Dominio'!$D$2 -> Descripción | B5: ='Objetos Dominio'!$D$8 -> Objeto de dominio que representa a quien pertenece la bitácora, la información del vuelo, la matrícula de la aeronave, la tripulación y que rango tienen, las horas de vuelo y su total.
A6: Atributo | B6: Tipo de Dato | C6: Longitud mínima | D6: Longitud máxima | E6: Precisión | F6: Cantidad cifras redondeo | G6: Tipo redondeo | H6: Rango Inicial | I6: Rango Final | J6: Formato | K6: Valor por defecto | L6: Regla especial | M6: ¿Quitar espacios en blanco al inicio? | N6: ¿Quitar espacios en blanco al final? | O6: ¿Auto generado? | P6: ¿Calculado? | Q6: ¿Obligatorio? | R6: ¿Modificable? | S6: ¿Sensible? | T6: ¿Identifica al registro? | U6: Descripción | V6: =A42 -> Consultar la Información de Detalle de la Bitácora Diaria | W6: =A46 -> Editar la Información de Detalle Bitacora Diaria | X6: =A37 -> Agregar la Información a Detalle Bitacora Diaria | Y6: =A49 -> Eliminar Información de un Detalle Bitacora Diaria
A7: ='Deta_BitacoraDiaria_Muestreo '!A3 -> Id | B7: Alfanumérico | C7: 36 | D7: 36 | J7: XXXXXXXX-XXXX-XXXX-XXXX-XXXXXXXXXXXX donde X es cualquier digito o una letra de la "A" a la "F" | M7: SI | N7: SI | O7: SI | P7: NO | Q7: SI | R7: NO | S7: NO | T7: SI | U7: ='Deta_BitacoraDiaria_Muestreo '!A2 -> Corresponde a un identificador único de la bitácora dentro del objeto de dominio . | V7: Filtro/Listar/ No Mostrar | W7: Requerido / No modificable | X7: Requerido | Y7: Requerido
A8: ='Deta_BitacoraDiaria_Muestreo '!B3 -> Bitácora Diaria | B8: Bitácora Diaria | M8: SI | N8: SI | O8: NO | P8: NO | Q8: SI | R8: SI | S8: NO | T8: NO | U8: ='Deta_BitacoraDiaria_Muestreo '!B2 -> Corresponde al nombre del empleado al que le pertenece la bitácora | V8: Filtro/Listar/Mostrar[Orden{1}/CriterioOrdenamiento{1, ASC}/BusquedaGeneral{SI}/Ordenador{NO}/Reordenamiento{NO} /PropiedadesMostrar{ BitacoraDiaria.Aerolinea, BitacoraDiaria.Empleado, BitacoraDiaria.Fecha}] | W8: Requerido / modificable | X8: Requerido | Y8: No Requerido
A9: ='Deta_BitacoraDiaria_Muestreo '!C3 -> Vuelo | B9: Vuelo | M9: SI | N9: SI | O9: NO | P9: NO | Q9: SI | R9: SI | S9: NO | T9: NO | U9: ='Deta_BitacoraDiaria_Muestreo '!C2 -> Corresponde al vuelo | V9: Filtro/Listar/Mostrar[Orden{2}/CriterioOrdenamiento{2, ASC}/BusquedaGeneral{SI}/Ordenador{NO}/Reordenamiento{NO} /PropiedadesMostrar{ Vuelo.Fecha,Vuelo.Numero,Vuelo.RutaAerolinea}] | W9: Requerido / modificable | X9: Requerido | Y9: No Requerido
A10: ='Deta_BitacoraDiaria_Muestreo '!D3 -> Fecha Real Salida Vuelo | B10: Fecha/Hora | C10: 6 | D10: 6 | M10: SI | N10: SI | O10: NO | P10: NO | Q10: SI | R10: SI | S10: NO | T10: NO | U10: ='Deta_BitacoraDiaria_Muestreo '!D2 -> Corresponde a la fecha y hora de salida del vuelo | V10: Filtro/Listar/Mostrar[Orden{3}/CriterioOrdenamiento{3, ASC}/BusquedaGeneral{SI}/Ordenador{SI}/Reordenamiento{SI} ] | W10: Requerido / modificable | X10: Requerido | Y10: No Requerido
A11: ='Deta_BitacoraDiaria_Muestreo '!E3 -> Matricula Real | B11: Matricula | M11: SI | N11: SI | O11: NO | P11: NO | Q11: SI | R11: SI | S11: NO | T11: NO | U11: ='Deta_BitacoraDiaria_Muestreo '!E2 -> Corresponde a la matrícula de la aeronave | V11: Filtro/Listar/Mostrar[Orden{4}/CriterioOrdenamiento{4, ASC}/BusquedaGeneral{SI}/Ordenador{SI}/Reordenamiento{SI} ] | W11: Requerido / modificable | X11: Requerido | Y11: No Requerido
A12: ='Deta_BitacoraDiaria_Muestreo '!F3 -> PAX | B12: Numérico Entero | H12: 1 | I12: 935 | M12: SI | N12: SI | O12: NO | P12: NO | Q12: SI | R12: SI | S12: NO | T12: NO | U12: ='Deta_BitacoraDiaria_Muestreo '!F2 -> Corresponde al número de pasajeros | V12: Filtro/Listar/Mostrar[Orden{5}/BusquedaGeneral{NO}/Ordenador{NO}/Reordenamiento{NO} ] | W12: Requerido / modificable | X12: Requerido | Y12: No Requerido
A13: ='Deta_BitacoraDiaria_Muestreo '!G3 -> Tiempo_Vuelo | B13: Fecha/Hora | M13: SI | N13: SI | O13: NO | P13: NO | Q13: SI | R13: SI | S13: NO | T13: NO | U13: ='Deta_BitacoraDiaria_Muestreo '!G2 -> Corresponde a la fecha y hora en la que inicia el vuelo | V13: Filtro/Listar/Mostrar[Orden{6}/BusquedaGeneral{NO}/Ordenador{NO}/Reordenamiento{NO} ] | W13: Requerido / modificable | X13: Requerido | Y13: No Requerido
A14: ='Deta_BitacoraDiaria_Muestreo '!H3 -> Hora_Despegue | B14: Fecha/Hora | M14: SI | N14: SI | O14: NO | P14: NO | Q14: SI | R14: SI | S14: NO | T14: NO | U14: ='Deta_BitacoraDiaria_Muestreo '!H2 -> Corresponde a la fecha y hora en la que se realiza el despegue | V14: Filtro/Listar/Mostrar[Orden{6}/BusquedaGeneral{NO}/Ordenador{NO}/Reordenamiento{NO} ] | W14: Requerido / modificable | X14: Requerido | Y14: No Requerido
A15: ='Deta_BitacoraDiaria_Muestreo '!I3 -> Hora_Aterrizaje | B15: Fecha/Hora | M15: SI | N15: SI | O15: NO | P15: NO | Q15: SI | R15: SI | S15: NO | T15: NO | U15: ='Deta_BitacoraDiaria_Muestreo '!I2 -> Corresponde a la fecha y hora en la que se realiza el aterrizaje | V15: Filtro/Listar/Mostrar[Orden{6}/BusquedaGeneral{NO}/Ordenador{NO}/Reordenamiento{NO} ] | W15: Requerido / modificable | X15: Requerido | Y15: No Requerido
A16: ='Deta_BitacoraDiaria_Muestreo '!J3 -> Aterrizaje_y_desembarque | B16: Fecha/Hora | M16: SI | N16: SI | O16: NO | P16: NO | Q16: SI | R16: SI | S16: NO | T16: NO | U16: ='Deta_BitacoraDiaria_Muestreo '!J2 -> Corresponde a la fecha y hora en la que se realiza el aterrizaje y desembarque | V16: Filtro/Listar/Mostrar[Orden{6}/BusquedaGeneral{NO}/Ordenador{NO}/Reordenamiento{NO} ] | W16: Requerido / modificable | X16: Requerido | Y16: No Requerido
A17: ='Deta_BitacoraDiaria_Muestreo '!K3 -> PF | B17: Tipo Integrante | M17: SI | N17: SI | O17: NO | P17: NO | Q17: SI | R17: SI | S17: NO | T17: NO | U17: ='Deta_BitacoraDiaria_Muestreo '!K2 -> Corresponde al nombre del empleado que realizo el vuelo | V17: Filtro/Listar/Mostrar[Orden{6}/BusquedaGeneral{NO}/Ordenador{NO}/Reordenamiento{NO} ] | W17: Requerido / modificable | X17: Requerido | Y17: No Requerido
A18: ='Deta_BitacoraDiaria_Muestreo '!L3 -> PFL | B18: Tipo Integrante | M18: SI | N18: SI | O18: NO | P18: NO | Q18: SI | R18: SI | S18: NO | T18: NO | U18: ='Deta_BitacoraDiaria_Muestreo '!L2 -> Corresponde al nombre del empleado que realizo el vuelo y aterrizo | V18: Filtro/Listar/Mostrar[Orden{6}/BusquedaGeneral{NO}/Ordenador{NO}/Reordenamiento{NO} ] | W18: Requerido / modificable | X18: Requerido | Y18: No Requerido
A19: ='Deta_BitacoraDiaria_Muestreo '!M3 -> PFTO | B19: Tipo Integrante | M19: SI | N19: SI | O19: NO | P19: NO | Q19: SI | R19: SI | S19: NO | T19: NO | U19: ='Deta_BitacoraDiaria_Muestreo '!M2 -> Corresponde al nombre del empleado que realizo el vuelo y el despegue | V19: Filtro/Listar/Mostrar[Orden{6}/BusquedaGeneral{NO}/Ordenador{NO}/Reordenamiento{NO} ] | W19: Requerido / modificable | X19: Requerido | Y19: No Requerido
A20: ='Deta_BitacoraDiaria_Muestreo '!N3 -> PM | B20: Tipo Integrante | M20: SI | N20: SI | O20: NO | P20: NO | Q20: SI | R20: SI | S20: NO | T20: NO | U20: ='Deta_BitacoraDiaria_Muestreo '!N2 -> Corresponde al nombre del empleado que monitorea todo durante el vuelo | V20: Filtro/Listar/Mostrar[Orden{6}/BusquedaGeneral{NO}/Ordenador{NO}/Reordenamiento{NO} ] | W20: Requerido / modificable | X20: Requerido | Y20: No Requerido
A21: ='Deta_BitacoraDiaria_Muestreo '!O3 -> Capitán | B21: EmpleadoAerolinea | M21: SI | N21: SI | O21: NO | P21: NO | Q21: SI | R21: SI | S21: NO | T21: NO | U21: ='Deta_BitacoraDiaria_Muestreo '!O2 -> Corresponde al nombre del Capitán | V21: Filtro/Listar/Mostrar[Orden{6}/BusquedaGeneral{SI}/Ordenador{NO}/Reordenamiento{NO} ] | W21: Requerido / modificable | X21: Requerido | Y21: No Requerido
A22: ='Deta_BitacoraDiaria_Muestreo '!P3 -> Copiloto | B22: EmpleadoAerolinea | M22: SI | N22: SI | O22: NO | P22: NO | Q22: SI | R22: SI | S22: NO | T22: NO | U22: ='Deta_BitacoraDiaria_Muestreo '!P2 -> Corresponde al nombre del copiloto | V22: Filtro/Listar/Mostrar[Orden{6}/BusquedaGeneral{SI}/Ordenador{NO}/Reordenamiento{NO} ] | W22: Requerido / modificable | X22: Requerido | Y22: No Requerido
A23: ='Deta_BitacoraDiaria_Muestreo '!Q3 -> Air | B23: Hora | M23: SI | N23: SI | O23: NO | P23: NO | Q23: SI | R23: SI | S23: NO | T23: NO | U23: ='Deta_BitacoraDiaria_Muestreo '!Q2 -> Corresponde al tiempo desde el despegue hasta el aterrizaje | V23: Filtro/Listar/Mostrar[Orden{6}/BusquedaGeneral{NO}/Ordenador{NO}/Reordenamiento{NO} ] | W23: Requerido / modificable | X23: Requerido | Y23: No Requerido
A24: ='Deta_BitacoraDiaria_Muestreo '!R3 -> Block | B24: Hora | M24: SI | N24: SI | O24: NO | P24: NO | Q24: SI | R24: SI | S24: NO | T24: NO | U24: ='Deta_BitacoraDiaria_Muestreo '!R2 -> Corresponde al tiempo desde el remolque hasta el parqueo | V24: Filtro/Listar/Mostrar[Orden{6}/BusquedaGeneral{NO}/Ordenador{NO}/Reordenamiento{NO} ] | W24: Requerido / modificable | X24: Requerido | Y24: No Requerido
A29: Combinaciones únicas
A30: Nombre combinación | B30: Descripción | C30: Atributos
A31: Nombre único | B31: El numero, la ruta ,la fecha y la matrícula de la aeronave no pueden repetirse. | C31: =A9 -> Vuelo
C32: =A11 -> Matricula Real
A35: Responsabilidad | B35: Descripción | D35: Entradas | G35: Salida | H35: Políticas (Reglas de Negocio) | J35: Excepción
C36: Parámetro | D36: Tipo de dato | E36: Descripción | F36: Tipo de Dato | G36: Descripción | H36: Política | I36: Descripción | J36: Detalle | K36: ¿Qué hago?
A37: Agregar la Información a Detalle Bitacora Diaria | B37: Permite Agregar la información de un empleado que ya existe en la bitácora | C37: datos | D37: DetallesBitácoraDiaria | E37: Contiene la información de los filtros que servirán como base para llevar a cabo la consulta de la información | H37: DetBitacora -POL-0002 | I37: No puede existir más de una bitácora realizada con la misma fecha. | J37: Generar una excepción indicándole al usuario que existen problemas con los datos y de ser posible indicarle cómo solucionarlos. | K37: Detener operación
H38: DetBitacora-POL-0003 | I38: No puede existir una bitácora con OUT,OFF,ON,IN,AIR y BLOCK con resultados negativos | J38: Generar una excepción indicándole al usuario que existen problemas con los datos y de ser posible indicarle cómo solucionarlos. | K38: Detener operación
H39: DetBitacora-POL-0001 | I39: Asegurar que los datos requeridos para llevar a cabo la acción sean válidos a nivel de tipo de dato, longitud, obligatoriedad, formato y rango. | J39: Generar una excepción indicándole al usuario que existen problemas con los datos y de ser posible indicarle cómo solucionarlos. | K39: Detener operación
H40: DetBitacora-POL-0005 | I40: No puede existir más de una bitácora con el mismo id | J40: Generar un nuevo identificador hasta garantizar que no exista. | K40: Continuar operación
A42: Consultar la Información de Detalle de la Bitácora Diaria | B42: Permite consultar la información de una bitácora | C42: Filtro | D42: DetallesBitácoraDiaria | E42: Contiene la información de los filtros que servirán como base para llevar a cabo la consulta de la información | F42: Lista<detalleBitácoraDiaria> | G42: Contiene la información de todos las bitácoras diarias que cumplen con el filtro de consulta | H42: DetBitacora-POL-0004 | I42: Asegurar que los datos que fueron enviados como filtro para llevar a cabo la acción sean válidos a nivel de tipo de dato, longitud, obligatoriedad, formato y rango. | J42: Generar una excepción indicándole al usuario que existen problemas con los datos y de ser posible indicarle cómo solucionarlos. | K42: Detener operación
A46: Editar la Información de Detalle Bitacora Diaria | B46: Permite actualizar la información de una bitácora que ya existe | C46: id | D46: Alfanumérico | E46: Contiene la información del identificador del detalle bitácora que se va a editar de forma definitiva | H46: DetBitacora-POL-0002 | I46: No puede existir más de una bitácora realizada con la misma fecha. | J46: Generar una excepción indicándole al usuario que existen problemas con los datos y de ser posible indicarle cómo solucionarlos. | K46: Detener operación
H47: DetBitacora-POL-0001 | I47: Asegurar que los datos requeridos para llevar a cabo la acción sean válidos a nivel de tipo de dato, longitud, obligatoriedad, formato y rango. | J47: Generar una excepción indicándole al usuario que existen problemas con los datos y de ser posible indicarle cómo solucionarlos. | K47: Detener operación
H48: DetBitacora-POL-0003 | I48: No puede existir una bitácora con OUT,OFF,ON,IN,AIR y BLOCK con resultados negativos | J48: Generar una excepción indicándole al usuario que existen problemas con los datos y de ser posible indicarle cómo solucionarlos. | K48: Detener operación
A49: Eliminar Información de un Detalle Bitacora Diaria | B49: Permite eliminar un detalle de una bitácora. | C49: id | D49: Alfanumérico | E49: Contiene la información del identificador del detalle bitácora que se va a eliminar de forma definitiva | H49: DetBitacora-POL-0001 | I49: Asegurar que los datos requeridos para llevar a cabo la acción sean válidos a nivel de tipo de dato, longitud, obligatoriedad, formato y rango. | J49: Generar una excepción indicándole al usuario que existen problemas con los datos y de ser posible indicarle cómo solucionarlos. | K49: Detener operación
H50: DetBitacora-POL-0006 | I50: Asegurar que el empleado no esté vinculado a un detalle bitácora Diaria | J50: Generar una excepción indicándole al usuario que existen problemas con los datos y de ser posible indicarle cómo solucionarlos. | K50: Detener operación

Sheet Deta_BitacoraDiaria_Muestreo 
A1: << Modelo de dominio | B1: << Objetos de dominio | S1: Caracterización objeto >>
A2: Corresponde a un identificador único de la bitácora dentro del objeto de dominio . | B2: Corresponde al nombre del empleado al que le pertenece la bitácora | C2: Corresponde al vuelo | D2: Corresponde a la fecha y hora de salida del vuelo | E2: Corresponde a la matrícula de la aeronave | F2: Corresponde al número de pasajeros | G2: Corresponde a la fecha y hora en la que inicia el vuelo | H2: Corresponde a la fecha y hora en la que se realiza el despegue | I2: Corresponde a la fecha y hora en la que se realiza el aterrizaje | J2: Corresponde a la fecha y hora en la que se realiza el aterrizaje y desembarque | K2: Corresponde al nombre del empleado que realizo el vuelo | L2: Corresponde al nombre del empleado que realizo el vuelo y aterrizo | M2: Corresponde al nombre del empleado que realizo el vuelo y el despegue | N2: Corresponde al nombre del empleado que monitorea todo durante el vuelo | O2: Corresponde al nombre del Capitán | P2: Corresponde al nombre del copiloto | Q2: Corresponde al tiempo desde el despegue hasta el aterrizaje | R2: Corresponde al tiempo desde el remolque hasta el parqueo | S2: El número, la ruta ,la fecha y la matrícula de la aeronave no pueden repetirse.
A3: Id | B3: Bitácora Diaria | C3: Vuelo | D3: Fecha Real Salida Vuelo | E3: Matricula Real | F3: PAX | G3: Tiempo_Vuelo | H3: Hora_Despegue | I3: Hora_Aterrizaje | J3: Aterrizaje_y_desembarque | K3: PF | L3: PFL | M3: PFTO | N3: PM | O3: Capitán | P3: Copiloto | Q3: Air | R3: Block | S3: combinación única 1
A4: FCDE13AF-66B1-431E-AF58-013DBB61E7F2 | B4: ='BitacoraDiaria_Muestreo '!F4 -> Latam Airlines-4472021-01/01/AA | C4: ='Vuelo_Muestreo '!E4 -> 4061-BOG-CLO-AV-01/01/AA | D4: 45292.681 | E4: =Matricula_Muestreo!B4 -> CC-BAQ | F4: 101 | G4: 45292.074 | H4: 45292.094 | I4: 45292.117 | J4: 45292.121 | K4: =TipoIntegrante_Muestreo!C5 -> Copiloto | L4: =TipoIntegrante_Muestreo!C4 -> Capitán | M4: =TipoIntegrante_Muestreo!C4 -> Capitán | N4: =TipoIntegrante_Muestreo!C5 -> Copiloto | O4: =EmpleadoAerolinea_Muestreo!I4 -> Latam Airlines-4472021 | P4: =EmpleadoAerolinea_Muestreo!I23 -> Latam Airlines-1036952691 | Q4: =TEXT(I4-H4,"h:mm") -> 0:34 | R4: =TEXT(J4-G4,"h:mm") -> 1:08 | S4: =_xlfn.CONCAT(C4)&" "&E4 -> 4061-BOG-CLO-AV-01/01/AA CC-BAQ
K7: DEBE SER UN CHECKBOX | O7: SE Escribe el nombre del compañero con quien volo(opcional) | Q7: widget de hora

Sheet Empleado_Caracterización
A1: << Modelo de dominio | B1: << Objetos de dominio | C1: << Muestreo Datos
A2: ='Objetos Dominio'!$A$2 -> Nombre | B2: ='Objetos Dominio'!$A$9 -> Empleado
A3: ='Objetos Dominio'!$B$2 -> Tipo | B3: ='Objetos Dominio'!$B$9 -> Propio
A4: ='Objetos Dominio'!$C$2 -> Contexto Origen | B4: ='Objetos Dominio'!$C$9 -> Flight Hours
A5: ='Objetos Dominio'!$D$2 -> Descripción | B5: ='Objetos Dominio'!$D$9 -> Objeto de dominio que representa el nombre y el código de la persona que trabaja en la aerolínea
A6: Atributo | B6: Tipo de Dato | C6: Longitud mínima | D6: Longitud máxima | E6: Precisión | F6: Cantidad cifras redondeo | G6: Tipo redondeo | H6: Rango Inicial | I6: Rango Final | J6: Formato | K6: Valor por defecto | L6: Regla especial | M6: ¿Quitar espacios en blanco al inicio? | N6: ¿Quitar espacios en blanco al final? | O6: ¿Auto generado? | P6: ¿Calculado? | Q6: ¿Obligatorio? | R6: ¿Modificable? | S6: ¿Sensible? | T6: ¿Identifica al registro? | U6: Descripción | V6: =A27 -> Agregar la información de un nuevo Empleado | W6: =A32 -> Consultar la Información del Empleado | X6: =A36 -> Restablecer la Contraseña del Empleado | Y6: =A40 -> Modificar la Clave del Empleado | Z6: =A44 -> Autenticar la Información del Empleado
A7: =Empleado_Muestreo!A3 -> Id | B7: Alfanumérico | C7: 36 | D7: 36 | J7: XXXXXXXX-XXXX-XXXX-XXXX-XXXXXXXXXXXX donde X es cualquier digito o una letra de la "A" a la "F" | M7: SI | N7: SI | O7: SI | P7: NO | Q7: SI | R7: NO | S7: NO | T7: SI | U7: =Empleado_Muestreo!$A$2 -> Corresponde a un identificador único del Empleado dentro del objeto de dominio Empleado. | V7: Requerido | W7: Filtro/Listar/ No Mostrar | X7: Requerido / No modificable | Y7: Requerido / No modificable | Z7: Requerido
A8: =Empleado_Muestreo!$B$3 -> Nombre | B8: Alfanumérico | C8: 3 | D8: 50 | J8: Cualquier cadena que incluye caracteres alfanuméricos, espacios, tildes(A-Z / a-z) | M8: SI | N8: SI | O8: NO | P8: NO | Q8: SI | R8: SI | S8: NO | T8: NO | U8: =Empleado_Muestreo!$B$2 -> Corresponde al nombre del empleado para el cual está configurado . | V8: Requerido | W8: Filtro/Listar/Mostrar[Orden{1}/CriterioOrdenamiento{1, ASC}/BusquedaGeneral{SI}/Ordenador{NO}/Reordenamiento{NO} ] | X8: Requerido / No modificable | Y8: Requerido / No modificable | Z8: No requerido
A9: =Empleado_Muestreo!C3 -> Email | B9: Alfanumérico | C9: 12 | D9: 150 | J9: Debe cumplir con el formato de un correo electrónico | M9: SI | N9: SI | O9: NO | P9: NO | Q9: SI | R9: NO | S9: NO | T9: SI | U9: Corresponde al correo del empleado con el cual va ingresar a la plataforma | V9: Requerido | W9: Filtro/Listar/Mostrar[Orden{2}/CriterioOrdenamiento{2, ASC}/BusquedaGeneral{SI}/Ordenador{NO}/Reordenamiento{NO} ] | X9: Requerido /No modificable | Y9: Requerido / No modificable | Z9: Requerido
A10: =Empleado_Muestreo!D3 -> Contrasena | B10: Alfanumérico | C10: 8 | D10: 16 | J10: Cualquier cadena que incluye caracteres alfanuméricos, espacios, tildes(A-Z / a-z) | M10: SI | N10: SI | O10: NO | P10: NO | Q10: SI | R10: SI | S10: SI | T10: NO | U10: Corresponde al atributo que contiene la contraseña con la cual ingresara el usuario | V10: Requerido | W10: Filtro/Listar/Mostrar[Orden{3}/BusquedaGeneral{NO}/Ordenador{NO}/Reordenamiento{NO} ] | X10: Requerido /modificable | Y10: Requerido /modificable | Z10: Requerido
A11: =Empleado_Muestreo!E3 -> EmailConfimado | B11: Lógico | M11: SI | N11: SI | O11: NO | P11: SI | Q11: SI | R11: SI | S11: NO | T11: NO | U11: Corresponde al atributo que contiene la confirmación de correo del usuario | V11: Requerido | W11: Filtro/Listar/Mostrar[Orden{4}/BusquedaGeneral{NO}/Ordenador{NO}/Reordenamiento{NO} ] | X11: Requerido / modificable | Y11: Requerido / modificable | Z11: No Requerido
A12: =Empleado_Muestreo!$F$3 -> numeroIdentificacion | B12: Numérico Entero | C12: 7 | D12: 7 | M12: SI | N12: SI | O12: NO | P12: NO | Q12: SI | R12: SI | S12: NO | T12: NO | U12: =Empleado_Muestreo!$F$2 -> Corresponde al número de identificación del empleado para el cual está configurado en la aerolínea. | V12: Requerido | W12: Filtro/Listar/Mostrar[Orden{5}/BusquedaGeneral{NO}/Ordenador{NO}/Reordenamiento{NO} ] | X12: Requerido /No modificable | Y12: Requerido /No modificable | Z12: No Requerido
A14: Combinaciones únicas
A15: Nombre combinación | B15: Descripción | C15: Atributos
A16: Año y número mes únicos | B16: =Empleado_Muestreo!G2 -> El número de identificación de un empleado no se puede repetir. | C16: =A12 -> numeroIdentificacion
A25: Responsabilidad | B25: Descripción | D25: Entradas | G25: Salida | H25: Políticas (Reglas de Negocio) | J25: Excepción
C26: Parámetro | D26: Tipo de dato | E26: Descripción | F26: Tipo de Dato | G26: Descripción | H26: Política | I26: Descripción | J26: Detalle | K26: ¿Qué hago?
A27: Agregar la información de un nuevo Empleado | B27: Permite agregar todos los detalles del empleado | C27: datos | D27: Empleado | E27: Contiene la información de los filtros que servirán como base para llevar a cabo la consulta de la información | H27: Empleado-POL-0001 | I27: Asegurar que los datos requeridos para llevar a cabo la acción sean válidos a nivel de tipo de dato, longitud, obligatoriedad, formato y rango. | J27: Generar una excepción indicándole al usuario que existen problemas con los datos y de ser posible indicarle cómo solucionarlos. | K27: Detener operación
H29: Empleado-POL-0002 | I29: No puede existir más de un Empleado con el mismo id | J29: Generar un nuevo identificador hasta garantizar que no exista | K29: Continuar operación
H30: Empleado-POL-0003 | I30: No puede existir más de un Empleado con el mismo número de identificación | J30: Generar una excepción indicándole al usuario que existen problemas con los datos y de ser posible indicarle cómo solucionarlos. | K30: Detener operación
H31: Empleado-POL-0004 | I31: No puede existir más de un Empleado con el mismo Email | J31: Generar una excepción indicándole al usuario que existen problemas con los datos y de ser posible indicarle cómo solucionarlos. | K31: Detener operación
A32: Consultar la Información del Empleado | B32: Permite revisar la información de un empleado | C32: Filtro | D32: Empleado | E32: Contiene la información de los filtros que servirán como base para llevar a cabo la consulta de la información | F32: Lista<Empleado> | G32: Contiene la información de todos los empleados que cumplen con el filtro de consulta | H32: Empleado-POL-0006 | I32: Asegurar que los datos que fueron enviados como filtro para llevar a cabo la acción sean válidos a nivel de tipo de dato, longitud, obligatoriedad, formato y rango. | J32: Generar una excepción indicándole al usuario que existen problemas con los datos y de ser posible indicarle cómo solucionarlos. | K32: Detener operación
A36: Restablecer la Contraseña del Empleado | B36: Permite restablecer la contraseña de un empleado | C36: Email | D36: Alfanumérico | E36: Contiene el email del empleado | H36: Empleado-POL-0001 | I36: Asegurar que los datos requeridos para llevar a cabo la acción sean válidos a nivel de tipo de dato, longitud, obligatoriedad, formato y rango. | J36: Generar una excepción indicándole al usuario que existen problemas con los datos y de ser posible indicarle cómo solucionarlos. | K36: Detener operación
C37: Contraseña nueva | D37: Alfanumérico | E37: Contiene la nueva contraseña del usuario a restablecer
A40: Modificar la Clave del Empleado | B40: Permite modificar la clave de un empleado | C40: Contraseña nueva | D40: Alfanumérico | E40: Contiene la nueva contraseña del usuario a modificar | H40: Empleado-POL-0001 | I40: Asegurar que los datos requeridos para llevar a cabo la acción sean válidos a nivel de tipo de dato, longitud, obligatoriedad, formato y rango. | J40: Generar una excepción indicándole al usuario que existen problemas con los datos y de ser posible indicarle cómo solucionarlos. | K40: Detener operación
C41: Email | D41: Alfanumérico | E41: Contiene el email del empleado a modificar la contraseña
C42: Contraseña actual | D42: Alfanumérico | E42: Contiene la nueva contraseña que el usuario ha de ingresar
A44: Autenticar la Información del Empleado | B44: Permite autenticar la información de un empleado | C44: email | D44: Empleado | E44: Contiene el email del empleado autenticar | H44: Empleado-POL-0001 | I44: Asegurar que los datos requeridos para llevar a cabo la acción sean válidos a nivel de tipo de dato, longitud, obligatoriedad, formato y rango. | J44: Generar una excepción indicándole al usuario que existen problemas con los datos y de ser posible indicarle cómo solucionarlos. | K44: Detener operación
C45: Contraseña | D45: Alfanumérico | E45: Contiene la contraseña del empleado a autenticar
A48: Eliminar la Información del Empleado | B48: Permite eliminar un empleado | C48: id | D48: Alfanumérico | E48: Contiene la información del identificador del empleado a que se va a eliminar de forma definitiva | H48: Empleado-POL-0005 | I48: El empleado debe estar previamente autenticado | J48: Generar una excepción indicándole al usuario que existen problemas con los datos y de ser posible indicarle cómo solucionarlos. | K48: Detener operación
H49: Empleado-POL-0001 | I49: Asegurar que los datos requeridos para llevar a cabo la acción sean válidos a nivel de tipo de dato, longitud, obligatoriedad, formato y rango. | J49: Generar una excepción indicándole al usuario que existen problemas con los datos y de ser posible indicarle cómo solucionarlos. | K49: Detener operación
A50: Modificar la Información del Empleado | B50: Permite editar un empleado | C50: id | D50: Alfanumérico | E50: Contiene la información del identificador del empleado que se va a editar de forma definitiva | H50: Empleado-POL-0005 | I50: El empleado debe estar previamente autenticado | J50: Generar una excepción indicándole al usuario que existen problemas con los datos y de ser posible indicarle cómo solucionarlos. | K50: Detener operación
H51: Empleado-POL-0001 | I51: Asegurar que los datos requeridos para llevar a cabo la acción sean válidos a nivel de tipo de dato, longitud, obligatoriedad, formato y rango. | J51: Generar una excepción indicándole al usuario que existen problemas con los datos y de ser posible indicarle cómo solucionarlos. | K51: Detener operación

Sheet Empleado_Muestreo
A1: << Modelo de dominio | B1: << Objetos de dominio | F1: Caracterización objeto >>
A2: Corresponde a un identificador único del Empleado dentro del objeto de dominio Empleado. | B2: Corresponde al nombre del empleado para el cual está configurado . | C2: Corresponde al Email del empleado. | D2: Corresponde a la clave del empleado . | E2: Corresponde al nombre del empleado para el cual está configurado . | F2: Corresponde al número de identificación del empleado para el cual está configurado en la aerolínea. | G2: El número de identificación de un empleado no se puede repetir.
